Workbook

Sheet 入力用
C1: 4 | D1: 4 | E1: 4 | F1: 4 | G1: 4 | H1: 4 | I1: 4 | J1: 4 | K1: 4 | L1: 4 | M1: 3 | N1: 3 | O1: 3 | P1: 3 | Q1: 3 | R1: 3 | S1: 2 | T1: 2 | U1: 2 | V1: 2 | W1: 2 | X1: 2 | Y1: 1 | Z1: 1 | AA1: 1 | AB1: 1 | AC1: 1 | AD1: 平均 | AE1: 標準偏差 | AG1: 男
B2: 測定日 | C2: 入澤瑛麻 | D2: 加藤華 | E2: 髙橋ひかる | F2: 天間美嘉 | G2: 長根理子 | H2: 橋本和香菜 | I2: 藤井真菜 | J2: 松岡琴美 | K2: 吉木理彩 | L2: 渡邉妃菜乃 | M2: 岩田愛美 | N2: 内田真愛 | O2: 徳山暖枝 | P2: 中村楓芽 | Q2: 向山せら | R2: 山下永遠 | S2: 池田朝花 | T2: 後藤和香奈 | U2: 津島世奈 | V2: 濱口芽花 | W2: 濱田遥花 | X2: 林美桜 | Y2: 天野莉子 | Z2: 栗原奈々 | AA2: 佐々木真凜 | AB2: 天間麗奈 | AC2: 宮下日香莉 | AG2: 女
A3: 体重 (kg) | B3: 26/3 | C3: 44.6 | D3: 52.2 | E3: 57.1 | F3: 55.5 | G3: 55.3 | H3: 50.4 | I3: 59.6 | J3: 51 | K3: 56.4 | L3: 49.7 | M3: 51.9 | N3: 54.6 | O3: 61.4 | P3: 56 | Q3: 53.3 | R3: 66.6 | S3: 52.7 | T3: 63.3 | U3: 61.1 | V3: 61.9 | W3: 64.9 | X3: 58.7 | AD3: =AVERAGE(C3:X3) -> 56.281818 | AE3: =_xlfn.STDEV.S(C3:X3) -> 5.4896124
B4: 26/4 | C4: 45.4 | D4: 50.7 | E4: 57.3 | F4: 54.4 | G4: 55.2 | H4: 50.8 | I4: 60.6 | J4: 52.2 | K4: 57.1 | L4: 49.5 | M4: 52.8 | N4: 55.4 | O4: 62.7 | P4: 56.3 | Q4: 54.4 | R4: 67.4 | S4: 53.6 | T4: 63 | U4: 60.2 | V4: 61.2 | W4: 64.9 | X4: 57.6 | Y4: 66.1 | Z4: 57.7 | AA4: 48 | AB4: 53.4 | AC4: 59 | AD4: =AVERAGE(C4:AC4) -> 56.551852 | AE4: =_xlfn.STDEV.S(C4:X4) -> 5.414029
B5: 26/5 | C5: 45.8 | D5: 48.9 | E5: 56.8 | F5: 54.7 | G5: 54.8 | H5: 51.3 | J5: 51.4 | K5: 54.9 | L5: 49.6 | M5: 53.4 | N5: 55.3 | O5: 62.3 | P5: 55.4 | Q5: 53.1 | R5: 67.5 | S5: 53.1 | T5: 63.5 | U5: 60.7 | V5: 60.4 | W5: 65.8 | X5: 57.7 | Y5: 65.2 | Z5: 58 | AA5: 48.2 | AB5: 54.2 | AC5: 58.6 | AD5: =AVERAGE(C5:AC5) -> 56.176923 | AE5: =_xlfn.STDEV.S(C5:X5) -> 5.6419517
B6: 26/6 | AD6: =AVERAGE(C6:X6) -> #DIV/0! | AE6: =_xlfn.STDEV.S(C6:X6) -> #DIV/0!
B7: 26/7 | AD7: =AVERAGE(C7:X7) -> #DIV/0! | AE7: =_xlfn.STDEV.S(C7:X7) -> #DIV/0!
B8: 26/8 | AD8: =AVERAGE(C8:X8) -> #DIV/0! | AE8: =_xlfn.STDEV.S(C8:X8) -> #DIV/0!
B9: 26/9 | AD9: =AVERAGE(C9:X9) -> #DIV/0! | AE9: =_xlfn.STDEV.S(C9:X9) -> #DIV/0!
B10: 26/10 | AD10: =AVERAGE(C10:X10) -> #DIV/0! | AE10: =_xlfn.STDEV.S(C10:X10) -> #DIV/0!
B11: 26/11 | AD11: =AVERAGE(C11:X11) -> #DIV/0! | AE11: =_xlfn.STDEV.S(C11:X11) -> #DIV/0!
B12: 26/12 | AD12: =AVERAGE(C12:X12) -> #DIV/0! | AE12: =_xlfn.STDEV.S(C12:X12) -> #DIV/0!
B13: 27/1 | AD13: =AVERAGE(C13:X13) -> #DIV/0! | AE13: =_xlfn.STDEV.S(C13:X13) -> #DIV/0!
B14: 27/2 | AD14: =AVERAGE(C14:X14) -> #DIV/0! | AE14: =_xlfn.STDEV.S(C14:X14) -> #DIV/0!
B15: 27/3 | AD15: =AVERAGE(C15:X15) -> #DIV/0! | AE15: =_xlfn.STDEV.S(C15:X15) -> #DIV/0!
A16: 骨格筋量 (kg) | B16: 26/3 | C16: 19.5 | D16: 21.1 | E16: 24.8 | F16: 21.8 | G16: 25.3 | H16: 22.1 | I16: 26 | J16: 21.3 | K16: 23.4 | L16: 19.3 | M16: 23.4 | N16: 23.3 | O16: 23.3 | P16: 24.6 | Q16: 23.2 | R16: 26.7 | S16: 22.5 | T16: 26.2 | U16: 26.1 | V16: 28 | W16: 24.2 | X16: 24.9 | AD16: =AVERAGE(C16:X16) -> 23.681818 | AE16: =_xlfn.STDEV.S(C16:X16) -> 2.2775585
B17: 26/4 | C17: 18.6 | D17: 20.7 | E17: 24 | F17: 22.3 | G17: 25.2 | H17: 21.9 | I17: 25.8 | J17: 21.3 | K17: 23.6 | L17: 19.1 | M17: 24.2 | N17: 24.4 | O17: 23.5 | P17: 24.1 | Q17: 23.6 | R17: 27.1 | S17: 24 | T17: 25.9 | U17: 25.5 | V17: 27.4 | W17: 23.7 | X17: 23.6 | Y17: 27.8 | Z17: 24.3 | AA17: 21.5 | AB17: 24.5 | AC17: 26.3 | AD17: =AVERAGE(C17:AC17) -> 23.848148 | AE17: =_xlfn.STDEV.S(C17:X17) -> 2.2688985
B18: 26/5 | C18: 19.4 | D18: 20.3 | E18: 24.5 | F18: 22.6 | G18: 24.8 | H18: 22.3 | J18: 21.8 | K18: 23.2 | L18: 19.7 | M18: 24.4 | N18: 25.2 | O18: 23.2 | P18: 23.7 | Q18: 23.9 | R18: 26.9 | S18: 23.5 | T18: 26.7 | U18: 25.9 | V18: 27.7 | W18: 24.1 | X18: 24.1 | Y18: 26.8 | Z18: 24.2 | AA18: 22 | AB18: 25.1 | AC18: 27.1 | AD18: =AVERAGE(C18:AC18) -> 23.965385 | AE18: =_xlfn.STDEV.S(C18:X18) -> 2.2180858
B19: 26/6 | AD19: =AVERAGE(C19:X19) -> #DIV/0! | AE19: =_xlfn.STDEV.S(C19:X19) -> #DIV/0!
B20: 26/7 | AD20: =AVERAGE(C20:X20) -> #DIV/0! | AE20: =_xlfn.STDEV.S(C20:X20) -> #DIV/0!
B21: 26/8 | AD21: =AVERAGE(C21:X21) -> #DIV/0! | AE21: =_xlfn.STDEV.S(C21:X21) -> #DIV/0!
B22: 26/9 | AD22: =AVERAGE(C22:X22) -> #DIV/0! | AE22: =_xlfn.STDEV.S(C22:X22) -> #DIV/0!
B23: 26/10 | AD23: =AVERAGE(C23:X23) -> #DIV/0! | AE23: =_xlfn.STDEV.S(C23:X23) -> #DIV/0!
B24: 26/11 | AD24: =AVERAGE(C24:X24) -> #DIV/0! | AE24: =_xlfn.STDEV.S(C24:X24) -> #DIV/0!
B25: 26/12 | AD25: =AVERAGE(C25:X25) -> #DIV/0! | AE25: =_xlfn.STDEV.S(C25:X25) -> #DIV/0!
B26: 27/1 | AD26: =AVERAGE(C26:X26) -> #DIV/0! | AE26: =_xlfn.STDEV.S(C26:X26) -> #DIV/0!
B27: 27/2 | AD27: =AVERAGE(C27:X27) -> #DIV/0! | AE27: =_xlfn.STDEV.S(C27:X27) -> #DIV/0!
B28: 27/3 | AD28: =AVERAGE(C28:X28) -> #DIV/0! | AE28: =_xlfn.STDEV.S(C28:X28) -> #DIV/0!
A29: 骨格筋量 / 体重 (%) | B29: 26/3 | C29: =ROUND((C16/C3)*100,1) -> 43.7 | D29: =ROUND((D16/D3)*100,1) -> 40.4 | E29: =ROUND((E16/E3)*100,1) -> 43.4 | F29: =ROUND((F16/F3)*100,1) -> 39.3 | G29: =ROUND((G16/G3)*100,1) -> 45.8 | H29: =ROUND((H16/H3)*100,1) -> 43.8 | I29: =ROUND((I16/I3)*100,1) -> 43.6 | J29: =ROUND((J16/J3)*100,1) -> 41.8 | ... AC29: =ROUND((AC16/AC3)*100,1) -> #DIV/0! | AD29: =AVERAGE(C29:Y29) -> #DIV/0! | AE29: =_xlfn.STDEV.S(C29:X29) -> 2.3428809
B30: 26/4 | C30: =ROUND((C17/C4)*100,1) -> 41 | D30: =ROUND((D17/D4)*100,1) -> 40.8 | E30: =ROUND((E17/E4)*100,1) -> 41.9 | F30: =ROUND((F17/F4)*100,1) -> 41 | G30: =ROUND((G17/G4)*100,1) -> 45.7 | H30: =ROUND((H17/H4)*100,1) -> 43.1 | I30: =ROUND((I17/I4)*100,1) -> 42.6 | J30: =ROUND((J17/J4)*100,1) -> 40.8 | ... AC30: =ROUND((AC17/AC4)*100,1) -> 44.6 | AD30: =AVERAGE(C30:X30) -> 41.868182 | AE30: =_xlfn.STDEV.S(C30:X30) -> 2.4323977
B31: 26/5 | C31: =ROUND((C18/C5)*100,1) -> 42.4 | D31: =ROUND((D18/D5)*100,1) -> 41.5 | E31: =ROUND((E18/E5)*100,1) -> 43.1 | F31: =ROUND((F18/F5)*100,1) -> 41.3 | G31: =ROUND((G18/G5)*100,1) -> 45.3 | H31: =ROUND((H18/H5)*100,1) -> 43.5 | I31: =ROUND((I18/I5)*100,1) -> #DIV/0! | J31: =ROUND((J18/J5)*100,1) -> 42.4 | ... AC31: =ROUND((AC18/AC5)*100,1) -> 46.2 | AD31: =AVERAGE(C31:X31) -> #DIV/0! | AE31: =_xlfn.STDEV.S(C31:X31) -> #DIV/0!
B32: 26/6 | C32: =ROUND((C19/C6)*100,1) -> #DIV/0! | D32: =ROUND((D19/D6)*100,1) -> #DIV/0! | E32: =ROUND((E19/E6)*100,1) -> #DIV/0! | F32: =ROUND((F19/F6)*100,1) -> #DIV/0! | G32: =ROUND((G19/G6)*100,1) -> #DIV/0! | H32: =ROUND((H19/H6)*100,1) -> #DIV/0! | I32: =ROUND((I19/I6)*100,1) -> #DIV/0! | J32: =ROUND((J19/J6)*100,1) -> #DIV/0! | ... AC32: =ROUND((AC19/AC6)*100,1) -> #DIV/0! | AD32: =AVERAGE(C32:X32) -> #DIV/0! | AE32: =_xlfn.STDEV.S(C32:X32) -> #DIV/0!
B33: 26/7 | C33: =ROUND((C20/C7)*100,1) -> #DIV/0! | D33: =ROUND((D20/D7)*100,1) -> #DIV/0! | E33: =ROUND((E20/E7)*100,1) -> #DIV/0! | F33: =ROUND((F20/F7)*100,1) -> #DIV/0! | G33: =ROUND((G20/G7)*100,1) -> #DIV/0! | H33: =ROUND((H20/H7)*100,1) -> #DIV/0! | I33: =ROUND((I20/I7)*100,1) -> #DIV/0! | J33: =ROUND((J20/J7)*100,1) -> #DIV/0! | ... AC33: =ROUND((AC20/AC7)*100,1) -> #DIV/0! | AD33: =AVERAGE(C33:X33) -> #DIV/0! | AE33: =_xlfn.STDEV.S(C33:X33) -> #DIV/0!
B34: 26/8 | C34: =ROUND((C21/C8)*100,1) -> #DIV/0! | D34: =ROUND((D21/D8)*100,1) -> #DIV/0! | E34: =ROUND((E21/E8)*100,1) -> #DIV/0! | F34: =ROUND((F21/F8)*100,1) -> #DIV/0! | G34: =ROUND((G21/G8)*100,1) -> #DIV/0! | H34: =ROUND((H21/H8)*100,1) -> #DIV/0! | I34: =ROUND((I21/I8)*100,1) -> #DIV/0! | J34: =ROUND((J21/J8)*100,1) -> #DIV/0! | ... AC34: =ROUND((AC21/AC8)*100,1) -> #DIV/0! | AD34: =AVERAGE(C34:X34) -> #DIV/0! | AE34: =_xlfn.STDEV.S(C34:X34) -> #DIV/0!
B35: 26/9 | C35: =ROUND((C22/C9)*100,1) -> #DIV/0! | D35: =ROUND((D22/D9)*100,1) -> #DIV/0! | E35: =ROUND((E22/E9)*100,1) -> #DIV/0! | F35: =ROUND((F22/F9)*100,1) -> #DIV/0! | G35: =ROUND((G22/G9)*100,1) -> #DIV/0! | H35: =ROUND((H22/H9)*100,1) -> #DIV/0! | I35: =ROUND((I22/I9)*100,1) -> #DIV/0! | J35: =ROUND((J22/J9)*100,1) -> #DIV/0! | ... AC35: =ROUND((AC22/AC9)*100,1) -> #DIV/0! | AD35: =AVERAGE(C35:X35) -> #DIV/0! | AE35: =_xlfn.STDEV.S(C35:X35) -> #DIV/0!
B36: 26/10 | C36: =ROUND((C23/C10)*100,1) -> #DIV/0! | D36: =ROUND((D23/D10)*100,1) -> #DIV/0! | E36: =ROUND((E23/E10)*100,1) -> #DIV/0! | F36: =ROUND((F23/F10)*100,1) -> #DIV/0! | G36: =ROUND((G23/G10)*100,1) -> #DIV/0! | H36: =ROUND((H23/H10)*100,1) -> #DIV/0! | I36: =ROUND((I23/I10)*100,1) -> #DIV/0! | J36: =ROUND((J23/J10)*100,1) -> #DIV/0! | ... AC36: =ROUND((AC23/AC10)*100,1) -> #DIV/0! | AD36: =AVERAGE(C36:X36) -> #DIV/0! | AE36: =_xlfn.STDEV.S(C36:X36) -> #DIV/0!
B37: 26/11 | C37: =ROUND((C24/C11)*100,1) -> #DIV/0! | D37: =ROUND((D24/D11)*100,1) -> #DIV/0! | E37: =ROUND((E24/E11)*100,1) -> #DIV/0! | F37: =ROUND((F24/F11)*100,1) -> #DIV/0! | G37: =ROUND((G24/G11)*100,1) -> #DIV/0! | H37: =ROUND((H24/H11)*100,1) -> #DIV/0! | I37: =ROUND((I24/I11)*100,1) -> #DIV/0! | J37: =ROUND((J24/J11)*100,1) -> #DIV/0! | ... AC37: =ROUND((AC24/AC11)*100,1) -> #DIV/0! | AD37: =AVERAGE(C37:X37) -> #DIV/0! | AE37: =_xlfn.STDEV.S(C37:X37) -> #DIV/0!
B38: 26/12 | C38: =ROUND((C25/C12)*100,1) -> #DIV/0! | D38: =ROUND((D25/D12)*100,1) -> #DIV/0! | E38: =ROUND((E25/E12)*100,1) -> #DIV/0! | F38: =ROUND((F25/F12)*100,1) -> #DIV/0! | G38: =ROUND((G25/G12)*100,1) -> #DIV/0! | H38: =ROUND((H25/H12)*100,1) -> #DIV/0! | I38: =ROUND((I25/I12)*100,1) -> #DIV/0! | J38: =ROUND((J25/J12)*100,1) -> #DIV/0! | ... AC38: =ROUND((AC25/AC12)*100,1) -> #DIV/0! | AD38: =AVERAGE(C38:X38) -> #DIV/0! | AE38: =_xlfn.STDEV.S(C38:X38) -> #DIV/0!
B39: 27/1 | C39: =ROUND((C26/C13)*100,1) -> #DIV/0! | D39: =ROUND((D26/D13)*100,1) -> #DIV/0! | E39: =ROUND((E26/E13)*100,1) -> #DIV/0! | F39: =ROUND((F26/F13)*100,1) -> #DIV/0! | G39: =ROUND((G26/G13)*100,1) -> #DIV/0! | H39: =ROUND((H26/H13)*100,1) -> #DIV/0! | I39: =ROUND((I26/I13)*100,1) -> #DIV/0! | J39: =ROUND((J26/J13)*100,1) -> #DIV/0! | ... AC39: =ROUND((AC26/AC13)*100,1) -> #DIV/0! | AD39: =AVERAGE(C39:X39) -> #DIV/0! | AE39: =_xlfn.STDEV.S(C39:X39) -> #DIV/0!
B40: 27/2 | C40: =ROUND((C27/C14)*100,1) -> #DIV/0! | D40: =ROUND((D27/D14)*100,1) -> #DIV/0! | E40: =ROUND((E27/E14)*100,1) -> #DIV/0! | F40: =ROUND((F27/F14)*100,1) -> #DIV/0! | G40: =ROUND((G27/G14)*100,1) -> #DIV/0! | H40: =ROUND((H27/H14)*100,1) -> #DIV/0! | I40: =ROUND((I27/I14)*100,1) -> #DIV/0! | J40: =ROUND((J27/J14)*100,1) -> #DIV/0! | ... AC40: =ROUND((AC27/AC14)*100,1) -> #DIV/0! | AD40: =AVERAGE(C40:X40) -> #DIV/0! | AE40: =_xlfn.STDEV.S(C40:X40) -> #DIV/0!
...

Sheet 平均
A2: NSSU Soft tennis Team Inbody Feedback Sheet
A8: 氏名： | B8: チーム平均 | C8: 性別： | D8: =入力用!AG2 -> 女
A9: 測定種目 | B9: 体重 (kg) | C9: 骨格筋量 (kg) | D9: 骨格筋量/体重 (%) | E9: 体脂肪量 (kg) | F9: 体脂肪率 (%)
A10: =入力用!B3 -> 26/3 | B10: =入力用!AD3 -> 56.281818 | C10: =入力用!AD16 -> 23.681818 | D10: =入力用!AD29 -> #DIV/0! | E10: =入力用!AD42 -> 13.740909 | F10: =入力用!AD55 -> 24.259091
A11: =入力用!B4 -> 26/4 | B11: =入力用!AD4 -> 56.551852 | C11: =入力用!AD17 -> 23.848148 | D11: =入力用!AD30 -> 41.868182 | E11: =入力用!AD43 -> 13.844444 | F11: =入力用!AD56 -> 24.296296
A12: =入力用!B5 -> 26/5 | B12: =入力用!AD5 -> 56.176923 | C12: =入力用!AD18 -> 23.965385 | D12: =入力用!AD31 -> #DIV/0! | E12: =入力用!AD44 -> 13.296154 | F12: =入力用!AD57 -> 23.419231
A13: =入力用!B6 -> 26/6 | B13: =入力用!AD6 -> #DIV/0! | C13: =入力用!AD19 -> #DIV/0! | D13: =入力用!AD32 -> #DIV/0! | E13: =入力用!AD45 -> #DIV/0! | F13: =入力用!AD58 -> #DIV/0!
A14: =入力用!B7 -> 26/7 | B14: =入力用!AD7 -> #DIV/0! | C14: =入力用!AD20 -> #DIV/0! | D14: =入力用!AD33 -> #DIV/0! | E14: =入力用!AD46 -> #DIV/0! | F14: =入力用!AD59 -> #DIV/0!
A15: =入力用!B8 -> 26/8 | B15: =入力用!AD8 -> #DIV/0! | C15: =入力用!AD21 -> #DIV/0! | D15: =入力用!AD34 -> #DIV/0! | E15: =入力用!AD47 -> #DIV/0! | F15: =入力用!AD60 -> #DIV/0!
A16: =入力用!B9 -> 26/9 | B16: =入力用!AD9 -> #DIV/0! | C16: =入力用!AD22 -> #DIV/0! | D16: =入力用!AD35 -> #DIV/0! | E16: =入力用!AD48 -> #DIV/0! | F16: =入力用!AD61 -> #DIV/0!
A17: =入力用!B10 -> 26/10 | B17: =入力用!AD10 -> #DIV/0! | C17: =入力用!AD23 -> #DIV/0! | D17: =入力用!AD36 -> #DIV/0! | E17: =入力用!AD49 -> #DIV/0! | F17: =入力用!AD62 -> #DIV/0!
A18: =入力用!B11 -> 26/11 | B18: =入力用!AD11 -> #DIV/0! | C18: =入力用!AD24 -> #DIV/0! | D18: =入力用!AD37 -> #DIV/0! | E18: =入力用!AD50 -> #DIV/0! | F18: =入力用!AD63 -> #DIV/0!
A19: =入力用!B12 -> 26/12 | B19: =入力用!AD12 -> #DIV/0! | C19: =入力用!AD25 -> #DIV/0! | D19: =入力用!AD38 -> #DIV/0! | E19: =入力用!AD51 -> #DIV/0! | F19: =入力用!AD64 -> #DIV/0!
A20: =入力用!B13 -> 27/1 | B20: =入力用!AD13 -> #DIV/0! | C20: =入力用!AD26 -> #DIV/0! | D20: =入力用!AD39 -> #DIV/0! | E20: =入力用!AD52 -> #DIV/0! | F20: =入力用!AD65 -> #DIV/0!
A21: =入力用!B15 -> 27/3 | B21: =入力用!AD15 -> #DIV/0! | C21: =入力用!AD28 -> #DIV/0! | D21: =入力用!AD41 -> #DIV/0! | E21: =入力用!AD54 -> #DIV/0! | F21: =入力用!AD67 -> #DIV/0!

Sheet 入澤
A2: NSSU Soft tennis Team Inbody Feedback Sheet
A8: 氏名： | B8: =入力用!C2 -> 入澤瑛麻 | C8: 性別： | D8: =入力用!AG2 -> 女
A9: 測定日 | B9: 体重 (kg) | C9: 骨格筋量 (kg) | D9: 骨格筋量/体重 (%) | E9: 体脂肪量 (kg) | F9: 体脂肪率 (%)
A10: =入力用!B3 -> 26/3 | B10: =入力用!C3 -> 44.6 | C10: =入力用!C16 -> 19.5 | D10: =入力用!C29 -> 43.7 | E10: =入力用!C42 -> 9.1 | F10: =入力用!C55 -> 20.4
A11: =入力用!B4 -> 26/4 | B11: =入力用!C4 -> 45.4 | C11: =入力用!C17 -> 18.6 | D11: =入力用!C30 -> 41 | E11: =入力用!C43 -> 11.3 | F11: =入力用!C56 -> 24.8
A12: =入力用!B5 -> 26/5 | B12: =入力用!C5 -> 45.8 | C12: =入力用!C18 -> 19.4 | D12: =入力用!C31 -> 42.4 | E12: =入力用!C44 -> 10.4 | F12: =入力用!C57 -> 22.7
A13: =入力用!B6 -> 26/6 | B13: =入力用!C6 -> 0 | C13: =入力用!C19 -> 0 | D13: =入力用!C32 -> #DIV/0! | E13: =入力用!C45 -> 0 | F13: =入力用!C58 -> 0
A14: =入力用!B7 -> 26/7 | B14: =入力用!C7 -> 0 | C14: =入力用!C20 -> 0 | D14: =入力用!C33 -> #DIV/0! | E14: =入力用!C46 -> 0 | F14: =入力用!C59 -> 0
A15: =入力用!B8 -> 26/8 | B15: =入力用!C8 -> 0 | C15: =入力用!C21 -> 0 | D15: =入力用!C34 -> #DIV/0! | E15: =入力用!C47 -> 0 | F15: =入力用!C60 -> 0
A16: =入力用!B9 -> 26/9 | B16: =入力用!C9 -> 0 | C16: =入力用!C22 -> 0 | D16: =入力用!C35 -> #DIV/0! | E16: =入力用!C48 -> 0 | F16: =入力用!C61 -> 0
A17: =入力用!B10 -> 26/10 | B17: =入力用!C10 -> 0 | C17: =入力用!C23 -> 0 | D17: =入力用!C36 -> #DIV/0! | E17: =入力用!C49 -> 0 | F17: =入力用!C62 -> 0
A18: =入力用!B11 -> 26/11 | B18: =入力用!C11 -> 0 | C18: =入力用!C24 -> 0 | D18: =入力用!C37 -> #DIV/0! | E18: =入力用!C50 -> 0 | F18: =入力用!C63 -> 0
A19: =入力用!B12 -> 26/12 | B19: =入力用!C12 -> 0 | C19: =入力用!C25 -> 0 | D19: =入力用!C38 -> #DIV/0! | E19: =入力用!C51 -> 0 | F19: =入力用!C64 -> 0
A20: =入力用!B13 -> 27/1 | B20: =入力用!C13 -> 0 | C20: =入力用!C26 -> 0 | D20: =入力用!C39 -> #DIV/0! | E20: =入力用!C52 -> 0 | F20: =入力用!C65 -> 0
A21: =入力用!B15 -> 27/3 | B21: =入力用!C15 -> 0 | C21: =入力用!C28 -> 0 | D21: =入力用!C41 -> #DIV/0! | E21: =入力用!C54 -> 0 | F21: =入力用!C67 -> 0

Sheet 橋本
A2: NSSU Soft tennis Team Inbody Feedback Sheet
A8: 氏名： | B8: =入力用!H2 -> 橋本和香菜 | C8: 性別： | D8: =入力用!AG2 -> 女
A9: 測定日 | B9: 体重 (kg) | C9: 骨格筋量 (kg) | D9: 骨格筋量/体重 (%) | E9: 体脂肪量 (kg) | F9: 体脂肪率 (%)
A10: =入力用!B3 -> 26/3 | B10: =入力用!H3 -> 50.4 | C10: =入力用!H16 -> 22.1 | D10: =入力用!H29 -> 43.8 | E10: =入力用!H42 -> 10.6 | F10: =入力用!H55 -> 21.1
A11: =入力用!B4 -> 26/4 | B11: =入力用!H4 -> 50.8 | C11: =入力用!H17 -> 21.9 | D11: =入力用!H30 -> 43.1 | E11: =入力用!H43 -> 11.5 | F11: =入力用!H56 -> 22.7
A12: =入力用!B5 -> 26/5 | B12: =入力用!H5 -> 51.3 | C12: =入力用!H18 -> 22.3 | D12: =入力用!H31 -> 43.5 | E12: =入力用!H44 -> 11.1 | F12: =入力用!H57 -> 21.7
A13: =入力用!B6 -> 26/6 | B13: =入力用!H6 -> 0 | C13: =入力用!H19 -> 0 | D13: =入力用!H32 -> #DIV/0! | E13: =入力用!H45 -> 0 | F13: =入力用!H58 -> 0
A14: =入力用!B7 -> 26/7 | B14: =入力用!H7 -> 0 | C14: =入力用!H20 -> 0 | D14: =入力用!H33 -> #DIV/0! | E14: =入力用!H46 -> 0 | F14: =入力用!H59 -> 0
A15: =入力用!B8 -> 26/8 | B15: =入力用!H8 -> 0 | C15: =入力用!H21 -> 0 | D15: =入力用!H34 -> #DIV/0! | E15: =入力用!H47 -> 0 | F15: =入力用!H60 -> 0
A16: =入力用!B9 -> 26/9 | B16: =入力用!H9 -> 0 | C16: =入力用!H22 -> 0 | D16: =入力用!H35 -> #DIV/0! | E16: =入力用!H48 -> 0 | F16: =入力用!H61 -> 0
A17: =入力用!B10 -> 26/10 | B17: =入力用!H10 -> 0 | C17: =入力用!H23 -> 0 | D17: =入力用!H36 -> #DIV/0! | E17: =入力用!H49 -> 0 | F17: =入力用!H62 -> 0
A18: =入力用!B11 -> 26/11 | B18: =入力用!H11 -> 0 | C18: =入力用!H24 -> 0 | D18: =入力用!H37 -> #DIV/0! | E18: =入力用!H50 -> 0 | F18: =入力用!H63 -> 0
A19: =入力用!B12 -> 26/12 | B19: =入力用!H12 -> 0 | C19: =入力用!H25 -> 0 | D19: =入力用!H38 -> #DIV/0! | E19: =入力用!H51 -> 0 | F19: =入力用!H64 -> 0
A20: =入力用!B13 -> 27/1 | B20: =入力用!H13 -> 0 | C20: =入力用!H26 -> 0 | D20: =入力用!H39 -> #DIV/0! | E20: =入力用!H52 -> 0 | F20: =入力用!H65 -> 0
A21: =入力用!B15 -> 27/3 | B21: =入力用!H15 -> 0 | C21: =入力用!H28 -> 0 | D21: =入力用!H41 -> #DIV/0! | E21: =入力用!H54 -> 0 | F21: =入力用!H67 -> 0

Sheet 加藤
A2: NSSU Soft tennis Team Inbody Feedback Sheet
A8: 氏名： | B8: =入力用!D2 -> 加藤華 | C8: 性別： | D8: =入力用!AG2 -> 女
A9: 測定日 | B9: 体重 (kg) | C9: 骨格筋量 (kg) | D9: 骨格筋量/体重 (%) | E9: 体脂肪量 (kg) | F9: 体脂肪率 (%)
A10: =入力用!B3 -> 26/3 | B10: =入力用!D3 -> 52.2 | C10: =入力用!D16 -> 21.1 | D10: =入力用!D29 -> 40.4 | E10: =入力用!D42 -> 13.9 | F10: =入力用!D55 -> 26.7
A11: =入力用!B4 -> 26/4 | B11: =入力用!D4 -> 50.7 | C11: =入力用!D17 -> 20.7 | D11: =入力用!D30 -> 40.8 | E11: =入力用!D43 -> 12.9 | F11: =入力用!D56 -> 25.5
A12: =入力用!B5 -> 26/5 | B12: =入力用!D5 -> 48.9 | C12: =入力用!D18 -> 20.3 | D12: =入力用!D31 -> 41.5 | E12: =入力用!D44 -> 11.9 | F12: =入力用!D57 -> 24.3
A13: =入力用!B6 -> 26/6 | B13: =入力用!D6 -> 0 | C13: =入力用!D19 -> 0 | D13: =入力用!D32 -> #DIV/0! | E13: =入力用!D45 -> 0 | F13: =入力用!D58 -> 0
A14: =入力用!B7 -> 26/7 | B14: =入力用!D7 -> 0 | C14: =入力用!D20 -> 0 | D14: =入力用!D33 -> #DIV/0! | E14: =入力用!D46 -> 0 | F14: =入力用!D59 -> 0
A15: =入力用!B8 -> 26/8 | B15: =入力用!D8 -> 0 | C15: =入力用!D21 -> 0 | D15: =入力用!D34 -> #DIV/0! | E15: =入力用!D47 -> 0 | F15: =入力用!D60 -> 0
A16: =入力用!B9 -> 26/9 | B16: =入力用!D9 -> 0 | C16: =入力用!D22 -> 0 | D16: =入力用!D35 -> #DIV/0! | E16: =入力用!D48 -> 0 | F16: =入力用!D61 -> 0
A17: =入力用!B10 -> 26/10 | B17: =入力用!D10 -> 0 | C17: =入力用!D23 -> 0 | D17: =入力用!D36 -> #DIV/0! | E17: =入力用!D49 -> 0 | F17: =入力用!D62 -> 0
A18: =入力用!B11 -> 26/11 | B18: =入力用!D11 -> 0 | C18: =入力用!D24 -> 0 | D18: =入力用!D37 -> #DIV/0! | E18: =入力用!D50 -> 0 | F18: =入力用!D63 -> 0
A19: =入力用!B12 -> 26/12 | B19: =入力用!D12 -> 0 | C19: =入力用!D25 -> 0 | D19: =入力用!D38 -> #DIV/0! | E19: =入力用!D51 -> 0 | F19: =入力用!D64 -> 0
A20: =入力用!B13 -> 27/1 | B20: =入力用!D13 -> 0 | C20: =入力用!D26 -> 0 | D20: =入力用!D39 -> #DIV/0! | E20: =入力用!D52 -> 0 | F20: =入力用!D65 -> 0
A21: =入力用!B15 -> 27/3 | B21: =入力用!D15 -> 0 | C21: =入力用!D28 -> 0 | D21: =入力用!D41 -> #DIV/0! | E21: =入力用!D54 -> 0 | F21: =入力用!D67 -> 0

Sheet 髙橋
A2: NSSU Soft tennis Team Inbody Feedback Sheet
A8: 氏名： | B8: =入力用!E2 -> 髙橋ひかる | C8: 性別： | D8: =入力用!AG2 -> 女
A9: 測定日 | B9: 体重 (kg) | C9: 骨格筋量 (kg) | D9: 骨格筋量/体重 (%) | E9: 体脂肪量 (kg) | F9: 体脂肪率 (%)
A10: =入力用!B3 -> 26/3 | B10: =入力用!E3 -> 57.1 | C10: =入力用!E16 -> 24.8 | D10: =入力用!E29 -> 43.4 | E10: =入力用!E42 -> 12.9 | F10: =入力用!E55 -> 22.6
A11: =入力用!B4 -> 26/4 | B11: =入力用!E4 -> 57.3 | C11: =入力用!E17 -> 24 | D11: =入力用!E30 -> 41.9 | E11: =入力用!E43 -> 14.6 | F11: =入力用!E56 -> 25.5
A12: =入力用!B5 -> 26/5 | B12: =入力用!E5 -> 56.8 | C12: =入力用!E18 -> 24.5 | D12: =入力用!E31 -> 43.1 | E12: =入力用!E44 -> 13 | F12: =入力用!E57 -> 22.9
A13: =入力用!B6 -> 26/6 | B13: =入力用!E6 -> 0 | C13: =入力用!E19 -> 0 | D13: =入力用!E32 -> #DIV/0! | E13: =入力用!E45 -> 0 | F13: =入力用!E58 -> 0
A14: =入力用!B7 -> 26/7 | B14: =入力用!E7 -> 0 | C14: =入力用!E20 -> 0 | D14: =入力用!E33 -> #DIV/0! | E14: =入力用!E46 -> 0 | F14: =入力用!E59 -> 0
A15: =入力用!B8 -> 26/8 | B15: =入力用!E8 -> 0 | C15: =入力用!E21 -> 0 | D15: =入力用!E34 -> #DIV/0! | E15: =入力用!E47 -> 0 | F15: =入力用!E60 -> 0
A16: =入力用!B9 -> 26/9 | B16: =入力用!E9 -> 0 | C16: =入力用!E22 -> 0 | D16: =入力用!E35 -> #DIV/0! | E16: =入力用!E48 -> 0 | F16: =入力用!E61 -> 0
A17: =入力用!B10 -> 26/10 | B17: =入力用!E10 -> 0 | C17: =入力用!E23 -> 0 | D17: =入力用!E36 -> #DIV/0! | E17: =入力用!E49 -> 0 | F17: =入力用!E62 -> 0
A18: =入力用!B11 -> 26/11 | B18: =入力用!E11 -> 0 | C18: =入力用!E24 -> 0 | D18: =入力用!E37 -> #DIV/0! | E18: =入力用!E50 -> 0 | F18: =入力用!E63 -> 0
A19: =入力用!B12 -> 26/12 | B19: =入力用!E12 -> 0 | C19: =入力用!E25 -> 0 | D19: =入力用!E38 -> #DIV/0! | E19: =入力用!E51 -> 0 | F19: =入力用!E64 -> 0
A20: =入力用!B13 -> 27/1 | B20: =入力用!E13 -> 0 | C20: =入力用!E26 -> 0 | D20: =入力用!E39 -> #DIV/0! | E20: =入力用!E52 -> 0 | F20: =入力用!E65 -> 0
A21: =入力用!B15 -> 27/3 | B21: =入力用!E15 -> 0 | C21: =入力用!E28 -> 0 | D21: =入力用!E41 -> #DIV/0! | E21: =入力用!E54 -> 0 | F21: =入力用!E67 -> 0

Sheet 天間
A2: NSSU Soft tennis Team Inbody Feedback Sheet
A8: 氏名： | B8: =入力用!F2 -> 天間美嘉 | C8: 性別： | D8: =入力用!AG2 -> 女
A9: 測定日 | B9: 体重 (kg) | C9: 骨格筋量 (kg) | D9: 骨格筋量/体重 (%) | E9: 体脂肪量 (kg) | F9: 体脂肪率 (%)
A10: =入力用!B3 -> 26/3 | B10: =入力用!F3 -> 55.5 | C10: =入力用!F16 -> 21.8 | D10: =入力用!F29 -> 39.3 | E10: =入力用!F42 -> 15.6 | F10: =入力用!F55 -> 28.1
A11: =入力用!B4 -> 26/4 | B11: =入力用!F4 -> 54.4 | C11: =入力用!F17 -> 22.3 | D11: =入力用!F30 -> 41 | E11: =入力用!F43 -> 13.8 | F11: =入力用!F56 -> 25.3
A12: =入力用!B5 -> 26/5 | B12: =入力用!F5 -> 54.7 | C12: =入力用!F18 -> 22.6 | D12: =入力用!F31 -> 41.3 | E12: =入力用!F44 -> 14.1 | F12: =入力用!F57 -> 25.8
A13: =入力用!B6 -> 26/6 | B13: =入力用!F6 -> 0 | C13: =入力用!F19 -> 0 | D13: =入力用!F32 -> #DIV/0! | E13: =入力用!F45 -> 0 | F13: =入力用!F58 -> 0
A14: =入力用!B7 -> 26/7 | B14: =入力用!F7 -> 0 | C14: =入力用!F20 -> 0 | D14: =入力用!F33 -> #DIV/0! | E14: =入力用!F46 -> 0 | F14: =入力用!F59 -> 0
A15: =入力用!B8 -> 26/8 | B15: =入力用!F8 -> 0 | C15: =入力用!F21 -> 0 | D15: =入力用!F34 -> #DIV/0! | E15: =入力用!F47 -> 0 | F15: =入力用!F60 -> 0
A16: =入力用!B9 -> 26/9 | B16: =入力用!F9 -> 0 | C16: =入力用!F22 -> 0 | D16: =入力用!F35 -> #DIV/0! | E16: =入力用!F48 -> 0 | F16: =入力用!F61 -> 0
A17: =入力用!B10 -> 26/10 | B17: =入力用!F10 -> 0 | C17: =入力用!F23 -> 0 | D17: =入力用!F36 -> #DIV/0! | E17: =入力用!F49 -> 0 | F17: =入力用!F62 -> 0
A18: =入力用!B11 -> 26/11 | B18: =入力用!F11 -> 0 | C18: =入力用!F24 -> 0 | D18: =入力用!F37 -> #DIV/0! | E18: =入力用!F50 -> 0 | F18: =入力用!F63 -> 0
A19: =入力用!B12 -> 26/12 | B19: =入力用!F12 -> 0 | C19: =入力用!F25 -> 0 | D19: =入力用!F38 -> #DIV/0! | E19: =入力用!F51 -> 0 | F19: =入力用!F64 -> 0
A20: =入力用!B13 -> 27/1 | B20: =入力用!F13 -> 0 | C20: =入力用!F26 -> 0 | D20: =入力用!F39 -> #DIV/0! | E20: =入力用!F52 -> 0 | F20: =入力用!F65 -> 0
A21: =入力用!B15 -> 27/3 | B21: =入力用!F15 -> 0 | C21: =入力用!F28 -> 0 | D21: =入力用!F41 -> #DIV/0! | E21: =入力用!F54 -> 0 | F21: =入力用!F67 -> 0

Sheet 長根
A2: NSSU Soft tennis Team Inbody Feedback Sheet
A8: 氏名： | B8: =入力用!G2 -> 長根理子 | C8: 性別： | D8: =入力用!AG2 -> 女
A9: 測定日 | B9: 体重 (kg) | C9: 骨格筋量 (kg) | D9: 骨格筋量/体重 (%) | E9: 体脂肪量 (kg) | F9: 体脂肪率 (%)
A10: =入力用!B3 -> 26/3 | B10: =入力用!G3 -> 55.3 | C10: =入力用!G16 -> 25.3 | D10: =入力用!G29 -> 45.8 | E10: =入力用!G42 -> 10.2 | F10: =入力用!G55 -> 18.5
A11: =入力用!B4 -> 26/4 | B11: =入力用!G4 -> 55.2 | C11: =入力用!G17 -> 25.2 | D11: =入力用!G30 -> 45.7 | E11: =入力用!G43 -> 10.5 | F11: =入力用!G56 -> 19
A12: =入力用!B5 -> 26/5 | B12: =入力用!G5 -> 54.8 | C12: =入力用!G18 -> 24.8 | D12: =入力用!G31 -> 45.3 | E12: =入力用!G44 -> 10.4 | F12: =入力用!G57 -> 19
A13: =入力用!B6 -> 26/6 | B13: =入力用!G6 -> 0 | C13: =入力用!G19 -> 0 | D13: =入力用!G32 -> #DIV/0! | E13: =入力用!G45 -> 0 | F13: =入力用!G58 -> 0
A14: =入力用!B7 -> 26/7 | B14: =入力用!G7 -> 0 | C14: =入力用!G20 -> 0 | D14: =入力用!G33 -> #DIV/0! | E14: =入力用!G46 -> 0 | F14: =入力用!G59 -> 0
A15: =入力用!B8 -> 26/8 | B15: =入力用!G8 -> 0 | C15: =入力用!G21 -> 0 | D15: =入力用!G34 -> #DIV/0! | E15: =入力用!G47 -> 0 | F15: =入力用!G60 -> 0
A16: =入力用!B9 -> 26/9 | B16: =入力用!G9 -> 0 | C16: =入力用!G22 -> 0 | D16: =入力用!G35 -> #DIV/0! | E16: =入力用!G48 -> 0 | F16: =入力用!G61 -> 0
A17: =入力用!B10 -> 26/10 | B17: =入力用!G10 -> 0 | C17: =入力用!G23 -> 0 | D17: =入力用!G36 -> #DIV/0! | E17: =入力用!G49 -> 0 | F17: =入力用!G62 -> 0
A18: =入力用!B11 -> 26/11 | B18: =入力用!G11 -> 0 | C18: =入力用!G24 -> 0 | D18: =入力用!G37 -> #DIV/0! | E18: =入力用!G50 -> 0 | F18: =入力用!G63 -> 0
A19: =入力用!B12 -> 26/12 | B19: =入力用!G12 -> 0 | C19: =入力用!G25 -> 0 | D19: =入力用!G38 -> #DIV/0! | E19: =入力用!G51 -> 0 | F19: =入力用!G64 -> 0
A20: =入力用!B13 -> 27/1 | B20: =入力用!G13 -> 0 | C20: =入力用!G26 -> 0 | D20: =入力用!G39 -> #DIV/0! | E20: =入力用!G52 -> 0 | F20: =入力用!G65 -> 0
A21: =入力用!B15 -> 27/3 | B21: =入力用!G15 -> 0 | C21: =入力用!G28 -> 0 | D21: =入力用!G41 -> #DIV/0! | E21: =入力用!G54 -> 0 | F21: =入力用!G67 -> 0

Sheet 藤井
A2: NSSU Soft tennis Team Inbody Feedback Sheet
A8: 氏名： | B8: =入力用!I2 -> 藤井真菜 | C8: 性別： | D8: =入力用!AG2 -> 女
A9: 測定日 | B9: 体重 (kg) | C9: 骨格筋量 (kg) | D9: 骨格筋量/体重 (%) | E9: 体脂肪量 (kg) | F9: 体脂肪率 (%)
A10: =入力用!B3 -> 26/3 | B10: =入力用!I3 -> 59.6 | C10: =入力用!I16 -> 26 | D10: =入力用!I29 -> 43.6 | E10: =入力用!I42 -> 12.5 | F10: =入力用!I55 -> 21
A11: =入力用!B4 -> 26/4 | B11: =入力用!I4 -> 60.6 | C11: =入力用!I17 -> 25.8 | D11: =入力用!I30 -> 42.6 | E11: =入力用!I43 -> 14.4 | F11: =入力用!I56 -> 23.7
A12: =入力用!B5 -> 26/5 | B12: =入力用!I5 -> 0 | C12: =入力用!I18 -> 0 | D12: =入力用!I31 -> #DIV/0! | E12: =入力用!I44 -> 0 | F12: =入力用!I57 -> 0
A13: =入力用!B6 -> 26/6 | B13: =入力用!I6 -> 0 | C13: =入力用!I19 -> 0 | D13: =入力用!I32 -> #DIV/0! | E13: =入力用!I45 -> 0 | F13: =入力用!I58 -> 0
A14: =入力用!B7 -> 26/7 | B14: =入力用!I7 -> 0 | C14: =入力用!I20 -> 0 | D14: =入力用!I33 -> #DIV/0! | E14: =入力用!I46 -> 0 | F14: =入力用!I59 -> 0
A15: =入力用!B8 -> 26/8 | B15: =入力用!I8 -> 0 | C15: =入力用!I21 -> 0 | D15: =入力用!I34 -> #DIV/0! | E15: =入力用!I47 -> 0 | F15: =入力用!I60 -> 0
A16: =入力用!B9 -> 26/9 | B16: =入力用!I9 -> 0 | C16: =入力用!I22 -> 0 | D16: =入力用!I35 -> #DIV/0! | E16: =入力用!I48 -> 0 | F16: =入力用!I61 -> 0
A17: =入力用!B10 -> 26/10 | B17: =入力用!I10 -> 0 | C17: =入力用!I23 -> 0 | D17: =入力用!I36 -> #DIV/0! | E17: =入力用!I49 -> 0 | F17: =入力用!I62 -> 0
A18: =入力用!B11 -> 26/11 | B18: =入力用!I11 -> 0 | C18: =入力用!I24 -> 0 | D18: =入力用!I37 -> #DIV/0! | E18: =入力用!I50 -> 0 | F18: =入力用!I63 -> 0
A19: =入力用!B12 -> 26/12 | B19: =入力用!I12 -> 0 | C19: =入力用!I25 -> 0 | D19: =入力用!I38 -> #DIV/0! | E19: =入力用!I51 -> 0 | F19: =入力用!I64 -> 0
A20: =入力用!B13 -> 27/1 | B20: =入力用!I13 -> 0 | C20: =入力用!I26 -> 0 | D20: =入力用!I39 -> #DIV/0! | E20: =入力用!I52 -> 0 | F20: =入力用!I65 -> 0
A21: =入力用!B15 -> 27/3 | B21: =入力用!I15 -> 0 | C21: =入力用!I28 -> 0 | D21: =入力用!I41 -> #DIV/0! | E21: =入力用!I54 -> 0 | F21: =入力用!I67 -> 0

Sheet 松岡
A2: NSSU Soft tennis Team Inbody Feedback Sheet
A8: 氏名： | B8: =入力用!J2 -> 松岡琴美 | C8: 性別： | D8: =入力用!AG2 -> 女
A9: 測定日 | B9: 体重 (kg) | C9: 骨格筋量 (kg) | D9: 骨格筋量/体重 (%) | E9: 体脂肪量 (kg) | F9: 体脂肪率 (%)
A10: =入力用!B3 -> 26/3 | B10: =入力用!J3 -> 51 | C10: =入力用!J16 -> 21.3 | D10: =入力用!J29 -> 41.8 | E10: =入力用!J42 -> 12.3 | F10: =入力用!J55 -> 24.1
A11: =入力用!B4 -> 26/4 | B11: =入力用!J4 -> 52.2 | C11: =入力用!J17 -> 21.3 | D11: =入力用!J30 -> 40.8 | E11: =入力用!J43 -> 13.8 | F11: =入力用!J56 -> 26.4
A12: =入力用!B5 -> 26/5 | B12: =入力用!J5 -> 51.4 | C12: =入力用!J18 -> 21.8 | D12: =入力用!J31 -> 42.4 | E12: =入力用!J44 -> 12.2 | F12: =入力用!J57 -> 23.7
A13: =入力用!B6 -> 26/6 | B13: =入力用!J6 -> 0 | C13: =入力用!J19 -> 0 | D13: =入力用!J32 -> #DIV/0! | E13: =入力用!J45 -> 0 | F13: =入力用!J58 -> 0
A14: =入力用!B7 -> 26/7 | B14: =入力用!J7 -> 0 | C14: =入力用!J20 -> 0 | D14: =入力用!J33 -> #DIV/0! | E14: =入力用!J46 -> 0 | F14: =入力用!J59 -> 0
A15: =入力用!B8 -> 26/8 | B15: =入力用!J8 -> 0 | C15: =入力用!J21 -> 0 | D15: =入力用!J34 -> #DIV/0! | E15: =入力用!J47 -> 0 | F15: =入力用!J60 -> 0
A16: =入力用!B9 -> 26/9 | B16: =入力用!J9 -> 0 | C16: =入力用!J22 -> 0 | D16: =入力用!J35 -> #DIV/0! | E16: =入力用!J48 -> 0 | F16: =入力用!J61 -> 0
A17: =入力用!B10 -> 26/10 | B17: =入力用!J10 -> 0 | C17: =入力用!J23 -> 0 | D17: =入力用!J36 -> #DIV/0! | E17: =入力用!J49 -> 0 | F17: =入力用!J62 -> 0
A18: =入力用!B11 -> 26/11 | B18: =入力用!J11 -> 0 | C18: =入力用!J24 -> 0 | D18: =入力用!J37 -> #DIV/0! | E18: =入力用!J50 -> 0 | F18: =入力用!J63 -> 0
A19: =入力用!B12 -> 26/12 | B19: =入力用!J12 -> 0 | C19: =入力用!J25 -> 0 | D19: =入力用!J38 -> #DIV/0! | E19: =入力用!J51 -> 0 | F19: =入力用!J64 -> 0
A20: =入力用!B13 -> 27/1 | B20: =入力用!J13 -> 0 | C20: =入力用!J26 -> 0 | D20: =入力用!J39 -> #DIV/0! | E20: =入力用!J52 -> 0 | F20: =入力用!J65 -> 0
A21: =入力用!B15 -> 27/3 | B21: =入力用!J15 -> 0 | C21: =入力用!J28 -> 0 | D21: =入力用!J41 -> #DIV/0! | E21: =入力用!J54 -> 0 | F21: =入力用!J67 -> 0

Sheet 吉木
A2: NSSU Soft tennis Team Inbody Feedback Sheet
A8: 氏名： | B8: =入力用!K2 -> 吉木理彩 | C8: 性別： | D8: =入力用!AG2 -> 女
A9: 測定日 | B9: 体重 (kg) | C9: 骨格筋量 (kg) | D9: 骨格筋量/体重 (%) | E9: 体脂肪量 (kg) | F9: 体脂肪率 (%)
A10: =入力用!B3 -> 26/3 | B10: =入力用!K3 -> 56.4 | C10: =入力用!K16 -> 23.4 | D10: =入力用!K29 -> 41.5 | E10: =入力用!K42 -> 14.2 | F10: =入力用!K55 -> 25.2
A11: =入力用!B4 -> 26/4 | B11: =入力用!K4 -> 57.1 | C11: =入力用!K17 -> 23.6 | D11: =入力用!K30 -> 41.3 | E11: =入力用!K43 -> 14.5 | F11: =入力用!K56 -> 25.4
A12: =入力用!B5 -> 26/5 | B12: =入力用!K5 -> 54.9 | C12: =入力用!K18 -> 23.2 | D12: =入力用!K31 -> 42.3 | E12: =入力用!K44 -> 13.2 | F12: =入力用!K57 -> 24
A13: =入力用!B6 -> 26/6 | B13: =入力用!K6 -> 0 | C13: =入力用!K19 -> 0 | D13: =入力用!K32 -> #DIV/0! | E13: =入力用!K45 -> 0 | F13: =入力用!K58 -> 0
A14: =入力用!B7 -> 26/7 | B14: =入力用!K7 -> 0 | C14: =入力用!K20 -> 0 | D14: =入力用!K33 -> #DIV/0! | E14: =入力用!K46 -> 0 | F14: =入力用!K59 -> 0
A15: =入力用!B8 -> 26/8 | B15: =入力用!K8 -> 0 | C15: =入力用!K21 -> 0 | D15: =入力用!K34 -> #DIV/0! | E15: =入力用!K47 -> 0 | F15: =入力用!K60 -> 0
A16: =入力用!B9 -> 26/9 | B16: =入力用!K9 -> 0 | C16: =入力用!K22 -> 0 | D16: =入力用!K35 -> #DIV/0! | E16: =入力用!K48 -> 0 | F16: =入力用!K61 -> 0
A17: =入力用!B10 -> 26/10 | B17: =入力用!K10 -> 0 | C17: =入力用!K23 -> 0 | D17: =入力用!K36 -> #DIV/0! | E17: =入力用!K49 -> 0 | F17: =入力用!K62 -> 0
A18: =入力用!B11 -> 26/11 | B18: =入力用!K11 -> 0 | C18: =入力用!K24 -> 0 | D18: =入力用!K37 -> #DIV/0! | E18: =入力用!K50 -> 0 | F18: =入力用!K63 -> 0
A19: =入力用!B12 -> 26/12 | B19: =入力用!K12 -> 0 | C19: =入力用!K25 -> 0 | D19: =入力用!K38 -> #DIV/0! | E19: =入力用!K51 -> 0 | F19: =入力用!K64 -> 0
A20: =入力用!B13 -> 27/1 | B20: =入力用!K13 -> 0 | C20: =入力用!K26 -> 0 | D20: =入力用!K39 -> #DIV/0! | E20: =入力用!K52 -> 0 | F20: =入力用!K65 -> 0
A21: =入力用!B15 -> 27/3 | B21: =入力用!K15 -> 0 | C21: =入力用!K28 -> 0 | D21: =入力用!K41 -> #DIV/0! | E21: =入力用!K54 -> 0 | F21: =入力用!K67 -> 0

Sheet 渡邉
A2: NSSU Soft tennis Team Inbody Feedback Sheet
A8: 氏名： | B8: =入力用!L2 -> 渡邉妃菜乃 | C8: 性別： | D8: =入力用!AG2 -> 女
A9: 測定日 | B9: 体重 (kg) | C9: 骨格筋量 (kg) | D9: 骨格筋量/体重 (%) | E9: 体脂肪量 (kg) | F9: 体脂肪率 (%)
A10: =入力用!B3 -> 26/3 | B10: =入力用!L3 -> 49.7 | C10: =入力用!L16 -> 19.3 | D10: =入力用!L29 -> 38.8 | E10: =入力用!L42 -> 14.5 | F10: =入力用!L55 -> 29.2
A11: =入力用!B4 -> 26/4 | B11: =入力用!L4 -> 49.5 | C11: =入力用!L17 -> 19.1 | D11: =入力用!L30 -> 38.6 | E11: =入力用!L43 -> 14.7 | F11: =入力用!L56 -> 29.6
A12: =入力用!B5 -> 26/5 | B12: =入力用!L5 -> 49.6 | C12: =入力用!L18 -> 19.7 | D12: =入力用!L31 -> 39.7 | E12: =入力用!L44 -> 13.7 | F12: =入力用!L57 -> 27.5
A13: =入力用!B6 -> 26/6 | B13: =入力用!L6 -> 0 | C13: =入力用!L19 -> 0 | D13: =入力用!L32 -> #DIV/0! | E13: =入力用!L45 -> 0 | F13: =入力用!L58 -> 0
A14: =入力用!B7 -> 26/7 | B14: =入力用!L7 -> 0 | C14: =入力用!L20 -> 0 | D14: =入力用!L33 -> #DIV/0! | E14: =入力用!L46 -> 0 | F14: =入力用!L59 -> 0
A15: =入力用!B8 -> 26/8 | B15: =入力用!L8 -> 0 | C15: =入力用!L21 -> 0 | D15: =入力用!L34 -> #DIV/0! | E15: =入力用!L47 -> 0 | F15: =入力用!L60 -> 0
A16: =入力用!B9 -> 26/9 | B16: =入力用!L9 -> 0 | C16: =入力用!L22 -> 0 | D16: =入力用!L35 -> #DIV/0! | E16: =入力用!L48 -> 0 | F16: =入力用!L61 -> 0
A17: =入力用!B10 -> 26/10 | B17: =入力用!L10 -> 0 | C17: =入力用!L23 -> 0 | D17: =入力用!L36 -> #DIV/0! | E17: =入力用!L49 -> 0 | F17: =入力用!L62 -> 0
A18: =入力用!B11 -> 26/11 | B18: =入力用!L11 -> 0 | C18: =入力用!L24 -> 0 | D18: =入力用!L37 -> #DIV/0! | E18: =入力用!L50 -> 0 | F18: =入力用!L63 -> 0
A19: =入力用!B12 -> 26/12 | B19: =入力用!L12 -> 0 | C19: =入力用!L25 -> 0 | D19: =入力用!L38 -> #DIV/0! | E19: =入力用!L51 -> 0 | F19: =入力用!L64 -> 0
A20: =入力用!B13 -> 27/1 | B20: =入力用!L13 -> 0 | C20: =入力用!L26 -> 0 | D20: =入力用!L39 -> #DIV/0! | E20: =入力用!L52 -> 0 | F20: =入力用!L65 -> 0
A21: =入力用!B15 -> 27/3 | B21: =入力用!L15 -> 0 | C21: =入力用!L28 -> 0 | D21: =入力用!L41 -> #DIV/0! | E21: =入力用!L54 -> 0 | F21: =入力用!L67 -> 0

Sheet 岩田
A2: NSSU Soft tennis Team Inbody Feedback Sheet
A8: 氏名： | B8: =入力用!M2 -> 岩田愛美 | C8: 性別： | D8: 女
A9: 測定日 | B9: 体重 (kg) | C9: 骨格筋量 (kg) | D9: 骨格筋量/体重 (%) | E9: 体脂肪量 (kg) | F9: 体脂肪率 (%)
A10: =入力用!B3 -> 26/3 | B10: =入力用!M3 -> 51.9 | C10: =入力用!M16 -> 23.4 | D10: =入力用!M29 -> 45.1 | E10: =入力用!M42 -> 10.1 | F10: =入力用!M55 -> 19.4
A11: =入力用!B4 -> 26/4 | B11: =入力用!M4 -> 52.8 | C11: =入力用!M17 -> 24.2 | D11: =入力用!M30 -> 45.8 | E11: =入力用!M43 -> 9.8 | F11: =入力用!M56 -> 18.5
A12: =入力用!B5 -> 26/5 | B12: =入力用!M5 -> 53.4 | C12: =入力用!M18 -> 24.4 | D12: =入力用!M31 -> 45.7 | E12: =入力用!M44 -> 10 | F12: =入力用!M57 -> 18.7
A13: =入力用!B6 -> 26/6 | B13: =入力用!M6 -> 0 | C13: =入力用!M19 -> 0 | D13: =入力用!M32 -> #DIV/0! | E13: =入力用!M45 -> 0 | F13: =入力用!M58 -> 0
A14: =入力用!B7 -> 26/7 | B14: =入力用!M7 -> 0 | C14: =入力用!M20 -> 0 | D14: =入力用!M33 -> #DIV/0! | E14: =入力用!M46 -> 0 | F14: =入力用!M59 -> 0
A15: =入力用!B8 -> 26/8 | B15: =入力用!M8 -> 0 | C15: =入力用!M21 -> 0 | D15: =入力用!M34 -> #DIV/0! | E15: =入力用!M47 -> 0 | F15: =入力用!M60 -> 0
A16: =入力用!B9 -> 26/9 | B16: =入力用!M9 -> 0 | C16: =入力用!M22 -> 0 | D16: =入力用!M35 -> #DIV/0! | E16: =入力用!M48 -> 0 | F16: =入力用!M61 -> 0
A17: =入力用!B10 -> 26/10 | B17: =入力用!M10 -> 0 | C17: =入力用!M23 -> 0 | D17: =入力用!M36 -> #DIV/0! | E17: =入力用!M49 -> 0 | F17: =入力用!M62 -> 0
A18: =入力用!B11 -> 26/11 | B18: =入力用!M11 -> 0 | C18: =入力用!M24 -> 0 | D18: =入力用!M37 -> #DIV/0! | E18: =入力用!M50 -> 0 | F18: =入力用!M63 -> 0
A19: =入力用!B12 -> 26/12 | B19: =入力用!M12 -> 0 | C19: =入力用!M25 -> 0 | D19: =入力用!M38 -> #DIV/0! | E19: =入力用!M51 -> 0 | F19: =入力用!M64 -> 0
A20: =入力用!B13 -> 27/1 | B20: =入力用!M13 -> 0 | C20: =入力用!M26 -> 0 | D20: =入力用!M39 -> #DIV/0! | E20: =入力用!M52 -> 0 | F20: =入力用!M65 -> 0
A21: =入力用!B15 -> 27/3 | B21: =入力用!M15 -> 0 | C21: =入力用!M28 -> 0 | D21: =入力用!M41 -> #DIV/0! | E21: =入力用!M54 -> 0 | F21: =入力用!M67 -> 0

Sheet 内田
A2: NSSU Soft tennis Team Inbody Feedback Sheet
A8: 氏名： | B8: =入力用!N2 -> 内田真愛 | C8: 性別： | D8: 女
A9: 測定日 | B9: 体重 (kg) | C9: 骨格筋量 (kg) | D9: 骨格筋量/体重 (%) | E9: 体脂肪量 (kg) | F9: 体脂肪率 (%)
A10: =入力用!B3 -> 26/3 | B10: =入力用!N3 -> 54.6 | C10: =入力用!N16 -> 23.3 | D10: =入力用!N29 -> 42.7 | E10: =入力用!N42 -> 12.5 | F10: =入力用!N55 -> 22.8
A11: =入力用!B4 -> 26/4 | B11: =入力用!N4 -> 55.4 | C11: =入力用!N17 -> 24.4 | D11: =入力用!N30 -> 44 | E11: =入力用!N43 -> 11.5 | F11: =入力用!N56 -> 20.8
A12: =入力用!B5 -> 26/5 | B12: =入力用!N5 -> 55.3 | C12: =入力用!N18 -> 25.2 | D12: =入力用!N31 -> 45.6 | E12: =入力用!N44 -> 10.2 | F12: =入力用!N57 -> 18.4
A13: =入力用!B6 -> 26/6 | B13: =入力用!N6 -> 0 | C13: =入力用!N19 -> 0 | D13: =入力用!N32 -> #DIV/0! | E13: =入力用!N45 -> 0 | F13: =入力用!N58 -> 0
A14: =入力用!B7 -> 26/7 | B14: =入力用!N7 -> 0 | C14: =入力用!N20 -> 0 | D14: =入力用!N33 -> #DIV/0! | E14: =入力用!N46 -> 0 | F14: =入力用!N59 -> 0
A15: =入力用!B8 -> 26/8 | B15: =入力用!N8 -> 0 | C15: =入力用!N21 -> 0 | D15: =入力用!N34 -> #DIV/0! | E15: =入力用!N47 -> 0 | F15: =入力用!N60 -> 0
A16: =入力用!B9 -> 26/9 | B16: =入力用!N9 -> 0 | C16: =入力用!N22 -> 0 | D16: =入力用!N35 -> #DIV/0! | E16: =入力用!N48 -> 0 | F16: =入力用!N61 -> 0
A17: =入力用!B10 -> 26/10 | B17: =入力用!N10 -> 0 | C17: =入力用!N23 -> 0 | D17: =入力用!N36 -> #DIV/0! | E17: =入力用!N49 -> 0 | F17: =入力用!N62 -> 0
A18: =入力用!B11 -> 26/11 | B18: =入力用!N11 -> 0 | C18: =入力用!N24 -> 0 | D18: =入力用!N37 -> #DIV/0! | E18: =入力用!N50 -> 0 | F18: =入力用!N63 -> 0
A19: =入力用!B12 -> 26/12 | B19: =入力用!N12 -> 0 | C19: =入力用!N25 -> 0 | D19: =入力用!N38 -> #DIV/0! | E19: =入力用!N51 -> 0 | F19: =入力用!N64 -> 0
A20: =入力用!B13 -> 27/1 | B20: =入力用!N13 -> 0 | C20: =入力用!N26 -> 0 | D20: =入力用!N39 -> #DIV/0! | E20: =入力用!N52 -> 0 | F20: =入力用!N65 -> 0
A21: =入力用!B15 -> 27/3 | B21: =入力用!N15 -> 0 | C21: =入力用!N28 -> 0 | D21: =入力用!N41 -> #DIV/0! | E21: =入力用!N54 -> 0 | F21: =入力用!N67 -> 0

Sheet 徳山
A2: NSSU Soft tennis Team Inbody Feedback Sheet
A8: 氏名： | B8: =入力用!O2 -> 徳山暖枝 | C8: 性別： | D8: 女
A9: 測定日 | B9: 体重 (kg) | C9: 骨格筋量 (kg) | D9: 骨格筋量/体重 (%) | E9: 体脂肪量 (kg) | F9: 体脂肪率 (%)
A10: =入力用!B3 -> 26/3 | B10: =入力用!O3 -> 61.4 | C10: =入力用!O16 -> 23.3 | D10: =入力用!O29 -> 37.9 | E10: =入力用!O42 -> 19.4 | F10: =入力用!O55 -> 31.6
A11: =入力用!B4 -> 26/4 | B11: =入力用!O4 -> 62.7 | C11: =入力用!O17 -> 23.5 | D11: =入力用!O30 -> 37.5 | E11: =入力用!O43 -> 20.1 | F11: =入力用!O56 -> 32.1
A12: =入力用!B5 -> 26/5 | B12: =入力用!O5 -> 62.3 | C12: =入力用!O18 -> 23.2 | D12: =入力用!O31 -> 37.2 | E12: =入力用!O44 -> 20.8 | F12: =入力用!O57 -> 33.3
A13: =入力用!B6 -> 26/6 | B13: =入力用!O6 -> 0 | C13: =入力用!O19 -> 0 | D13: =入力用!O32 -> #DIV/0! | E13: =入力用!O45 -> 0 | F13: =入力用!O58 -> 0
A14: =入力用!B7 -> 26/7 | B14: =入力用!O7 -> 0 | C14: =入力用!O20 -> 0 | D14: =入力用!O33 -> #DIV/0! | E14: =入力用!O46 -> 0 | F14: =入力用!O59 -> 0
A15: =入力用!B8 -> 26/8 | B15: =入力用!O8 -> 0 | C15: =入力用!O21 -> 0 | D15: =入力用!O34 -> #DIV/0! | E15: =入力用!O47 -> 0 | F15: =入力用!O60 -> 0
A16: =入力用!B9 -> 26/9 | B16: =入力用!O9 -> 0 | C16: =入力用!O22 -> 0 | D16: =入力用!O35 -> #DIV/0! | E16: =入力用!O48 -> 0 | F16: =入力用!O61 -> 0
A17: =入力用!B10 -> 26/10 | B17: =入力用!O10 -> 0 | C17: =入力用!O23 -> 0 | D17: =入力用!O36 -> #DIV/0! | E17: =入力用!O49 -> 0 | F17: =入力用!O62 -> 0
A18: =入力用!B11 -> 26/11 | B18: =入力用!O11 -> 0 | C18: =入力用!O24 -> 0 | D18: =入力用!O37 -> #DIV/0! | E18: =入力用!O50 -> 0 | F18: =入力用!O63 -> 0
A19: =入力用!B12 -> 26/12 | B19: =入力用!O12 -> 0 | C19: =入力用!O25 -> 0 | D19: =入力用!O38 -> #DIV/0! | E19: =入力用!O51 -> 0 | F19: =入力用!O64 -> 0
A20: =入力用!B13 -> 27/1 | B20: =入力用!O13 -> 0 | C20: =入力用!O26 -> 0 | D20: =入力用!O39 -> #DIV/0! | E20: =入力用!O52 -> 0 | F20: =入力用!O65 -> 0
A21: =入力用!B15 -> 27/3 | B21: =入力用!O15 -> 0 | C21: =入力用!O28 -> 0 | D21: =入力用!O41 -> #DIV/0! | E21: =入力用!O54 -> 0 | F21: =入力用!O67 -> 0

Sheet 中村
A2: NSSU Soft tennis Team Inbody Feedback Sheet
A8: 氏名： | B8: =入力用!P2 -> 中村楓芽 | C8: 性別： | D8: 女
A9: 測定日 | B9: 体重 (kg) | C9: 骨格筋量 (kg) | D9: 骨格筋量/体重 (%) | E9: 体脂肪量 (kg) | F9: 体脂肪率 (%)
A10: =入力用!B3 -> 26/3 | B10: =入力用!P3 -> 56 | C10: =入力用!P16 -> 24.6 | D10: =入力用!P29 -> 43.9 | E10: =入力用!P42 -> 12.3 | F10: =入力用!P55 -> 21.9
A11: =入力用!B4 -> 26/4 | B11: =入力用!P4 -> 56.3 | C11: =入力用!P17 -> 24.1 | D11: =入力用!P30 -> 42.8 | E11: =入力用!P43 -> 13.6 | F11: =入力用!P56 -> 24.1
A12: =入力用!B5 -> 26/5 | B12: =入力用!P5 -> 55.4 | C12: =入力用!P18 -> 23.7 | D12: =入力用!P31 -> 42.8 | E12: =入力用!P44 -> 13.3 | F12: =入力用!P57 -> 24
A13: =入力用!B6 -> 26/6 | B13: =入力用!P6 -> 0 | C13: =入力用!P19 -> 0 | D13: =入力用!P32 -> #DIV/0! | E13: =入力用!P45 -> 0 | F13: =入力用!P58 -> 0
A14: =入力用!B7 -> 26/7 | B14: =入力用!P7 -> 0 | C14: =入力用!P20 -> 0 | D14: =入力用!P33 -> #DIV/0! | E14: =入力用!P46 -> 0 | F14: =入力用!P59 -> 0
A15: =入力用!B8 -> 26/8 | B15: =入力用!P8 -> 0 | C15: =入力用!P21 -> 0 | D15: =入力用!P34 -> #DIV/0! | E15: =入力用!P47 -> 0 | F15: =入力用!P60 -> 0
A16: =入力用!B9 -> 26/9 | B16: =入力用!P9 -> 0 | C16: =入力用!P22 -> 0 | D16: =入力用!P35 -> #DIV/0! | E16: =入力用!P48 -> 0 | F16: =入力用!P61 -> 0
A17: =入力用!B10 -> 26/10 | B17: =入力用!P10 -> 0 | C17: =入力用!P23 -> 0 | D17: =入力用!P36 -> #DIV/0! | E17: =入力用!P49 -> 0 | F17: =入力用!P62 -> 0
A18: =入力用!B11 -> 26/11 | B18: =入力用!P11 -> 0 | C18: =入力用!P24 -> 0 | D18: =入力用!P37 -> #DIV/0! | E18: =入力用!P50 -> 0 | F18: =入力用!P63 -> 0
A19: =入力用!B12 -> 26/12 | B19: =入力用!P12 -> 0 | C19: =入力用!P25 -> 0 | D19: =入力用!P38 -> #DIV/0! | E19: =入力用!P51 -> 0 | F19: =入力用!P64 -> 0
A20: =入力用!B13 -> 27/1 | B20: =入力用!P13 -> 0 | C20: =入力用!P26 -> 0 | D20: =入力用!P39 -> #DIV/0! | E20: =入力用!P52 -> 0 | F20: =入力用!P65 -> 0
A21: =入力用!B15 -> 27/3 | B21: =入力用!P15 -> 0 | C21: =入力用!P28 -> 0 | D21: =入力用!P41 -> #DIV/0! | E21: =入力用!P54 -> 0 | F21: =入力用!P67 -> 0

Sheet 向山
A2: NSSU Soft tennis Team Inbody Feedback Sheet
A8: 氏名： | B8: =入力用!Q2 -> 向山せら | C8: 性別： | D8: 女
A9: 測定日 | B9: 体重 (kg) | C9: 骨格筋量 (kg) | D9: 骨格筋量/体重 (%) | E9: 体脂肪量 (kg) | F9: 体脂肪率 (%)
A10: =入力用!B3 -> 26/3 | B10: =入力用!Q3 -> 53.3 | C10: =入力用!Q16 -> 23.2 | D10: =入力用!Q29 -> 43.5 | E10: =入力用!Q42 -> 11.9 | F10: =入力用!Q55 -> 22.4
A11: =入力用!B4 -> 26/4 | B11: =入力用!Q4 -> 54.4 | C11: =入力用!Q17 -> 23.6 | D11: =入力用!Q30 -> 43.4 | E11: =入力用!Q43 -> 12.3 | F11: =入力用!Q56 -> 22.6
A12: =入力用!B5 -> 26/5 | B12: =入力用!Q5 -> 53.1 | C12: =入力用!Q18 -> 23.9 | D12: =入力用!Q31 -> 45 | E12: =入力用!Q44 -> 10.7 | F12: =入力用!Q57 -> 20.1
A13: =入力用!B6 -> 26/6 | B13: =入力用!Q6 -> 0 | C13: =入力用!Q19 -> 0 | D13: =入力用!Q32 -> #DIV/0! | E13: =入力用!Q45 -> 0 | F13: =入力用!Q58 -> 0
A14: =入力用!B7 -> 26/7 | B14: =入力用!Q7 -> 0 | C14: =入力用!Q20 -> 0 | D14: =入力用!Q33 -> #DIV/0! | E14: =入力用!Q46 -> 0 | F14: =入力用!Q59 -> 0
A15: =入力用!B8 -> 26/8 | B15: =入力用!Q8 -> 0 | C15: =入力用!Q21 -> 0 | D15: =入力用!Q34 -> #DIV/0! | E15: =入力用!Q47 -> 0 | F15: =入力用!Q60 -> 0
A16: =入力用!B9 -> 26/9 | B16: =入力用!Q9 -> 0 | C16: =入力用!Q22 -> 0 | D16: =入力用!Q35 -> #DIV/0! | E16: =入力用!Q48 -> 0 | F16: =入力用!Q61 -> 0
A17: =入力用!B10 -> 26/10 | B17: =入力用!Q10 -> 0 | C17: =入力用!Q23 -> 0 | D17: =入力用!Q36 -> #DIV/0! | E17: =入力用!Q49 -> 0 | F17: =入力用!Q62 -> 0
A18: =入力用!B11 -> 26/11 | B18: =入力用!Q11 -> 0 | C18: =入力用!Q24 -> 0 | D18: =入力用!Q37 -> #DIV/0! | E18: =入力用!Q50 -> 0 | F18: =入力用!Q63 -> 0
A19: =入力用!B12 -> 26/12 | B19: =入力用!Q12 -> 0 | C19: =入力用!Q25 -> 0 | D19: =入力用!Q38 -> #DIV/0! | E19: =入力用!Q51 -> 0 | F19: =入力用!Q64 -> 0
A20: =入力用!B13 -> 27/1 | B20: =入力用!Q13 -> 0 | C20: =入力用!Q26 -> 0 | D20: =入力用!Q39 -> #DIV/0! | E20: =入力用!Q52 -> 0 | F20: =入力用!Q65 -> 0
A21: =入力用!B15 -> 27/3 | B21: =入力用!Q15 -> 0 | C21: =入力用!Q28 -> 0 | D21: =入力用!Q41 -> #DIV/0! | E21: =入力用!Q54 -> 0 | F21: =入力用!Q67 -> 0

Sheet 山下
A2: NSSU Soft tennis Team Inbody Feedback Sheet
A8: 氏名： | B8: =入力用!R2 -> 山下永遠 | C8: 性別： | D8: 女
A9: 測定日 | B9: 体重 (kg) | C9: 骨格筋量 (kg) | D9: 骨格筋量/体重 (%) | E9: 体脂肪量 (kg) | F9: 体脂肪率 (%)
A10: =入力用!B3 -> 26/3 | B10: =入力用!R3 -> 66.6 | C10: =入力用!R16 -> 26.7 | D10: =入力用!R29 -> 40.1 | E10: =入力用!R42 -> 19 | F10: =入力用!R55 -> 28.6
A11: =入力用!B4 -> 26/4 | B11: =入力用!R4 -> 67.4 | C11: =入力用!R17 -> 27.1 | D11: =入力用!R30 -> 40.2 | E11: =入力用!R43 -> 19.2 | F11: =入力用!R56 -> 28.4
A12: =入力用!B5 -> 26/5 | B12: =入力用!R5 -> 67.5 | C12: =入力用!R18 -> 26.9 | D12: =入力用!R31 -> 39.9 | E12: =入力用!R44 -> 19.6 | F12: =入力用!R57 -> 29
A13: =入力用!B6 -> 26/6 | B13: =入力用!R6 -> 0 | C13: =入力用!R19 -> 0 | D13: =入力用!R32 -> #DIV/0! | E13: =入力用!R45 -> 0 | F13: =入力用!R58 -> 0
A14: =入力用!B7 -> 26/7 | B14: =入力用!R7 -> 0 | C14: =入力用!R20 -> 0 | D14: =入力用!R33 -> #DIV/0! | E14: =入力用!R46 -> 0 | F14: =入力用!R59 -> 0
A15: =入力用!B8 -> 26/8 | B15: =入力用!R8 -> 0 | C15: =入力用!R21 -> 0 | D15: =入力用!R34 -> #DIV/0! | E15: =入力用!R47 -> 0 | F15: =入力用!R60 -> 0
A16: =入力用!B9 -> 26/9 | B16: =入力用!R9 -> 0 | C16: =入力用!R22 -> 0 | D16: =入力用!R35 -> #DIV/0! | E16: =入力用!R48 -> 0 | F16: =入力用!R61 -> 0
A17: =入力用!B10 -> 26/10 | B17: =入力用!R10 -> 0 | C17: =入力用!R23 -> 0 | D17: =入力用!R36 -> #DIV/0! | E17: =入力用!R49 -> 0 | F17: =入力用!R62 -> 0
A18: =入力用!B11 -> 26/11 | B18: =入力用!R11 -> 0 | C18: =入力用!R24 -> 0 | D18: =入力用!R37 -> #DIV/0! | E18: =入力用!R50 -> 0 | F18: =入力用!R63 -> 0
A19: =入力用!B12 -> 26/12 | B19: =入力用!R12 -> 0 | C19: =入力用!R25 -> 0 | D19: =入力用!R38 -> #DIV/0! | E19: =入力用!R51 -> 0 | F19: =入力用!R64 -> 0
A20: =入力用!B13 -> 27/1 | B20: =入力用!R13 -> 0 | C20: =入力用!R26 -> 0 | D20: =入力用!R39 -> #DIV/0! | E20: =入力用!R52 -> 0 | F20: =入力用!R65 -> 0
A21: =入力用!B15 -> 27/3 | B21: =入力用!R15 -> 0 | C21: =入力用!R28 -> 0 | D21: =入力用!R41 -> #DIV/0! | E21: =入力用!R54 -> 0 | F21: =入力用!R67 -> 0

Sheet 池田
A2: NSSU Soft tennis Team Inbody Feedback Sheet
A8: 氏名： | B8: =入力用!S2 -> 池田朝花 | C8: 性別： | D8: 女
A9: 測定日 | B9: 体重 (kg) | C9: 骨格筋量 (kg) | D9: 骨格筋量/体重 (%) | E9: 体脂肪量 (kg) | F9: 体脂肪率 (%)
A10: =入力用!B3 -> 26/3 | B10: =入力用!S3 -> 52.7 | C10: =入力用!S16 -> 22.5 | D10: =入力用!S29 -> 42.7 | E10: =入力用!S42 -> 12 | F10: =入力用!S55 -> 22.7
A11: =入力用!B4 -> 26/4 | B11: =入力用!S4 -> 53.6 | C11: =入力用!S17 -> 24 | D11: =入力用!S30 -> 44.8 | E11: =入力用!S43 -> 10.8 | F11: =入力用!S56 -> 20.1
A12: =入力用!B5 -> 26/5 | B12: =入力用!S5 -> 53.1 | C12: =入力用!S18 -> 23.5 | D12: =入力用!S31 -> 44.3 | E12: =入力用!S44 -> 11.1 | F12: =入力用!S57 -> 20.8
A13: =入力用!B6 -> 26/6 | B13: =入力用!S6 -> 0 | C13: =入力用!S19 -> 0 | D13: =入力用!S32 -> #DIV/0! | E13: =入力用!S45 -> 0 | F13: =入力用!S58 -> 0
A14: =入力用!B7 -> 26/7 | B14: =入力用!S7 -> 0 | C14: =入力用!S20 -> 0 | D14: =入力用!S33 -> #DIV/0! | E14: =入力用!S46 -> 0 | F14: =入力用!S59 -> 0
A15: =入力用!B8 -> 26/8 | B15: =入力用!S8 -> 0 | C15: =入力用!S21 -> 0 | D15: =入力用!S34 -> #DIV/0! | E15: =入力用!S47 -> 0 | F15: =入力用!S60 -> 0
A16: =入力用!B9 -> 26/9 | B16: =入力用!S9 -> 0 | C16: =入力用!S22 -> 0 | D16: =入力用!S35 -> #DIV/0! | E16: =入力用!S48 -> 0 | F16: =入力用!S61 -> 0
A17: =入力用!B10 -> 26/10 | B17: =入力用!S10 -> 0 | C17: =入力用!S23 -> 0 | D17: =入力用!S36 -> #DIV/0! | E17: =入力用!S49 -> 0 | F17: =入力用!S62 -> 0
A18: =入力用!B11 -> 26/11 | B18: =入力用!S11 -> 0 | C18: =入力用!S24 -> 0 | D18: =入力用!S37 -> #DIV/0! | E18: =入力用!S50 -> 0 | F18: =入力用!S63 -> 0
A19: =入力用!B12 -> 26/12 | B19: =入力用!S12 -> 0 | C19: =入力用!S25 -> 0 | D19: =入力用!S38 -> #DIV/0! | E19: =入力用!S51 -> 0 | F19: =入力用!S64 -> 0
A20: =入力用!B13 -> 27/1 | B20: =入力用!S13 -> 0 | C20: =入力用!S26 -> 0 | D20: =入力用!S39 -> #DIV/0! | E20: =入力用!S52 -> 0 | F20: =入力用!S65 -> 0
A21: =入力用!B15 -> 27/3 | B21: =入力用!S15 -> 0 | C21: =入力用!S28 -> 0 | D21: =入力用!S41 -> #DIV/0! | E21: =入力用!S54 -> 0 | F21: =入力用!S67 -> 0

Sheet 後藤
A2: NSSU Soft tennis Team Inbody Feedback Sheet
A8: 氏名： | B8: =入力用!T2 -> 後藤和香奈 | C8: 性別： | D8: =入力用!AG2 -> 女
A9: 測定日 | B9: 体重 (kg) | C9: 骨格筋量 (kg) | D9: 骨格筋量/体重 (%) | E9: 体脂肪量 (kg) | F9: 体脂肪率 (%)
A10: =入力用!B3 -> 26/3 | B10: =入力用!T3 -> 63.3 | C10: =入力用!T16 -> 26.2 | D10: =入力用!T29 -> 41.4 | E10: =入力用!T42 -> 16.5 | F10: =入力用!T55 -> 26
A11: =入力用!B4 -> 26/4 | B11: =入力用!T4 -> 63 | C11: =入力用!T17 -> 25.9 | D11: =入力用!T30 -> 41.1 | E11: =入力用!T43 -> 17.1 | F11: =入力用!T56 -> 27.1
A12: =入力用!B5 -> 26/5 | B12: =入力用!T5 -> 63.5 | C12: =入力用!T18 -> 26.7 | D12: =入力用!T31 -> 42 | E12: =入力用!T44 -> 16 | F12: =入力用!T57 -> 25.2
A13: =入力用!B6 -> 26/6 | B13: =入力用!T6 -> 0 | C13: =入力用!T19 -> 0 | D13: =入力用!T32 -> #DIV/0! | E13: =入力用!T45 -> 0 | F13: =入力用!T58 -> 0
A14: =入力用!B7 -> 26/7 | B14: =入力用!T7 -> 0 | C14: =入力用!T20 -> 0 | D14: =入力用!T33 -> #DIV/0! | E14: =入力用!T46 -> 0 | F14: =入力用!T59 -> 0
A15: =入力用!B8 -> 26/8 | B15: =入力用!T8 -> 0 | C15: =入力用!T21 -> 0 | D15: =入力用!T34 -> #DIV/0! | E15: =入力用!T47 -> 0 | F15: =入力用!T60 -> 0
A16: =入力用!B9 -> 26/9 | B16: =入力用!T9 -> 0 | C16: =入力用!T22 -> 0 | D16: =入力用!T35 -> #DIV/0! | E16: =入力用!T48 -> 0 | F16: =入力用!T61 -> 0
A17: =入力用!B10 -> 26/10 | B17: =入力用!T10 -> 0 | C17: =入力用!T23 -> 0 | D17: =入力用!T36 -> #DIV/0! | E17: =入力用!T49 -> 0 | F17: =入力用!T62 -> 0
A18: =入力用!B11 -> 26/11 | B18: =入力用!T11 -> 0 | C18: =入力用!T24 -> 0 | D18: =入力用!T37 -> #DIV/0! | E18: =入力用!T50 -> 0 | F18: =入力用!T63 -> 0
A19: =入力用!B12 -> 26/12 | B19: =入力用!T12 -> 0 | C19: =入力用!T25 -> 0 | D19: =入力用!T38 -> #DIV/0! | E19: =入力用!T51 -> 0 | F19: =入力用!T64 -> 0
A20: =入力用!B13 -> 27/1 | B20: =入力用!T13 -> 0 | C20: =入力用!T26 -> 0 | D20: =入力用!T39 -> #DIV/0! | E20: =入力用!T52 -> 0 | F20: =入力用!T65 -> 0
A21: =入力用!B15 -> 27/3 | B21: =入力用!T15 -> 0 | C21: =入力用!T28 -> 0 | D21: =入力用!T41 -> #DIV/0! | E21: =入力用!T54 -> 0 | F21: =入力用!T67 -> 0

Sheet 津島
A2: NSSU Soft tennis Team Inbody Feedback Sheet
A8: 氏名： | B8: =入力用!U2 -> 津島世奈 | C8: 性別： | D8: =入力用!AG2 -> 女
A9: 測定日 | B9: 体重 (kg) | C9: 骨格筋量 (kg) | D9: 骨格筋量/体重 (%) | E9: 体脂肪量 (kg) | F9: 体脂肪率 (%)
A10: =入力用!B3 -> 26/3 | B10: =入力用!U3 -> 61.1 | C10: =入力用!U16 -> 26.1 | D10: =入力用!U29 -> 42.7 | E10: =入力用!U42 -> 14.6 | F10: =入力用!U55 -> 23.9
A11: =入力用!B4 -> 26/4 | B11: =入力用!U4 -> 60.2 | C11: =入力用!U17 -> 25.5 | D11: =入力用!U30 -> 42.4 | E11: =入力用!U43 -> 15 | F11: =入力用!U56 -> 24.9
A12: =入力用!B5 -> 26/5 | B12: =入力用!U5 -> 60.7 | C12: =入力用!U18 -> 25.9 | D12: =入力用!U31 -> 42.7 | E12: =入力用!U44 -> 14.9 | F12: =入力用!U57 -> 24.5
A13: =入力用!B6 -> 26/6 | B13: =入力用!U6 -> 0 | C13: =入力用!U19 -> 0 | D13: =入力用!U32 -> #DIV/0! | E13: =入力用!U45 -> 0 | F13: =入力用!U58 -> 0
A14: =入力用!B7 -> 26/7 | B14: =入力用!U7 -> 0 | C14: =入力用!U20 -> 0 | D14: =入力用!U33 -> #DIV/0! | E14: =入力用!U46 -> 0 | F14: =入力用!U59 -> 0
A15: =入力用!B8 -> 26/8 | B15: =入力用!U8 -> 0 | C15: =入力用!U21 -> 0 | D15: =入力用!U34 -> #DIV/0! | E15: =入力用!U47 -> 0 | F15: =入力用!U60 -> 0
A16: =入力用!B9 -> 26/9 | B16: =入力用!U9 -> 0 | C16: =入力用!U22 -> 0 | D16: =入力用!U35 -> #DIV/0! | E16: =入力用!U48 -> 0 | F16: =入力用!U61 -> 0
A17: =入力用!B10 -> 26/10 | B17: =入力用!U10 -> 0 | C17: =入力用!U23 -> 0 | D17: =入力用!U36 -> #DIV/0! | E17: =入力用!U49 -> 0 | F17: =入力用!U62 -> 0
A18: =入力用!B11 -> 26/11 | B18: =入力用!U11 -> 0 | C18: =入力用!U24 -> 0 | D18: =入力用!U37 -> #DIV/0! | E18: =入力用!U50 -> 0 | F18: =入力用!U63 -> 0
A19: =入力用!B12 -> 26/12 | B19: =入力用!U12 -> 0 | C19: =入力用!U25 -> 0 | D19: =入力用!U38 -> #DIV/0! | E19: =入力用!U51 -> 0 | F19: =入力用!U64 -> 0
A20: =入力用!B13 -> 27/1 | B20: =入力用!U13 -> 0 | C20: =入力用!U26 -> 0 | D20: =入力用!U39 -> #DIV/0! | E20: =入力用!U52 -> 0 | F20: =入力用!U65 -> 0
A21: =入力用!B15 -> 27/3 | B21: =入力用!U15 -> 0 | C21: =入力用!U28 -> 0 | D21: =入力用!U41 -> #DIV/0! | E21: =入力用!U54 -> 0 | F21: =入力用!U67 -> 0

Sheet 濱口
A2: NSSU Soft tennis Team Inbody Feedback Sheet
A8: 氏名： | B8: =入力用!V2 -> 濱口芽花 | C8: 性別： | D8: =入力用!AG2 -> 女
A9: 測定日 | B9: 体重 (kg) | C9: 骨格筋量 (kg) | D9: 骨格筋量/体重 (%) | E9: 体脂肪量 (kg) | F9: 体脂肪率 (%)
A10: =入力用!B3 -> 26/3 | B10: =入力用!V3 -> 61.9 | C10: =入力用!V16 -> 28 | D10: =入力用!V29 -> 45.2 | E10: =入力用!V42 -> 12.3 | F10: =入力用!V55 -> 19.8
A11: =入力用!B4 -> 26/4 | B11: =入力用!V4 -> 61.2 | C11: =入力用!V17 -> 27.4 | D11: =入力用!V30 -> 44.8 | E11: =入力用!V43 -> 12.8 | F11: =入力用!V56 -> 21
A12: =入力用!B5 -> 26/5 | B12: =入力用!V5 -> 60.4 | C12: =入力用!V18 -> 27.7 | D12: =入力用!V31 -> 45.9 | E12: =入力用!V44 -> 11.3 | F12: =入力用!V57 -> 18.7
A13: =入力用!B6 -> 26/6 | B13: =入力用!V6 -> 0 | C13: =入力用!V19 -> 0 | D13: =入力用!V32 -> #DIV/0! | E13: =入力用!V45 -> 0 | F13: =入力用!V58 -> 0
A14: =入力用!B7 -> 26/7 | B14: =入力用!V7 -> 0 | C14: =入力用!V20 -> 0 | D14: =入力用!V33 -> #DIV/0! | E14: =入力用!V46 -> 0 | F14: =入力用!V59 -> 0
A15: =入力用!B8 -> 26/8 | B15: =入力用!V8 -> 0 | C15: =入力用!V21 -> 0 | D15: =入力用!V34 -> #DIV/0! | E15: =入力用!V47 -> 0 | F15: =入力用!V60 -> 0
A16: =入力用!B9 -> 26/9 | B16: =入力用!V9 -> 0 | C16: =入力用!V22 -> 0 | D16: =入力用!V35 -> #DIV/0! | E16: =入力用!V48 -> 0 | F16: =入力用!V61 -> 0
A17: =入力用!B10 -> 26/10 | B17: =入力用!V10 -> 0 | C17: =入力用!V23 -> 0 | D17: =入力用!V36 -> #DIV/0! | E17: =入力用!V49 -> 0 | F17: =入力用!V62 -> 0
A18: =入力用!B11 -> 26/11 | B18: =入力用!V11 -> 0 | C18: =入力用!V24 -> 0 | D18: =入力用!V37 -> #DIV/0! | E18: =入力用!V50 -> 0 | F18: =入力用!V63 -> 0
A19: =入力用!B12 -> 26/12 | B19: =入力用!V12 -> 0 | C19: =入力用!V25 -> 0 | D19: =入力用!V38 -> #DIV/0! | E19: =入力用!V51 -> 0 | F19: =入力用!V64 -> 0
A20: =入力用!B13 -> 27/1 | B20: =入力用!V13 -> 0 | C20: =入力用!V26 -> 0 | D20: =入力用!V39 -> #DIV/0! | E20: =入力用!V52 -> 0 | F20: =入力用!V65 -> 0
A21: =入力用!B15 -> 27/3 | B21: =入力用!V15 -> 0 | C21: =入力用!V28 -> 0 | D21: =入力用!V41 -> #DIV/0! | E21: =入力用!V54 -> 0 | F21: =入力用!V67 -> 0

Sheet 濱田
A2: NSSU Soft tennis Team Inbody Feedback Sheet
A8: 氏名： | B8: =入力用!W2 -> 濱田遥花 | C8: 性別： | D8: =入力用!AG2 -> 女
A9: 測定日 | B9: 体重 (kg) | C9: 骨格筋量 (kg) | D9: 骨格筋量/体重 (%) | E9: 体脂肪量 (kg) | F9: 体脂肪率 (%)
A10: =入力用!B3 -> 26/3 | B10: =入力用!W3 -> 64.9 | C10: =入力用!W16 -> 24.2 | D10: =入力用!W29 -> 37.3 | E10: =入力用!W42 -> 21.7 | F10: =入力用!W55 -> 33.5
A11: =入力用!B4 -> 26/4 | B11: =入力用!W4 -> 64.9 | C11: =入力用!W17 -> 23.7 | D11: =入力用!W30 -> 36.5 | E11: =入力用!W43 -> 22.8 | F11: =入力用!W56 -> 35.2
A12: =入力用!B5 -> 26/5 | B12: =入力用!W5 -> 65.8 | C12: =入力用!W18 -> 24.1 | D12: =入力用!W31 -> 36.6 | E12: =入力用!W44 -> 22.8 | F12: =入力用!W57 -> 34.7
A13: =入力用!B6 -> 26/6 | B13: =入力用!W6 -> 0 | C13: =入力用!W19 -> 0 | D13: =入力用!W32 -> #DIV/0! | E13: =入力用!W45 -> 0 | F13: =入力用!W58 -> 0
A14: =入力用!B7 -> 26/7 | B14: =入力用!W7 -> 0 | C14: =入力用!W20 -> 0 | D14: =入力用!W33 -> #DIV/0! | E14: =入力用!W46 -> 0 | F14: =入力用!W59 -> 0
A15: =入力用!B8 -> 26/8 | B15: =入力用!W8 -> 0 | C15: =入力用!W21 -> 0 | D15: =入力用!W34 -> #DIV/0! | E15: =入力用!W47 -> 0 | F15: =入力用!W60 -> 0
A16: =入力用!B9 -> 26/9 | B16: =入力用!W9 -> 0 | C16: =入力用!W22 -> 0 | D16: =入力用!W35 -> #DIV/0! | E16: =入力用!W48 -> 0 | F16: =入力用!W61 -> 0
A17: =入力用!B10 -> 26/10 | B17: =入力用!W10 -> 0 | C17: =入力用!W23 -> 0 | D17: =入力用!W36 -> #DIV/0! | E17: =入力用!W49 -> 0 | F17: =入力用!W62 -> 0
A18: =入力用!B11 -> 26/11 | B18: =入力用!W11 -> 0 | C18: =入力用!W24 -> 0 | D18: =入力用!W37 -> #DIV/0! | E18: =入力用!W50 -> 0 | F18: =入力用!W63 -> 0
A19: =入力用!B12 -> 26/12 | B19: =入力用!W12 -> 0 | C19: =入力用!W25 -> 0 | D19: =入力用!W38 -> #DIV/0! | E19: =入力用!W51 -> 0 | F19: =入力用!W64 -> 0
A20: =入力用!B13 -> 27/1 | B20: =入力用!W13 -> 0 | C20: =入力用!W26 -> 0 | D20: =入力用!W39 -> #DIV/0! | E20: =入力用!W52 -> 0 | F20: =入力用!W65 -> 0
A21: =入力用!B15 -> 27/3 | B21: =入力用!W15 -> 0 | C21: =入力用!W28 -> 0 | D21: =入力用!W41 -> #DIV/0! | E21: =入力用!W54 -> 0 | F21: =入力用!W67 -> 0

Sheet 林
A2: NSSU Soft tennis Team Inbody Feedback Sheet
A8: 氏名： | B8: =入力用!X2 -> 林美桜 | C8: 性別： | D8: =入力用!AG2 -> 女
A9: 測定日 | B9: 体重 (kg) | C9: 骨格筋量 (kg) | D9: 骨格筋量/体重 (%) | E9: 体脂肪量 (kg) | F9: 体脂肪率 (%)
A10: =入力用!B3 -> 26/3 | B10: =入力用!X3 -> 58.7 | C10: =入力用!X16 -> 24.9 | D10: =入力用!X29 -> 42.4 | E10: =入力用!X42 -> 14.2 | F10: =入力用!X55 -> 24.2
A11: =入力用!B4 -> 26/4 | B11: =入力用!X4 -> 57.6 | C11: =入力用!X17 -> 23.6 | D11: =入力用!X30 -> 41 | E11: =入力用!X43 -> 15 | F11: =入力用!X56 -> 26.1
A12: =入力用!B5 -> 26/5 | B12: =入力用!X5 -> 57.7 | C12: =入力用!X18 -> 24.1 | D12: =入力用!X31 -> 41.8 | E12: =入力用!X44 -> 14.6 | F12: =入力用!X57 -> 25.3
A13: =入力用!B6 -> 26/6 | B13: =入力用!X6 -> 0 | C13: =入力用!X19 -> 0 | D13: =入力用!X32 -> #DIV/0! | E13: =入力用!X45 -> 0 | F13: =入力用!X58 -> 0
A14: =入力用!B7 -> 26/7 | B14: =入力用!X7 -> 0 | C14: =入力用!X20 -> 0 | D14: =入力用!X33 -> #DIV/0! | E14: =入力用!X46 -> 0 | F14: =入力用!X59 -> 0
A15: =入力用!B8 -> 26/8 | B15: =入力用!X8 -> 0 | C15: =入力用!X21 -> 0 | D15: =入力用!X34 -> #DIV/0! | E15: =入力用!X47 -> 0 | F15: =入力用!X60 -> 0
A16: =入力用!B9 -> 26/9 | B16: =入力用!X9 -> 0 | C16: =入力用!X22 -> 0 | D16: =入力用!X35 -> #DIV/0! | E16: =入力用!X48 -> 0 | F16: =入力用!X61 -> 0
A17: =入力用!B10 -> 26/10 | B17: =入力用!X10 -> 0 | C17: =入力用!X23 -> 0 | D17: =入力用!X36 -> #DIV/0! | E17: =入力用!X49 -> 0 | F17: =入力用!X62 -> 0
A18: =入力用!B11 -> 26/11 | B18: =入力用!X11 -> 0 | C18: =入力用!X24 -> 0 | D18: =入力用!X37 -> #DIV/0! | E18: =入力用!X50 -> 0 | F18: =入力用!X63 -> 0
A19: =入力用!B12 -> 26/12 | B19: =入力用!X12 -> 0 | C19: =入力用!X25 -> 0 | D19: =入力用!X38 -> #DIV/0! | E19: =入力用!X51 -> 0 | F19: =入力用!X64 -> 0
A20: =入力用!B13 -> 27/1 | B20: =入力用!X13 -> 0 | C20: =入力用!X26 -> 0 | D20: =入力用!X39 -> #DIV/0! | E20: =入力用!X52 -> 0 | F20: =入力用!X65 -> 0
A21: =入力用!B15 -> 27/3 | B21: =入力用!X15 -> 0 | C21: =入力用!X28 -> 0 | D21: =入力用!X41 -> #DIV/0! | E21: =入力用!X54 -> 0 | F21: =入力用!X67 -> 0

Sheet 天野
A2: NSSU Soft tennis Team Inbody Feedback Sheet
A8: 氏名： | B8: =入力用!Y2 -> 天野莉子 | C8: 性別： | D8: =入力用!AG2 -> 女
A9: 測定日 | B9: 体重 (kg) | C9: 骨格筋量 (kg) | D9: 骨格筋量/体重 (%) | E9: 体脂肪量 (kg) | F9: 体脂肪率 (%)
A10: =入力用!B3 -> 26/3 | B10: =入力用!Y3 -> 0 | C10: =入力用!Y16 -> 0 | D10: =入力用!Y29 -> #DIV/0! | E10: =入力用!Y42 -> 0 | F10: =入力用!Y55 -> 0
A11: =入力用!B4 -> 26/4 | B11: =入力用!Y4 -> 66.1 | C11: =入力用!Y17 -> 27.8 | D11: =入力用!Y30 -> 42.1 | E11: =入力用!Y43 -> 16.9 | F11: =入力用!Y56 -> 25.5
A12: =入力用!B5 -> 26/5 | B12: =入力用!Y5 -> 65.2 | C12: =入力用!Y18 -> 26.8 | D12: =入力用!Y31 -> 41.1 | E12: =入力用!Y44 -> 17.3 | F12: =入力用!Y57 -> 26.5
A13: =入力用!B6 -> 26/6 | B13: =入力用!Y6 -> 0 | C13: =入力用!Y19 -> 0 | D13: =入力用!Y32 -> #DIV/0! | E13: =入力用!Y45 -> 0 | F13: =入力用!Y58 -> 0
A14: =入力用!B7 -> 26/7 | B14: =入力用!Y7 -> 0 | C14: =入力用!Y20 -> 0 | D14: =入力用!Y33 -> #DIV/0! | E14: =入力用!Y46 -> 0 | F14: =入力用!Y59 -> 0
A15: =入力用!B8 -> 26/8 | B15: =入力用!Y8 -> 0 | C15: =入力用!Y21 -> 0 | D15: =入力用!Y34 -> #DIV/0! | E15: =入力用!Y47 -> 0 | F15: =入力用!Y60 -> 0
A16: =入力用!B9 -> 26/9 | B16: =入力用!Y9 -> 0 | C16: =入力用!Y22 -> 0 | D16: =入力用!Y35 -> #DIV/0! | E16: =入力用!Y48 -> 0 | F16: =入力用!Y61 -> 0
A17: =入力用!B10 -> 26/10 | B17: =入力用!Y10 -> 0 | C17: =入力用!Y23 -> 0 | D17: =入力用!Y36 -> #DIV/0! | E17: =入力用!Y49 -> 0 | F17: =入力用!Y62 -> 0
A18: =入力用!B11 -> 26/11 | B18: =入力用!Y11 -> 0 | C18: =入力用!Y24 -> 0 | D18: =入力用!Y37 -> #DIV/0! | E18: =入力用!Y50 -> 0 | F18: =入力用!Y63 -> 0
A19: =入力用!B12 -> 26/12 | B19: =入力用!Y12 -> 0 | C19: =入力用!Y25 -> 0 | D19: =入力用!Y38 -> #DIV/0! | E19: =入力用!Y51 -> 0 | F19: =入力用!Y64 -> 0
A20: =入力用!B13 -> 27/1 | B20: =入力用!Y13 -> 0 | C20: =入力用!Y26 -> 0 | D20: =入力用!Y39 -> #DIV/0! | E20: =入力用!Y52 -> 0 | F20: =入力用!Y65 -> 0
A21: =入力用!B14 -> 27/2 | B21: =入力用!Y14 -> 0 | C21: =入力用!Y27 -> 0 | D21: =入力用!Y40 -> #DIV/0! | E21: =入力用!Y53 -> 0 | F21: =入力用!Y66 -> 0
A22: =入力用!B15 -> 27/3 | B22: =入力用!Y15 -> 0 | C22: =入力用!Y28 -> 0 | D22: =入力用!Y41 -> #DIV/0! | E22: =入力用!Y54 -> 0 | F22: =入力用!Y67 -> 0

Sheet 栗原
A2: NSSU Soft tennis Team Inbody Feedback Sheet
A8: 氏名： | B8: =入力用!Z2 -> 栗原奈々 | C8: 性別： | D8: =入力用!AG2 -> 女
A9: 測定日 | B9: 体重 (kg) | C9: 骨格筋量 (kg) | D9: 骨格筋量/体重 (%) | E9: 体脂肪量 (kg) | F9: 体脂肪率 (%)
A10: =入力用!B3 -> 26/3 | B10: =入力用!Z3 -> 0 | C10: =入力用!Z16 -> 0 | D10: =入力用!Z29 -> #DIV/0! | E10: =入力用!Z42 -> 0 | F10: =入力用!Z55 -> 0
A11: =入力用!B4 -> 26/4 | B11: =入力用!Z4 -> 57.7 | C11: =入力用!Z17 -> 24.3 | D11: =入力用!Z30 -> 42.1 | E11: =入力用!Z43 -> 14 | F11: =入力用!Z56 -> 24.3
A12: =入力用!B5 -> 26/5 | B12: =入力用!Z5 -> 58 | C12: =入力用!Z18 -> 24.2 | D12: =入力用!Z31 -> 41.7 | E12: =入力用!Z44 -> 14.4 | F12: =入力用!Z57 -> 24.9
A13: =入力用!B6 -> 26/6 | B13: =入力用!Z6 -> 0 | C13: =入力用!Z19 -> 0 | D13: =入力用!Z32 -> #DIV/0! | E13: =入力用!Z45 -> 0 | F13: =入力用!Z58 -> 0
A14: =入力用!B7 -> 26/7 | B14: =入力用!Z7 -> 0 | C14: =入力用!Z20 -> 0 | D14: =入力用!Z33 -> #DIV/0! | E14: =入力用!Z46 -> 0 | F14: =入力用!Z59 -> 0
A15: =入力用!B8 -> 26/8 | B15: =入力用!Z8 -> 0 | C15: =入力用!Z21 -> 0 | D15: =入力用!Z34 -> #DIV/0! | E15: =入力用!Z47 -> 0 | F15: =入力用!Z60 -> 0
A16: =入力用!B9 -> 26/9 | B16: =入力用!Z9 -> 0 | C16: =入力用!Z22 -> 0 | D16: =入力用!Z35 -> #DIV/0! | E16: =入力用!Z48 -> 0 | F16: =入力用!Z61 -> 0
A17: =入力用!B10 -> 26/10 | B17: =入力用!Z10 -> 0 | C17: =入力用!Z23 -> 0 | D17: =入力用!Z36 -> #DIV/0! | E17: =入力用!Z49 -> 0 | F17: =入力用!Z62 -> 0
A18: =入力用!B11 -> 26/11 | B18: =入力用!Z11 -> 0 | C18: =入力用!Z24 -> 0 | D18: =入力用!Z37 -> #DIV/0! | E18: =入力用!Z50 -> 0 | F18: =入力用!Z63 -> 0
A19: =入力用!B12 -> 26/12 | B19: =入力用!Z12 -> 0 | C19: =入力用!Z25 -> 0 | D19: =入力用!Z38 -> #DIV/0! | E19: =入力用!Z51 -> 0 | F19: =入力用!Z64 -> 0
A20: =入力用!B13 -> 27/1 | B20: =入力用!Z13 -> 0 | C20: =入力用!Z26 -> 0 | D20: =入力用!Z39 -> #DIV/0! | E20: =入力用!Z52 -> 0 | F20: =入力用!Z65 -> 0
A21: =入力用!B14 -> 27/2 | B21: =入力用!Z14 -> 0 | C21: =入力用!Z27 -> 0 | D21: =入力用!Z40 -> #DIV/0! | E21: =入力用!Z53 -> 0 | F21: =入力用!Z66 -> 0
A22: =入力用!B15 -> 27/3 | B22: =入力用!Z15 -> 0 | C22: =入力用!Z28 -> 0 | D22: =入力用!Z41 -> #DIV/0! | E22: =入力用!Z54 -> 0 | F22: =入力用!Z67 -> 0

Sheet 佐々木
A2: NSSU Soft tennis Team Inbody Feedback Sheet
A8: 氏名： | B8: =入力用!AA2 -> 佐々木真凜 | C8: 性別： | D8: =入力用!AG2 -> 女
A9: 測定日 | B9: 体重 (kg) | C9: 骨格筋量 (kg) | D9: 骨格筋量/体重 (%) | E9: 体脂肪量 (kg) | F9: 体脂肪率 (%)
A10: =入力用!B3 -> 26/3 | B10: =入力用!AA3 -> 0 | C10: =入力用!AA16 -> 0 | D10: =入力用!AA29 -> #DIV/0! | E10: =入力用!AA42 -> 0 | F10: =入力用!AA55 -> 0
A11: =入力用!B4 -> 26/4 | B11: =入力用!AA4 -> 48 | C11: =入力用!AA17 -> 21.5 | D11: =入力用!AA30 -> 44.8 | E11: =入力用!AA43 -> 8.5 | F11: =入力用!AA56 -> 17.7
A12: =入力用!B5 -> 26/5 | B12: =入力用!AA5 -> 48.2 | C12: =入力用!AA18 -> 22 | D12: =入力用!AA31 -> 45.6 | E12: =入力用!AA44 -> 8.3 | F12: =入力用!AA57 -> 17.1
A13: =入力用!B6 -> 26/6 | B13: =入力用!AA6 -> 0 | C13: =入力用!AA19 -> 0 | D13: =入力用!AA32 -> #DIV/0! | E13: =入力用!AA45 -> 0 | F13: =入力用!AA58 -> 0
A14: =入力用!B7 -> 26/7 | B14: =入力用!AA7 -> 0 | C14: =入力用!AA20 -> 0 | D14: =入力用!AA33 -> #DIV/0! | E14: =入力用!AA46 -> 0 | F14: =入力用!AA59 -> 0
A15: =入力用!B8 -> 26/8 | B15: =入力用!AA8 -> 0 | C15: =入力用!AA21 -> 0 | D15: =入力用!AA34 -> #DIV/0! | E15: =入力用!AA47 -> 0 | F15: =入力用!AA60 -> 0
A16: =入力用!B9 -> 26/9 | B16: =入力用!AA9 -> 0 | C16: =入力用!AA22 -> 0 | D16: =入力用!AA35 -> #DIV/0! | E16: =入力用!AA48 -> 0 | F16: =入力用!AA61 -> 0
A17: =入力用!B10 -> 26/10 | B17: =入力用!AA10 -> 0 | C17: =入力用!AA23 -> 0 | D17: =入力用!AA36 -> #DIV/0! | E17: =入力用!AA49 -> 0 | F17: =入力用!AA62 -> 0
A18: =入力用!B11 -> 26/11 | B18: =入力用!AA11 -> 0 | C18: =入力用!AA24 -> 0 | D18: =入力用!AA37 -> #DIV/0! | E18: =入力用!AA50 -> 0 | F18: =入力用!AA63 -> 0
A19: =入力用!B12 -> 26/12 | B19: =入力用!AA12 -> 0 | C19: =入力用!AA25 -> 0 | D19: =入力用!AA38 -> #DIV/0! | E19: =入力用!AA51 -> 0 | F19: =入力用!AA64 -> 0
A20: =入力用!B13 -> 27/1 | B20: =入力用!AA13 -> 0 | C20: =入力用!AA26 -> 0 | D20: =入力用!AA39 -> #DIV/0! | E20: =入力用!AA52 -> 0 | F20: =入力用!AA65 -> 0
A21: =入力用!B14 -> 27/2 | B21: =入力用!AA14 -> 0 | C21: =入力用!AA27 -> 0 | D21: =入力用!AA40 -> #DIV/0! | E21: =入力用!AA53 -> 0 | F21: =入力用!AA66 -> 0
A22: =入力用!B15 -> 27/3 | B22: =入力用!AA15 -> 0 | C22: =入力用!AA28 -> 0 | D22: =入力用!AA41 -> #DIV/0! | E22: =入力用!AA54 -> 0 | F22: =入力用!AA67 -> 0

Sheet 天間麗
A2: NSSU Soft tennis Team Inbody Feedback Sheet
A8: 氏名： | B8: =入力用!AB2 -> 天間麗奈 | C8: 性別： | D8: 女
A9: 測定日 | B9: 体重 (kg) | C9: 骨格筋量 (kg) | D9: 骨格筋量/体重 (%) | E9: 体脂肪量 (kg) | F9: 体脂肪率 (%)
A10: =入力用!B3 -> 26/3 | B10: =入力用!AB3 -> 0 | C10: =入力用!AB16 -> 0 | D10: =入力用!AB29 -> #DIV/0! | E10: =入力用!AB42 -> 0 | F10: =入力用!AB55 -> 0
A11: =入力用!B4 -> 26/4 | B11: =入力用!AB4 -> 53.4 | C11: =入力用!AB17 -> 24.5 | D11: =入力用!AB30 -> 45.9 | E11: =入力用!AB43 -> 9.7 | F11: =入力用!AB56 -> 18.1
A12: =入力用!B5 -> 26/5 | B12: =入力用!AB5 -> 54.2 | C12: =入力用!AB18 -> 25.1 | D12: =入力用!AB31 -> 46.3 | E12: =入力用!AB44 -> 9.4 | F12: =入力用!AB57 -> 17.3
A13: =入力用!B6 -> 26/6 | B13: =入力用!AB6 -> 0 | C13: =入力用!AB19 -> 0 | D13: =入力用!AB32 -> #DIV/0! | E13: =入力用!AB45 -> 0 | F13: =入力用!AB58 -> 0
A14: =入力用!B7 -> 26/7 | B14: =入力用!AB7 -> 0 | C14: =入力用!AB20 -> 0 | D14: =入力用!AB33 -> #DIV/0! | E14: =入力用!AB46 -> 0 | F14: =入力用!AB59 -> 0
A15: =入力用!B8 -> 26/8 | B15: =入力用!AB8 -> 0 | C15: =入力用!AB21 -> 0 | D15: =入力用!AB34 -> #DIV/0! | E15: =入力用!AB47 -> 0 | F15: =入力用!AB60 -> 0
A16: =入力用!B9 -> 26/9 | B16: =入力用!AB9 -> 0 | C16: =入力用!AB22 -> 0 | D16: =入力用!AB35 -> #DIV/0! | E16: =入力用!AB48 -> 0 | F16: =入力用!AB61 -> 0
A17: =入力用!B10 -> 26/10 | B17: =入力用!AB10 -> 0 | C17: =入力用!AB23 -> 0 | D17: =入力用!AB36 -> #DIV/0! | E17: =入力用!AB49 -> 0 | F17: =入力用!AB62 -> 0
A18: =入力用!B11 -> 26/11 | B18: =入力用!AB11 -> 0 | C18: =入力用!AB24 -> 0 | D18: =入力用!AB37 -> #DIV/0! | E18: =入力用!AB50 -> 0 | F18: =入力用!AB63 -> 0
A19: =入力用!B12 -> 26/12 | B19: =入力用!AB12 -> 0 | C19: =入力用!AB25 -> 0 | D19: =入力用!AB38 -> #DIV/0! | E19: =入力用!AB51 -> 0 | F19: =入力用!AB64 -> 0
A20: =入力用!B13 -> 27/1 | B20: =入力用!AB13 -> 0 | C20: =入力用!AB26 -> 0 | D20: =入力用!AB39 -> #DIV/0! | E20: =入力用!AB52 -> 0 | F20: =入力用!AB65 -> 0
A21: =入力用!B14 -> 27/2 | B21: =入力用!AB14 -> 0 | C21: =入力用!AB27 -> 0 | D21: =入力用!AB40 -> #DIV/0! | E21: =入力用!AB53 -> 0 | F21: =入力用!AB66 -> 0
