Workbook

Sheet 入力用
C1: 4 | D1: 4 | E1: 4 | F1: 4 | G1: 4 | H1: 4 | I1: 4 | J1: 4 | K1: 4 | L1: 4 | M1: 3 | N1: 3 | O1: 3 | P1: 3 | Q1: 3 | R1: 3 | S1: 3 | T1: 3 | U1: 3 | V1: 3 | W1: 2 | X1: 2 | Y1: 2 | Z1: 2 | AA1: 2 | AB1: 2 | AC1: 1 | AD1: 1 | AE1: 1 | AF1: 1 | AG1: 1 | AH1: 1 | AI1: 平均 | AJ1: 標準偏差 | AL1: 男
B2: 測定日 | C2: 五十嵐美結 | D2: 尾崎瀬里奈 | E2: 樫尾陽和里 | F2: 左近知美 | G2: 竹本萌花 | H2: 達光咲 | I2: 生井沢日向子 | J2: 原田美結 | K2: 藤原未凪 | L2: 細田美帆 | M2: 入澤瑛麻 | N2: 加藤華 | O2: 髙橋ひかる | P2: 天間美嘉 | Q2: 長根理子 | R2: 橋本和香菜 | S2: 藤井真菜 | T2: 松岡琴美 | U2: 吉木理彩 | V2: 渡邉妃菜乃 | W2: 岩田愛美 | X2: 内田真愛 | Y2: 徳山暖枝 | Z2: 中村楓芽 | AA2: 向山せら | AB2: 山下永遠 | AC2: 池田朝花 | AD2: 後藤和香奈 | AE2: 津島世奈 | AF2: 濱口芽花 | AG2: 濱田遥花 | AH2: 林美桜 | AL2: 女
A3: 体重 (kg) | B3: 24/12 | C3: 57.2 | D3: 48.3 | E3: 63.3 | F3: 57.1 | G3: 57 | H3: 47 | I3: 62.6 | J3: 54.2 | K3: 66.1 | L3: 51.6 | M3: 43.9 | N3: 49.7 | O3: 60.1 | P3: 56.8 | Q3: 57.9 | R3: 48 | S3: 63.3 | T3: 49.6 | U3: 54 | V3: 51.5 | W3: 55.3 | X3: 57.4 | Y3: 62.8 | Z3: 58.2 | AA3: 55.6 | AB3: 64.2 | AI3: =AVERAGE(C3:AH3) -> 55.873077 | AJ3: =_xlfn.STDEV.S(C3:AH3) -> 5.9180103
B4: 25/1 | C4: 58.5 | D4: 51.8 | E4: 62.8 | F4: 56.1 | G4: 56.4 | H4: 46.6 | I4: 65.3 | J4: 54.3 | K4: 67.6 | L4: 52.3 | M4: 45.1 | N4: 50.7 | O4: 61.1 | Q4: 57.7 | R4: 48 | S4: 63.5 | T4: 50 | U4: 55.5 | V4: 51.4 | W4: 55.5 | X4: 56 | Y4: 60.8 | Z4: 57.3 | AA4: 56.5 | AB4: 64 | AI4: =AVERAGE(C4:AH4) -> 56.192 | AJ4: =_xlfn.STDEV.S(C4:AH4) -> 5.9092385
B5: 25/2 | AI5: =AVERAGE(C5:AH5) -> #DIV/0! | AJ5: =_xlfn.STDEV.S(C5:AH5) -> #DIV/0!
B6: 25/3 | C6: 58.3 | D6: 52.7 | E6: 63.3 | F6: 55.3 | G6: 57.4 | H6: 47.3 | I6: 66 | J6: 55.1 | K6: 69 | L6: 53.4 | M6: 44.3 | N6: 50.4 | O6: 61 | P6: 58.2 | Q6: 59.7 | R6: 49.4 | S6: 66.1 | T6: 52.8 | U6: 57.5 | V6: 50.6 | W6: 54.5 | X6: 55.7 | Y6: 63.6 | Z6: 57.4 | AA6: 58.1 | AB6: 64.1 | AC6: 52.7 | AD6: 60.9 | AE6: 58.9 | AF6: 58.9 | AG6: 65.2 | AH6: 56.9 | AI6: =AVERAGE(C6:AH6) -> 57.334375 | AJ6: =_xlfn.STDEV.S(C6:AH6) -> 5.779419
B7: 25/4 | C7: 56.6 | D7: 51.3 | E7: 63.2 | F7: 56.4 | G7: 56.2 | H7: 47.7 | I7: 64.8 | J7: 56.3 | K7: 68 | M7: 43.2 | N7: 50.8 | O7: 58.6 | Q7: 58.7 | R7: 50.3 | S7: 64.5 | T7: 51.1 | U7: 56.5 | V7: 49.2 | W7: 54.3 | X7: 56.9 | Y7: 61.9 | Z7: 57.9 | AA7: 58.2 | AB7: 65.8 | AC7: 52.6 | AD7: 61.6 | AE7: 56.5 | AF7: 58.9 | AG7: 64.8 | AH7: 56.7 | AI7: =AVERAGE(C7:AH7) -> 56.983333 | AJ7: =_xlfn.STDEV.S(C7:AH7) -> 5.8385806
B8: 25/5 | C8: 56.4 | D8: 53 | E8: 62.5 | G8: 56.9 | L8: 52.5 | M8: 42.6 | N8: 51 | O8: 58.6 | P8: 59.7 | Q8: 58.6 | R8: 49.6 | S8: 66.1 | T8: 52.9 | U8: 56.4 | V8: 50.3 | W8: 54 | X8: 55.5 | Y8: 63.6 | Z8: 58 | AA8: 58 | AB8: 65.4 | AC8: 53.7 | AD8: 63.3 | AE8: 59.4 | AF8: 59.9 | AG8: 65.4 | AH8: 54.2 | AI8: =AVERAGE(C8:AH8) -> 56.944444 | AJ8: =_xlfn.STDEV.S(C8:AH8) -> 5.521659
B9: 25/6 | AI9: =AVERAGE(C9:AH9) -> #DIV/0! | AJ9: =_xlfn.STDEV.S(C9:AH9) -> #DIV/0!
B10: 25/7 | C10: 56 | D10: 52.3 | E10: 61 | F10: 56.2 | H10: 46 | I10: 60.7 | J10: 54.8 | K10: 69.9 | M10: 43.5 | N10: 51.2 | O10: 56.8 | P10: 60.5 | R10: 47.5 | S10: 64.1 | T10: 52.1 | U10: 54.9 | V10: 48.4 | W10: 52.7 | X10: 55.2 | Y10: 62.2 | Z10: 59.6 | AA10: 56.8 | AB10: 66.5 | AC10: 52 | AD10: 60.7 | AE10: 58 | AF10: 58.8 | AG10: 63.8 | AH10: 56.2 | AI10: =AVERAGE(C10:AH10) -> 56.496552 | AJ10: =_xlfn.STDEV.S(C10:AH10) -> 6.1096225
B11: 25/8 | D11: 52.1 | E11: 63.1 | F11: 55.4 | G11: 56 | H11: 45.8 | I11: 61.7 | K11: 69.4 | N11: 50.5 | O11: 55.1 | Q11: 59.6 | R11: 48.9 | S11: 65.3 | T11: 51.9 | V11: 48.4 | W11: 53.5 | X11: 53.5 | Y11: 61.1 | Z11: 57.4 | AB11: 64.8 | AC11: 52.3 | AE11: 58.3 | AG11: 63.2 | AH11: 56.1 | AI11: =AVERAGE(C11:AH11) -> 56.669565 | AJ11: =_xlfn.STDEV.S(C11:AH11) -> 6.0901884
B12: 25/9 | AI12: =AVERAGE(C12:AH12) -> #DIV/0! | AJ12: =_xlfn.STDEV.S(C12:AH12) -> #DIV/0!
B13: 25/10 | C13: 55.4 | D13: 52.9 | F13: 53.5 | I13: 62.5 | L13: 53 | M13: 42.3 | N13: 51 | O13: 56 | P13: 59 | Q13: 57.7 | R13: 47.7 | S13: 64 | T13: 51.6 | U13: 57.5 | V13: 49 | W13: 54.3 | X13: 54.9 | Y13: 61 | Z13: 56.3 | AA13: 56.6 | AB13: 64.5 | AC13: 53.8 | AD13: 61 | AE13: 58.7 | AF13: 55.5 | AG13: 62.1 | AH13: 56.7 | AI13: =AVERAGE(C13:AH13) -> 55.87037 | AJ13: =_xlfn.STDEV.S(C13:AH13) -> 5.0838216
B14: 25/11
B15: 25/12 | C15: 55.2 | D15: 50.6 | E15: 65.2 | F15: 56.5 | I15: 61.9 | L15: 51.9 | M15: 42.7 | N15: 50.3 | O15: 53.5 | P15: 56.7 | Q15: 55.7 | R15: 48.7 | S15: 61.1 | T15: 50.8 | U15: 57.2 | V15: 48.2 | W15: 53.2 | X15: 55.2 | Y15: 61.8 | Z15: 54.8 | AA15: 54.9 | AB15: 64.1 | AC15: 52.5 | AD15: 62.1 | AE15: 58.4 | AF15: 58.1 | AG15: 61.1 | AH15: 56.5 | AI15: =AVERAGE(C15:AH15) -> 55.675 | AJ15: =_xlfn.STDEV.S(C15:AH15) -> 5.2509347
A16: 骨格筋量 (kg) | B16: 24/12 | C16: 22.9 | D16: 21.7 | E16: 24.1 | F16: 25.5 | G16: 22.5 | H16: 20.8 | I16: 25.3 | J16: 22.5 | K16: 24.4 | L16: 22.2 | M16: 18.9 | N16: 19.8 | O16: 24.9 | P16: 22 | Q16: 24 | R16: 20.9 | S16: 27.3 | T16: 20.2 | U16: 23 | V16: 19.4 | W16: 24.7 | X16: 24.7 | Y16: 22.8 | Z16: 24.3 | AA16: 23.3 | AB16: 26.5 | AI16: =AVERAGE(C16:AH16) -> 23.023077 | AJ16: =_xlfn.STDEV.S(C16:AH16) -> 2.1779454
B17: 25/1 | C17: 23.3 | D17: 23 | E17: 23.9 | F17: 25.2 | G17: 22.2 | H17: 20.2 | I17: 26.2 | J17: 23.2 | K17: 25 | L17: 22.7 | M17: 18.4 | N17: 19.9 | O17: 24.6 | Q17: 23.4 | R17: 20.1 | S17: 26.5 | T17: 19.7 | U17: 22.5 | V17: 18.8 | W17: 24.3 | X17: 24.2 | Y17: 22.3 | Z17: 23.9 | AA17: 24.4 | AB17: 26.3 | AI17: =AVERAGE(C17:AH17) -> 22.968 | AJ17: =_xlfn.STDEV.S(C17:AH17) -> 2.3163765
B18: 25/2 | AI18: =AVERAGE(C18:AH18) -> #DIV/0! | AJ18: =_xlfn.STDEV.S(C18:AH18) -> #DIV/0!
B19: 25/3 | C19: 23.6 | D19: 23.3 | E19: 24 | F19: 24.7 | G19: 22.8 | H19: 21 | I19: 27 | J19: 22.5 | K19: 25.2 | L19: 22.9 | M19: 19 | N19: 20.1 | O19: 24.2 | P19: 22.2 | Q19: 25.2 | R19: 21.5 | S19: 27.6 | T19: 21 | U19: 24 | V19: 18.9 | W19: 24.5 | X19: 24 | Y19: 23.3 | Z19: 24.2 | AA19: 25.1 | AB19: 25.6 | AC19: 22.8 | AD19: 25.5 | AE19: 24 | AF19: 26 | AG19: 25 | AH19: 23 | AI19: =AVERAGE(C19:AH19) -> 23.553125 | AJ19: =_xlfn.STDEV.S(C19:AH19) -> 2.0672538
B20: 25/4 | C20: 23.1 | D20: 22.9 | E20: 24.1 | F20: 25.2 | G20: 21.8 | H20: 21.1 | I20: 25.8 | J20: 22.7 | K20: 25.1 | M20: 18.2 | N20: 21.8 | O20: 23.9 | Q20: 25 | R20: 21.4 | S20: 27.2 | T20: 20.8 | U20: 23.4 | V20: 18.8 | W20: 24 | X20: 24.6 | Y20: 22.9 | Z20: 23.9 | AA20: 24.6 | AB20: 27.5 | AC20: 22.2 | AD20: 25.8 | AE20: 23.7 | AF20: 26.7 | AG20: 25 | AH20: 23.2 | AI20: =AVERAGE(C20:AH20) -> 23.546667 | AJ20: =_xlfn.STDEV.S(C20:AH20) -> 2.2012118
B21: 25/5 | C21: 23.4 | D21: 23.8 | E21: 23.1 | G21: 21.7 | L21: 22.4 | M21: 18.6 | N21: 20.8 | O21: 24.3 | P21: 22.6 | Q21: 25 | R21: 21.7 | S21: 27 | T21: 22.5 | U21: 23.5 | V21: 19.3 | W21: 24.2 | X21: 24.3 | Y21: 24.1 | Z21: 24.2 | AA21: 24.3 | AB21: 26.3 | AC21: 23.5 | AD21: 26.4 | AE21: 24.7 | AF21: 27.3 | AG21: 25.1 | AH21: 22.2 | AI21: =AVERAGE(C21:AH21) -> 23.566667 | AJ21: =_xlfn.STDEV.S(C21:AH21) -> 2.0821586
B22: 25/6 | AI22: =AVERAGE(C22:AH22) -> #DIV/0! | AJ22: =_xlfn.STDEV.S(C22:AH22) -> #DIV/0!
B23: 25/7 | C23: 23.4 | D23: 23.3 | E23: 22.8 | F23: 25.5 | H23: 19.9 | I23: 25.1 | J23: 22.9 | K23: 25.9 | M23: 18.4 | N23: 21.3 | O23: 23.1 | P23: 22.3 | R23: 21 | S23: 26.7 | T23: 21 | U23: 23.7 | V23: 19 | W23: 24 | X23: 24.5 | Y23: 23.2 | Z23: 25 | AA23: 23.5 | AB23: 26.5 | AC23: 22.4 | AD23: 25.6 | AE23: 24.9 | AF23: 26.8 | AG23: 23.8 | AH23: 22.8 | AI23: =AVERAGE(C23:AH23) -> 23.389655 | AJ23: =_xlfn.STDEV.S(C23:AH23) -> 2.1790143
B24: 25/8 | D24: 23.1 | E24: 24.1 | F24: 25.5 | G24: 21.6 | H24: 20.8 | I24: 25.4 | K24: 25.3 | N24: 20.8 | O24: 23.5 | Q24: 25.2 | R24: 21 | S24: 27.1 | T24: 21.3 | V24: 19.1 | W24: 24.8 | X24: 23.3 | Y24: 22.7 | Z24: 24.5 | AB24: 26.5 | AC24: 22.9 | AE24: 26 | AG24: 23.9 | AH24: 23.6 | AI24: =AVERAGE(C24:AH24) -> 23.565217 | AJ24: =_xlfn.STDEV.S(C24:AH24) -> 2.0770628
B25: 25/9 | AI25: =AVERAGE(C25:AH25) -> #DIV/0! | AJ25: =_xlfn.STDEV.S(C25:AH25) -> #DIV/0!
B26: 25/10 | C26: 22.4 | D26: 22.5 | F26: 24.6 | I26: 25.7 | L26: 22.8 | M26: 18.5 | N26: 21 | O26: 23.3 | P26: 22.5 | Q26: 23.9 | R26: 21.1 | S26: 26.2 | T26: 20.7 | U26: 24.1 | V26: 18.8 | W26: 23.9 | X26: 23.7 | Y26: 22.7 | Z26: 23.8 | AA26: 23.8 | AB26: 25.9 | AC26: 23.4 | AD26: 26.1 | AE26: 25.2 | AF26: 26.1 | AG26: 23.6 | AH26: 23.7 | AI26: =AVERAGE(C26:AH26) -> 23.333333 | AJ26: =_xlfn.STDEV.S(C26:AH26) -> 2.0290202
B27: 25/11
B28: 25/12 | C28: 22.2 | D28: 21.7 | E28: 24.3 | F28: 25.1 | I28: 25.6 | L28: 21.5 | M28: 18.5 | N28: 20.5 | O28: 22.8 | P28: 22.2 | Q28: 24.6 | R28: 21.3 | S28: 26 | T28: 21.1 | U28: 22.6 | V28: 18.5 | W28: 24.2 | X28: 24.9 | Y28: 23.2 | Z28: 22.8 | AA28: 23.2 | AB28: 26 | AC28: 23.5 | AD28: 26.1 | AE28: 25.1 | AF28: 26.3 | AG28: 24.3 | AH28: 23.9 | AI28: =AVERAGE(C28:AH28) -> 23.285714 | AJ28: =_xlfn.STDEV.S(C28:AH28) -> 2.1311993
A29: 骨格筋量 / 体重 (%) | B29: 24/12 | C29: =ROUND((C16/C3)*100,1) -> 40 | D29: =ROUND((D16/D3)*100,1) -> 44.9 | E29: =ROUND((E16/E3)*100,1) -> 38.1 | F29: =ROUND((F16/F3)*100,1) -> 44.7 | G29: =ROUND((G16/G3)*100,1) -> 39.5 | H29: =ROUND((H16/H3)*100,1) -> 44.3 | I29: =ROUND((I16/I3)*100,1) -> 40.4 | J29: =ROUND((J16/J3)*100,1) -> 41.5 | ... AH29: =ROUND((AH16/AH3)*100,1) -> #DIV/0! | AI29: =AVERAGE(C29:AH29) -> #DIV/0! | AJ29: =_xlfn.STDEV.S(C29:AH29) -> #DIV/0!
B30: 25/1 | C30: =ROUND((C17/C4)*100,1) -> 39.8 | D30: =ROUND((D17/D4)*100,1) -> 44.4 | E30: =ROUND((E17/E4)*100,1) -> 38.1 | F30: =ROUND((F17/F4)*100,1) -> 44.9 | G30: =ROUND((G17/G4)*100,1) -> 39.4 | H30: =ROUND((H17/H4)*100,1) -> 43.3 | I30: =ROUND((I17/I4)*100,1) -> 40.1 | J30: =ROUND((J17/J4)*100,1) -> 42.7 | ... AH30: =ROUND((AH17/AH4)*100,1) -> #DIV/0! | AI30: =AVERAGE(C30:AH30) -> #DIV/0! | AJ30: =_xlfn.STDEV.S(C30:AH30) -> #DIV/0!
B31: 25/2 | C31: =ROUND((C18/C5)*100,1) -> #DIV/0! | D31: =ROUND((D18/D5)*100,1) -> #DIV/0! | E31: =ROUND((E18/E5)*100,1) -> #DIV/0! | F31: =ROUND((F18/F5)*100,1) -> #DIV/0! | G31: =ROUND((G18/G5)*100,1) -> #DIV/0! | H31: =ROUND((H18/H5)*100,1) -> #DIV/0! | I31: =ROUND((I18/I5)*100,1) -> #DIV/0! | J31: =ROUND((J18/J5)*100,1) -> #DIV/0! | ... AH31: =ROUND((AH18/AH5)*100,1) -> #DIV/0! | AI31: =AVERAGE(C31:AH31) -> #DIV/0! | AJ31: =_xlfn.STDEV.S(C31:AH31) -> #DIV/0!
B32: 25/3 | C32: =ROUND((C19/C6)*100,1) -> 40.5 | D32: =ROUND((D19/D6)*100,1) -> 44.2 | E32: =ROUND((E19/E6)*100,1) -> 37.9 | F32: =ROUND((F19/F6)*100,1) -> 44.7 | G32: =ROUND((G19/G6)*100,1) -> 39.7 | H32: =ROUND((H19/H6)*100,1) -> 44.4 | I32: =ROUND((I19/I6)*100,1) -> 40.9 | J32: =ROUND((J19/J6)*100,1) -> 40.8 | ... AH32: =ROUND((AH19/AH6)*100,1) -> 40.4 | AI32: =AVERAGE(C32:AH32) -> 41.19375 | AJ32: =_xlfn.STDEV.S(C32:AH32) -> 2.4002604
B33: 25/4 | C33: =ROUND((C20/C7)*100,1) -> 40.8 | D33: =ROUND((D20/D7)*100,1) -> 44.6 | E33: =ROUND((E20/E7)*100,1) -> 38.1 | F33: =ROUND((F20/F7)*100,1) -> 44.7 | G33: =ROUND((G20/G7)*100,1) -> 38.8 | H33: =ROUND((H20/H7)*100,1) -> 44.2 | I33: =ROUND((I20/I7)*100,1) -> 39.8 | J33: =ROUND((J20/J7)*100,1) -> 40.3 | ... AH33: =ROUND((AH20/AH7)*100,1) -> 40.9 | AI33: =AVERAGE(C33:AH33) -> #DIV/0! | AJ33: =_xlfn.STDEV.S(C33:AH33) -> #DIV/0!
B34: 25/5 | C34: =ROUND((C21/C8)*100,1) -> 41.5 | D34: =ROUND((D21/D8)*100,1) -> 44.9 | E34: =ROUND((E21/E8)*100,1) -> 37 | F34: =ROUND((F21/F8)*100,1) -> #DIV/0! | G34: =ROUND((G21/G8)*100,1) -> 38.1 | H34: =ROUND((H21/H8)*100,1) -> #DIV/0! | I34: =ROUND((I21/I8)*100,1) -> #DIV/0! | J34: =ROUND((J21/J8)*100,1) -> #DIV/0! | ... AH34: =ROUND((AH21/AH8)*100,1) -> 41 | AI34: =AVERAGE(C34:AH34) -> #DIV/0! | AJ34: =_xlfn.STDEV.S(C34:AH34) -> #DIV/0!
B35: 25/6 | C35: =ROUND((C22/C9)*100,1) -> #DIV/0! | D35: =ROUND((D22/D9)*100,1) -> #DIV/0! | E35: =ROUND((E22/E9)*100,1) -> #DIV/0! | F35: =ROUND((F22/F9)*100,1) -> #DIV/0! | G35: =ROUND((G22/G9)*100,1) -> #DIV/0! | H35: =ROUND((H22/H9)*100,1) -> #DIV/0! | I35: =ROUND((I22/I9)*100,1) -> #DIV/0! | J35: =ROUND((J22/J9)*100,1) -> #DIV/0! | ... AH35: =ROUND((AH22/AH9)*100,1) -> #DIV/0! | AI35: =AVERAGE(C35:AH35) -> #DIV/0! | AJ35: =_xlfn.STDEV.S(C35:AH35) -> #DIV/0!
B36: 25/7 | C36: =ROUND((C23/C10)*100,1) -> 41.8 | D36: =ROUND((D23/D10)*100,1) -> 44.6 | E36: =ROUND((E23/E10)*100,1) -> 37.4 | F36: =ROUND((F23/F10)*100,1) -> 45.4 | G36: =ROUND((G23/G10)*100,1) -> #DIV/0! | H36: =ROUND((H23/H10)*100,1) -> 43.3 | I36: =ROUND((I23/I10)*100,1) -> 41.4 | J36: =ROUND((J23/J10)*100,1) -> 41.8 | ... AH36: =ROUND((AH23/AH10)*100,1) -> 40.6 | AI36: =AVERAGE(C36:AH36) -> #DIV/0! | AJ36: =_xlfn.STDEV.S(C36:AH36) -> #DIV/0!
B37: 25/8 | C37: =ROUND((C24/C11)*100,1) -> #DIV/0! | D37: =ROUND((D24/D11)*100,1) -> 44.3 | E37: =ROUND((E24/E11)*100,1) -> 38.2 | F37: =ROUND((F24/F11)*100,1) -> 46 | G37: =ROUND((G24/G11)*100,1) -> 38.6 | H37: =ROUND((H24/H11)*100,1) -> 45.4 | I37: =ROUND((I24/I11)*100,1) -> 41.2 | J37: =ROUND((J24/J11)*100,1) -> #DIV/0! | ... AH37: =ROUND((AH24/AH11)*100,1) -> 42.1 | AI37: =AVERAGE(C37:AH37) -> #DIV/0! | AJ37: =_xlfn.STDEV.S(C37:AH37) -> #DIV/0!
B38: 25/9 | C38: =ROUND((C25/C12)*100,1) -> #DIV/0! | D38: =ROUND((D25/D12)*100,1) -> #DIV/0! | E38: =ROUND((E25/E12)*100,1) -> #DIV/0! | F38: =ROUND((F25/F12)*100,1) -> #DIV/0! | G38: =ROUND((G25/G12)*100,1) -> #DIV/0! | H38: =ROUND((H25/H12)*100,1) -> #DIV/0! | I38: =ROUND((I25/I12)*100,1) -> #DIV/0! | J38: =ROUND((J25/J12)*100,1) -> #DIV/0! | ... AH38: =ROUND((AH25/AH12)*100,1) -> #DIV/0! | AI38: =AVERAGE(C38:AH38) -> #DIV/0! | AJ38: =_xlfn.STDEV.S(C38:AH38) -> #DIV/0!
B39: 25/10 | C39: =ROUND((C26/C13)*100,1) -> 40.4 | D39: =ROUND((D26/D13)*100,1) -> 42.5 | E39: =ROUND((E26/E13)*100,1) -> #DIV/0! | F39: =ROUND((F26/F13)*100,1) -> 46 | G39: =ROUND((G26/G13)*100,1) -> #DIV/0! | H39: =ROUND((H26/H13)*100,1) -> #DIV/0! | I39: =ROUND((I26/I13)*100,1) -> 41.1 | J39: =ROUND((J26/J13)*100,1) -> #DIV/0! | ... AH39: =ROUND((AH26/AH13)*100,1) -> 41.8 | AI39: =AVERAGE(C39:AH39) -> #DIV/0! | AJ39: =_xlfn.STDEV.S(C39:AH39) -> #DIV/0!
B40: 25/11
...

Sheet 平均
A2: NSSU Soft tennis Team Inbody Feedback Sheet
A8: 氏名： | B8: チーム平均 | C8: 性別： | D8: =入力用!AL2 -> 女
A9: 測定種目 | B9: 体重 (kg) | C9: 骨格筋量 (kg) | D9: 骨格筋量/体重 (%) | E9: 体脂肪量 (kg) | F9: 体脂肪率 (%)
A10: =入力用!B3 -> 24/12 | B10: =入力用!AI3 -> 55.873077 | C10: =入力用!AI16 -> 23.023077 | D10: =入力用!AI29 -> #DIV/0! | E10: =入力用!AI42 -> 14.226923 | F10: =入力用!AI55 -> 25.284615
A11: =入力用!B4 -> 25/1 | B11: =入力用!AI4 -> 56.192 | C11: =入力用!AI17 -> 22.968 | D11: =入力用!AI30 -> #DIV/0! | E11: =入力用!AI43 -> 14.548 | F11: =入力用!AI56 -> 25.68
A12: =入力用!B5 -> 25/2 | B12: =入力用!AI5 -> #DIV/0! | C12: =入力用!AI18 -> #DIV/0! | D12: =入力用!AI31 -> #DIV/0! | E12: =入力用!AI44 -> #DIV/0! | F12: =入力用!AI57 -> #DIV/0!
A13: =入力用!B6 -> 25/3 | B13: =入力用!AI6 -> 57.334375 | C13: =入力用!AI19 -> 23.553125 | D13: =入力用!AI32 -> 41.19375 | E13: =入力用!AI45 -> 14.875 | F13: =入力用!AI58 -> 25.690625
A14: =入力用!B7 -> 25/4 | B14: =入力用!AI7 -> 56.983333 | C14: =入力用!AI20 -> 23.546667 | D14: =入力用!AI33 -> #DIV/0! | E14: =入力用!AI46 -> 14.593333 | F14: =入力用!AI59 -> 25.396667
A15: =入力用!B8 -> 25/5 | B15: =入力用!AI8 -> 56.944444 | C15: =入力用!AI21 -> 23.566667 | D15: =入力用!AI34 -> #DIV/0! | E15: =入力用!AI47 -> 14.551852 | F15: =入力用!AI60 -> 25.348148
A16: =入力用!B9 -> 25/6 | B16: =入力用!AI9 -> #DIV/0! | C16: =入力用!AI22 -> #DIV/0! | D16: =入力用!AI35 -> #DIV/0! | E16: =入力用!AI48 -> #DIV/0! | F16: =入力用!AI61 -> #DIV/0!
A17: =入力用!B10 -> 25/7 | B17: =入力用!AI10 -> 56.496552 | C17: =入力用!AI23 -> 23.389655 | D17: =入力用!AI36 -> #DIV/0! | E17: =入力用!AI49 -> 14.241379 | F17: =入力用!AI62 -> 24.9
A18: =入力用!B11 -> 25/8 | B18: =入力用!AI11 -> 56.669565 | C18: =入力用!AI24 -> 23.565217 | D18: =入力用!AI37 -> #DIV/0! | E18: =入力用!AI50 -> 14.082609 | F18: =入力用!AI63 -> 24.521739
A19: =入力用!B12 -> 25/9 | B19: =入力用!AI12 -> #DIV/0! | C19: =入力用!AI25 -> #DIV/0! | D19: =入力用!AI38 -> #DIV/0! | E19: =入力用!AI51 -> #DIV/0! | F19: =入力用!AI64 -> #DIV/0!
A20: =入力用!B13 -> 25/10 | B20: =入力用!AI13 -> 55.87037 | C20: =入力用!AI26 -> 23.333333 | D20: =入力用!AI39 -> #DIV/0! | E20: =入力用!AI52 -> 13.648148 | F20: =入力用!AI65 -> 24.266667
A21: =入力用!B15 -> 25/12 | B21: =入力用!AI15 -> 55.675 | C21: =入力用!AI28 -> 23.285714 | D21: =入力用!AI41 -> #DIV/0! | E21: =入力用!AI54 -> 13.875 | F21: =入力用!AI67 -> 24.546429

Sheet 五十嵐
A2: NSSU Soft tennis Team Inbody Feedback Sheet
A8: 氏名： | B8: =入力用!C2 -> 五十嵐美結 | C8: 性別： | D8: =入力用!AL2 -> 女
A9: 測定日 | B9: 体重 (kg) | C9: 骨格筋量 (kg) | D9: 骨格筋量/体重 (%) | E9: 体脂肪量 (kg) | F9: 体脂肪率 (%)
A10: =入力用!B3 -> 24/12 | B10: =入力用!C3 -> 57.2 | C10: =入力用!C16 -> 22.9 | D10: =入力用!C29 -> 40 | E10: =入力用!C42 -> 16.3 | F10: =入力用!C55 -> 28.5
A11: =入力用!B4 -> 25/1 | B11: =入力用!C4 -> 58.5 | C11: =入力用!C17 -> 23.3 | D11: =入力用!C30 -> 39.8 | E11: =入力用!C43 -> 16.4 | F11: =入力用!C56 -> 28.1
A12: =入力用!B5 -> 25/2 | B12: =入力用!C5 -> 0 | C12: =入力用!C18 -> 0 | D12: =入力用!C31 -> #DIV/0! | E12: =入力用!C44 -> 0 | F12: =入力用!C57 -> 0
A13: =入力用!B6 -> 25/3 | B13: =入力用!C6 -> 58.3 | C13: =入力用!C19 -> 23.6 | D13: =入力用!C32 -> 40.5 | E13: =入力用!C45 -> 16.2 | F13: =入力用!C58 -> 27.7
A14: =入力用!B7 -> 25/4 | B14: =入力用!C7 -> 56.6 | C14: =入力用!C20 -> 23.1 | D14: =入力用!C33 -> 40.8 | E14: =入力用!C46 -> 15.3 | F14: =入力用!C59 -> 27
A15: =入力用!B8 -> 25/5 | B15: =入力用!C8 -> 56.4 | C15: =入力用!C21 -> 23.4 | D15: =入力用!C34 -> 41.5 | E15: =入力用!C47 -> 14.6 | F15: =入力用!C60 -> 25.9
A16: =入力用!B9 -> 25/6 | B16: =入力用!C9 -> 0 | C16: =入力用!C22 -> 0 | D16: =入力用!C35 -> #DIV/0! | E16: =入力用!C48 -> 0 | F16: =入力用!C61 -> 0
A17: =入力用!B10 -> 25/7 | B17: =入力用!C10 -> 56 | C17: =入力用!C23 -> 23.4 | D17: =入力用!C36 -> 41.8 | E17: =入力用!C49 -> 14.1 | F17: =入力用!C62 -> 25.1
A18: =入力用!B11 -> 25/8 | B18: =入力用!C11 -> 0 | C18: =入力用!C24 -> 0 | D18: =入力用!C37 -> #DIV/0! | E18: =入力用!C50 -> 0 | F18: =入力用!C63 -> 0
A19: =入力用!B12 -> 25/9 | B19: =入力用!C12 -> 0 | C19: =入力用!C25 -> 0 | D19: =入力用!C38 -> #DIV/0! | E19: =入力用!C51 -> 0 | F19: =入力用!C64 -> 0
A20: =入力用!B13 -> 25/10 | B20: =入力用!C13 -> 55.4 | C20: =入力用!C26 -> 22.4 | D20: =入力用!C39 -> 40.4 | E20: =入力用!C52 -> 14.6 | F20: =入力用!C65 -> 26.3
A21: =入力用!B15 -> 25/12 | B21: =入力用!C15 -> 55.2 | C21: =入力用!C28 -> 22.2 | D21: =入力用!C41 -> 40.2 | E21: =入力用!C54 -> 15.2 | F21: =入力用!C67 -> 27.5

Sheet 尾崎
A2: NSSU Soft tennis Team Inbody Feedback Sheet
A8: 氏名： | B8: =入力用!D2 -> 尾崎瀬里奈 | C8: 性別： | D8: =入力用!AL2 -> 女
A9: 測定日 | B9: 体重 (kg) | C9: 骨格筋量 (kg) | D9: 骨格筋量/体重 (%) | E9: 体脂肪量 (kg) | F9: 体脂肪率 (%)
A10: =入力用!B3 -> 24/12 | B10: =入力用!D3 -> 48.3 | C10: =入力用!D16 -> 21.7 | D10: =入力用!D29 -> 44.9 | E10: =入力用!D42 -> 8.8 | F10: =入力用!D55 -> 18.2
A11: =入力用!B4 -> 25/1 | B11: =入力用!D4 -> 51.8 | C11: =入力用!D17 -> 23 | D11: =入力用!D30 -> 44.4 | E11: =入力用!D43 -> 10 | F11: =入力用!D56 -> 19.2
A12: =入力用!B5 -> 25/2 | B12: =入力用!D5 -> 0 | C12: =入力用!D18 -> 0 | D12: =入力用!D31 -> #DIV/0! | E12: =入力用!D44 -> 0 | F12: =入力用!D57 -> 0
A13: =入力用!B6 -> 25/3 | B13: =入力用!D6 -> 52.7 | C13: =入力用!D19 -> 23.3 | D13: =入力用!D32 -> 44.2 | E13: =入力用!D45 -> 10.8 | F13: =入力用!D58 -> 20.4
A14: =入力用!B7 -> 25/4 | B14: =入力用!D7 -> 51.3 | C14: =入力用!D20 -> 22.9 | D14: =入力用!D33 -> 44.6 | E14: =入力用!D46 -> 10 | F14: =入力用!D59 -> 19.6
A15: =入力用!B8 -> 25/5 | B15: =入力用!D8 -> 53 | C15: =入力用!D21 -> 23.8 | D15: =入力用!D34 -> 44.9 | E15: =入力用!D47 -> 9.9 | F15: =入力用!D60 -> 18.7
A16: =入力用!B9 -> 25/6 | B16: =入力用!D9 -> 0 | C16: =入力用!D22 -> 0 | D16: =入力用!D35 -> #DIV/0! | E16: =入力用!D48 -> 0 | F16: =入力用!D61 -> 0
A17: =入力用!B10 -> 25/7 | B17: =入力用!D10 -> 52.3 | C17: =入力用!D23 -> 23.3 | D17: =入力用!D36 -> 44.6 | E17: =入力用!D49 -> 10.1 | F17: =入力用!D62 -> 19.3
A18: =入力用!B11 -> 25/8 | B18: =入力用!D11 -> 52.1 | C18: =入力用!D24 -> 23.1 | D18: =入力用!D37 -> 44.3 | E18: =入力用!D50 -> 10.3 | F18: =入力用!D63 -> 19.8
A19: =入力用!B12 -> 25/9 | B19: =入力用!D12 -> 0 | C19: =入力用!D25 -> 0 | D19: =入力用!D38 -> #DIV/0! | E19: =入力用!D51 -> 0 | F19: =入力用!D64 -> 0
A20: =入力用!B13 -> 25/10 | B20: =入力用!D13 -> 52.9 | C20: =入力用!D26 -> 22.5 | D20: =入力用!D39 -> 42.5 | E20: =入力用!D52 -> 12.1 | F20: =入力用!D65 -> 22.9
A21: =入力用!B15 -> 25/12 | B21: =入力用!D15 -> 50.6 | C21: =入力用!D28 -> 21.7 | D21: =入力用!D41 -> 42.9 | E21: =入力用!D54 -> 11.3 | F21: =入力用!D67 -> 22.3

Sheet 樫尾
A2: NSSU Soft tennis Team Inbody Feedback Sheet
A8: 氏名： | B8: =入力用!E2 -> 樫尾陽和里 | C8: 性別： | D8: =入力用!AL2 -> 女
A9: 測定日 | B9: 体重 (kg) | C9: 骨格筋量 (kg) | D9: 骨格筋量/体重 (%) | E9: 体脂肪量 (kg) | F9: 体脂肪率 (%)
A10: =入力用!B3 -> 24/12 | B10: =入力用!E3 -> 63.3 | C10: =入力用!E16 -> 24.1 | D10: =入力用!E29 -> 38.1 | E10: =入力用!E42 -> 19.9 | F10: =入力用!E55 -> 31.5
A11: =入力用!B4 -> 25/1 | B11: =入力用!E4 -> 62.8 | C11: =入力用!E17 -> 23.9 | D11: =入力用!E30 -> 38.1 | E11: =入力用!E43 -> 19.6 | F11: =入力用!E56 -> 31.3
A12: =入力用!B5 -> 25/2 | B12: =入力用!E5 -> 0 | C12: =入力用!E18 -> 0 | D12: =入力用!E31 -> #DIV/0! | E12: =入力用!E44 -> 0 | F12: =入力用!E57 -> 0
A13: =入力用!B6 -> 25/3 | B13: =入力用!E6 -> 63.3 | C13: =入力用!E19 -> 24 | D13: =入力用!E32 -> 37.9 | E13: =入力用!E45 -> 20 | F13: =入力用!E58 -> 31.6
A14: =入力用!B7 -> 25/4 | B14: =入力用!E7 -> 63.2 | C14: =入力用!E20 -> 24.1 | D14: =入力用!E33 -> 38.1 | E14: =入力用!E46 -> 19.9 | F14: =入力用!E59 -> 31.5
A15: =入力用!B8 -> 25/5 | B15: =入力用!E8 -> 62.5 | C15: =入力用!E21 -> 23.1 | D15: =入力用!E34 -> 37 | E15: =入力用!E47 -> 20.9 | F15: =入力用!E60 -> 33.5
A16: =入力用!B9 -> 25/6 | B16: =入力用!E9 -> 0 | C16: =入力用!E22 -> 0 | D16: =入力用!E35 -> #DIV/0! | E16: =入力用!E48 -> 0 | F16: =入力用!E61 -> 0
A17: =入力用!B10 -> 25/7 | B17: =入力用!E10 -> 61 | C17: =入力用!E23 -> 22.8 | D17: =入力用!E36 -> 37.4 | E17: =入力用!E49 -> 19.5 | F17: =入力用!E62 -> 31.9
A18: =入力用!B11 -> 25/8 | B18: =入力用!E11 -> 63.1 | C18: =入力用!E24 -> 24.1 | D18: =入力用!E37 -> 38.2 | E18: =入力用!E50 -> 19.5 | F18: =入力用!E63 -> 31
A19: =入力用!B12 -> 25/9 | B19: =入力用!E12 -> 0 | C19: =入力用!E25 -> 0 | D19: =入力用!E38 -> #DIV/0! | E19: =入力用!E51 -> 0 | F19: =入力用!E64 -> 0
A20: =入力用!B13 -> 25/10 | B20: =入力用!E13 -> 0 | C20: =入力用!E26 -> 0 | D20: =入力用!E39 -> #DIV/0! | E20: =入力用!E52 -> 0 | F20: =入力用!E65 -> 0
A21: =入力用!B15 -> 25/12 | B21: =入力用!E15 -> 65.2 | C21: =入力用!E28 -> 24.3 | D21: =入力用!E41 -> 37.3 | E21: =入力用!E54 -> 21.5 | F21: =入力用!E67 -> 32.9

Sheet 左近
A2: NSSU Soft tennis Team Inbody Feedback Sheet
A8: 氏名： | B8: 左近知美 | C8: 性別： | D8: 女
A9: 測定日 | B9: 体重 (kg) | C9: 骨格筋量 (kg) | D9: 骨格筋量/体重 (%) | E9: 体脂肪量 (kg) | F9: 体脂肪率 (%)
A10: =入力用!B3 -> 24/12 | B10: =入力用!F3 -> 57.1 | C10: =入力用!F16 -> 25.5 | D10: =入力用!F29 -> 44.7 | E10: =入力用!F42 -> 11.5 | F10: =入力用!F55 -> 20.1
A11: =入力用!B4 -> 25/1 | B11: =入力用!F4 -> 56.1 | C11: =入力用!F17 -> 25.2 | D11: =入力用!F30 -> 44.9 | E11: =入力用!F43 -> 11.6 | F11: =入力用!F56 -> 20.7
A12: =入力用!B5 -> 25/2 | B12: =入力用!F5 -> 0 | C12: =入力用!F18 -> 0 | D12: =入力用!F31 -> #DIV/0! | E12: =入力用!F44 -> 0 | F12: =入力用!F57 -> 0
A13: =入力用!B6 -> 25/3 | B13: =入力用!F6 -> 55.3 | C13: =入力用!F19 -> 24.7 | D13: =入力用!F32 -> 44.7 | E13: =入力用!F45 -> 11.6 | F13: =入力用!F58 -> 20.9
A14: =入力用!B7 -> 25/4 | B14: =入力用!F7 -> 56.4 | C14: =入力用!F20 -> 25.2 | D14: =入力用!F33 -> 44.7 | E14: =入力用!F46 -> 11.5 | F14: =入力用!F59 -> 20.3
A15: =入力用!B8 -> 25/5 | B15: =入力用!F8 -> 0 | C15: =入力用!F21 -> 0 | D15: =入力用!F34 -> #DIV/0! | E15: =入力用!F47 -> 0 | F15: =入力用!F60 -> 0
A16: =入力用!B9 -> 25/6 | B16: =入力用!F9 -> 0 | C16: =入力用!F22 -> 0 | D16: =入力用!F35 -> #DIV/0! | E16: =入力用!F48 -> 0 | F16: =入力用!F61 -> 0
A17: =入力用!B10 -> 25/7 | B17: =入力用!F10 -> 56.2 | C17: =入力用!F23 -> 25.5 | D17: =入力用!F36 -> 45.4 | E17: =入力用!F49 -> 10.4 | F17: =入力用!F62 -> 18.6
A18: =入力用!B11 -> 25/8 | B18: =入力用!F11 -> 55.4 | C18: =入力用!F24 -> 25.5 | D18: =入力用!F37 -> 46 | E18: =入力用!F50 -> 9.8 | F18: =入力用!F63 -> 17.7
A19: =入力用!B12 -> 25/9 | B19: =入力用!F12 -> 0 | C19: =入力用!F25 -> 0 | D19: =入力用!F38 -> #DIV/0! | E19: =入力用!F51 -> 0 | F19: =入力用!F64 -> 0
A20: =入力用!B13 -> 25/10 | B20: =入力用!F13 -> 53.5 | C20: =入力用!F26 -> 24.6 | D20: =入力用!F39 -> 46 | E20: =入力用!F52 -> 9.8 | F20: =入力用!F65 -> 18.2
A21: =入力用!B15 -> 25/12 | B21: =入力用!F15 -> 56.5 | C21: =入力用!F28 -> 25.1 | D21: =入力用!F41 -> 44.4 | E21: =入力用!F54 -> 12 | F21: =入力用!F67 -> 21.2

Sheet 竹本
A2: NSSU Soft tennis Team Inbody Feedback Sheet
A8: 氏名： | B8: 竹本萌花 | C8: 性別： | D8: 女
A9: 測定日 | B9: 体重 (kg) | C9: 骨格筋量 (kg) | D9: 骨格筋量/体重 (%) | E9: 体脂肪量 (kg) | F9: 体脂肪率 (%)
A10: =入力用!B3 -> 24/12 | B10: =入力用!G3 -> 57 | C10: =入力用!G16 -> 22.5 | D10: =入力用!G29 -> 39.5 | E10: =入力用!G42 -> 16.4 | F10: =入力用!G55 -> 28.8
A11: =入力用!B4 -> 25/1 | B11: =入力用!G4 -> 56.4 | C11: =入力用!G17 -> 22.2 | D11: =入力用!G30 -> 39.4 | E11: =入力用!G43 -> 16.1 | F11: =入力用!G56 -> 28.6
A12: =入力用!B5 -> 25/2 | B12: =入力用!G5 -> 0 | C12: =入力用!G18 -> 0 | D12: =入力用!G31 -> #DIV/0! | E12: =入力用!G44 -> 0 | F12: =入力用!G57 -> 0
A13: =入力用!B6 -> 25/3 | B13: =入力用!G6 -> 57.4 | C13: =入力用!G19 -> 22.8 | D13: =入力用!G32 -> 39.7 | E13: =入力用!G45 -> 16.1 | F13: =入力用!G58 -> 28
A14: =入力用!B7 -> 25/4 | B14: =入力用!G7 -> 56.2 | C14: =入力用!G20 -> 21.8 | D14: =入力用!G33 -> 38.8 | E14: =入力用!G46 -> 16.6 | F14: =入力用!G59 -> 29.5
A15: =入力用!B8 -> 25/5 | B15: =入力用!G8 -> 56.9 | C15: =入力用!G21 -> 21.7 | D15: =入力用!G34 -> 38.1 | E15: =入力用!G47 -> 17.5 | F15: =入力用!G60 -> 30.8
A16: =入力用!B9 -> 25/6 | B16: =入力用!G9 -> 0 | C16: =入力用!G22 -> 0 | D16: =入力用!G35 -> #DIV/0! | E16: =入力用!G48 -> 0 | F16: =入力用!G61 -> 0
A17: =入力用!B10 -> 25/7 | B17: =入力用!G10 -> 0 | C17: =入力用!G23 -> 0 | D17: =入力用!G36 -> #DIV/0! | E17: =入力用!G49 -> 0 | F17: =入力用!G62 -> 0
A18: =入力用!B11 -> 25/8 | B18: =入力用!G11 -> 56 | C18: =入力用!G24 -> 21.6 | D18: =入力用!G37 -> 38.6 | E18: =入力用!G50 -> 16.5 | F18: =入力用!G63 -> 29.4
A19: =入力用!B12 -> 25/9 | B19: =入力用!G12 -> 0 | C19: =入力用!G25 -> 0 | D19: =入力用!G38 -> #DIV/0! | E19: =入力用!G51 -> 0 | F19: =入力用!G64 -> 0
A20: =入力用!B13 -> 25/10 | B20: =入力用!G13 -> 0 | C20: =入力用!G26 -> 0 | D20: =入力用!G39 -> #DIV/0! | E20: =入力用!G52 -> 0 | F20: =入力用!G65 -> 0
A21: =入力用!B15 -> 25/12 | B21: =入力用!G15 -> 0 | C21: =入力用!G28 -> 0 | D21: =入力用!G41 -> #DIV/0! | E21: =入力用!G54 -> 0 | F21: =入力用!G67 -> 0

Sheet 達
A2: NSSU Soft tennis Team Inbody Feedback Sheet
A8: 氏名： | B8: 達光咲 | C8: 性別： | D8: 女
A9: 測定日 | B9: 体重 (kg) | C9: 骨格筋量 (kg) | D9: 骨格筋量/体重 (%) | E9: 体脂肪量 (kg) | F9: 体脂肪率 (%)
A10: =入力用!B3 -> 24/12 | B10: =入力用!H3 -> 47 | C10: =入力用!H16 -> 20.8 | D10: =入力用!H29 -> 44.3 | E10: =入力用!H42 -> 8.9 | F10: =入力用!H55 -> 19
A11: =入力用!B4 -> 25/1 | B11: =入力用!H4 -> 46.6 | C11: =入力用!H17 -> 20.2 | D11: =入力用!H30 -> 43.3 | E11: =入力用!H43 -> 9.6 | F11: =入力用!H56 -> 20.6
A12: =入力用!B5 -> 25/2 | B12: =入力用!H5 -> 0 | C12: =入力用!H18 -> 0 | D12: =入力用!H31 -> #DIV/0! | E12: =入力用!H44 -> 0 | F12: =入力用!H57 -> 0
A13: =入力用!B6 -> 25/3 | B13: =入力用!H6 -> 47.3 | C13: =入力用!H19 -> 21 | D13: =入力用!H32 -> 44.4 | E13: =入力用!H45 -> 9.1 | F13: =入力用!H58 -> 19.1
A14: =入力用!B7 -> 25/4 | B14: =入力用!H7 -> 47.7 | C14: =入力用!H20 -> 21.1 | D14: =入力用!H33 -> 44.2 | E14: =入力用!H46 -> 9.1 | F14: =入力用!H59 -> 20
A15: =入力用!B8 -> 25/5 | B15: =入力用!H8 -> 0 | C15: =入力用!H21 -> 0 | D15: =入力用!H34 -> #DIV/0! | E15: =入力用!H47 -> 0 | F15: =入力用!H60 -> 0
A16: =入力用!B9 -> 25/6 | B16: =入力用!H9 -> 0 | C16: =入力用!H22 -> 0 | D16: =入力用!H35 -> #DIV/0! | E16: =入力用!H48 -> 0 | F16: =入力用!H61 -> 0
A17: =入力用!B10 -> 25/7 | B17: =入力用!H10 -> 46 | C17: =入力用!H23 -> 19.9 | D17: =入力用!H36 -> 43.3 | E17: =入力用!H49 -> 9.2 | F17: =入力用!H62 -> 20
A18: =入力用!B11 -> 25/8 | B18: =入力用!H11 -> 45.8 | C18: =入力用!H24 -> 20.8 | D18: =入力用!H37 -> 45.4 | E18: =入力用!H50 -> 8 | F18: =入力用!H63 -> 17.5
A19: =入力用!B12 -> 25/9 | B19: =入力用!H12 -> 0 | C19: =入力用!H25 -> 0 | D19: =入力用!H38 -> #DIV/0! | E19: =入力用!H51 -> 0 | F19: =入力用!H64 -> 0
A20: =入力用!B13 -> 25/10 | B20: =入力用!H13 -> 0 | C20: =入力用!H26 -> 0 | D20: =入力用!H39 -> #DIV/0! | E20: =入力用!H52 -> 0 | F20: =入力用!H65 -> 0
A21: =入力用!B15 -> 25/12 | B21: =入力用!H15 -> 0 | C21: =入力用!H28 -> 0 | D21: =入力用!H41 -> #DIV/0! | E21: =入力用!H54 -> 0 | F21: =入力用!H67 -> 0

Sheet 生井沢
A2: NSSU Soft tennis Team Inbody Feedback Sheet
A8: 氏名： | B8: 生井沢日向子 | C8: 性別： | D8: 女
A9: 測定日 | B9: 体重 (kg) | C9: 骨格筋量 (kg) | D9: 骨格筋量/体重 (%) | E9: 体脂肪量 (kg) | F9: 体脂肪率 (%)
A10: =入力用!B3 -> 24/12 | B10: =入力用!I3 -> 62.6 | C10: =入力用!I16 -> 25.3 | D10: =入力用!I29 -> 40.4 | E10: =入力用!I42 -> 17.2 | F10: =入力用!I55 -> 27.5
A11: =入力用!B4 -> 25/1 | B11: =入力用!I4 -> 65.3 | C11: =入力用!I17 -> 26.2 | D11: =入力用!I30 -> 40.1 | E11: =入力用!I43 -> 18.2 | F11: =入力用!I56 -> 27.9
A12: =入力用!B5 -> 25/2 | B12: =入力用!I5 -> 0 | C12: =入力用!I18 -> 0 | D12: =入力用!I31 -> #DIV/0! | E12: =入力用!I44 -> 0 | F12: =入力用!I57 -> 0
A13: =入力用!B6 -> 25/3 | B13: =入力用!I6 -> 66 | C13: =入力用!I19 -> 27 | D13: =入力用!I32 -> 40.9 | E13: =入力用!I45 -> 17.7 | F13: =入力用!I58 -> 26.8
A14: =入力用!B7 -> 25/4 | B14: =入力用!I7 -> 64.8 | C14: =入力用!I20 -> 25.8 | D14: =入力用!I33 -> 39.8 | E14: =入力用!I46 -> 18.5 | F14: =入力用!I59 -> 28.6
A15: =入力用!B8 -> 25/5 | B15: =入力用!I8 -> 0 | C15: =入力用!I21 -> 0 | D15: =入力用!I34 -> #DIV/0! | E15: =入力用!I47 -> 0 | F15: =入力用!I60 -> 0
A16: =入力用!B9 -> 25/6 | B16: =入力用!I9 -> 0 | C16: =入力用!I22 -> 0 | D16: =入力用!I35 -> #DIV/0! | E16: =入力用!I48 -> 0 | F16: =入力用!I61 -> 0
A17: =入力用!B10 -> 25/7 | B17: =入力用!I10 -> 60.7 | C17: =入力用!I23 -> 25.1 | D17: =入力用!I36 -> 41.4 | E17: =入力用!I49 -> 15.2 | F17: =入力用!I62 -> 25.1
A18: =入力用!B11 -> 25/8 | B18: =入力用!I11 -> 61.7 | C18: =入力用!I24 -> 25.4 | D18: =入力用!I37 -> 41.2 | E18: =入力用!I50 -> 16.1 | F18: =入力用!I63 -> 26.2
A19: =入力用!B12 -> 25/9 | B19: =入力用!I12 -> 0 | C19: =入力用!I25 -> 0 | D19: =入力用!I38 -> #DIV/0! | E19: =入力用!I51 -> 0 | F19: =入力用!I64 -> 0
A20: =入力用!B13 -> 25/10 | B20: =入力用!I13 -> 62.5 | C20: =入力用!I26 -> 25.7 | D20: =入力用!I39 -> 41.1 | E20: =入力用!I52 -> 16.1 | F20: =入力用!I65 -> 25.8
A21: =入力用!B15 -> 25/12 | B21: =入力用!I15 -> 61.9 | C21: =入力用!I28 -> 25.6 | D21: =入力用!I41 -> 41.4 | E21: =入力用!I54 -> 16 | F21: =入力用!I67 -> 25.9

Sheet 原田
A2: NSSU Soft tennis Team Inbody Feedback Sheet
A8: 氏名： | B8: 原田美結 | C8: 性別： | D8: 女
A9: 測定日 | B9: 体重 (kg) | C9: 骨格筋量 (kg) | D9: 骨格筋量/体重 (%) | E9: 体脂肪量 (kg) | F9: 体脂肪率 (%)
A10: =入力用!B3 -> 24/12 | B10: =入力用!J3 -> 54.2 | C10: =入力用!J16 -> 22.5 | D10: =入力用!J29 -> 41.5 | E10: =入力用!J42 -> 12.9 | F10: =入力用!J55 -> 23.8
A11: =入力用!B4 -> 25/1 | B11: =入力用!J4 -> 54.3 | C11: =入力用!J17 -> 23.2 | D11: =入力用!J30 -> 42.7 | E11: =入力用!J43 -> 11.6 | F11: =入力用!J56 -> 21.4
A12: =入力用!B5 -> 25/2 | B12: =入力用!J5 -> 0 | C12: =入力用!J18 -> 0 | D12: =入力用!J31 -> #DIV/0! | E12: =入力用!J44 -> 0 | F12: =入力用!J57 -> 0
A13: =入力用!B6 -> 25/3 | B13: =入力用!J6 -> 55.1 | C13: =入力用!J19 -> 22.5 | D13: =入力用!J32 -> 40.8 | E13: =入力用!J45 -> 14.1 | F13: =入力用!J58 -> 25.7
A14: =入力用!B7 -> 25/4 | B14: =入力用!J7 -> 56.3 | C14: =入力用!J20 -> 22.7 | D14: =入力用!J33 -> 40.3 | E14: =入力用!J46 -> 15.1 | F14: =入力用!J59 -> 26.9
A15: =入力用!B8 -> 25/5 | B15: =入力用!J8 -> 0 | C15: =入力用!J21 -> 0 | D15: =入力用!J34 -> #DIV/0! | E15: =入力用!J47 -> 0 | F15: =入力用!J60 -> 0
A16: =入力用!B9 -> 25/6 | B16: =入力用!J9 -> 0 | C16: =入力用!J22 -> 0 | D16: =入力用!J35 -> #DIV/0! | E16: =入力用!J48 -> 0 | F16: =入力用!J61 -> 0
A17: =入力用!B10 -> 25/7 | B17: =入力用!J10 -> 54.8 | C17: =入力用!J23 -> 22.9 | D17: =入力用!J36 -> 41.8 | E17: =入力用!J49 -> 13.1 | F17: =入力用!J62 -> 23.8
A18: =入力用!B11 -> 25/8 | B18: =入力用!J11 -> 0 | C18: =入力用!J24 -> 0 | D18: =入力用!J37 -> #DIV/0! | E18: =入力用!J50 -> 0 | F18: =入力用!J63 -> 0
A19: =入力用!B12 -> 25/9 | B19: =入力用!J12 -> 0 | C19: =入力用!J25 -> 0 | D19: =入力用!J38 -> #DIV/0! | E19: =入力用!J51 -> 0 | F19: =入力用!J64 -> 0
A20: =入力用!B13 -> 25/10 | B20: =入力用!J13 -> 0 | C20: =入力用!J26 -> 0 | D20: =入力用!J39 -> #DIV/0! | E20: =入力用!J52 -> 0 | F20: =入力用!J65 -> 0
A21: =入力用!B15 -> 25/12 | B21: =入力用!J15 -> 0 | C21: =入力用!J28 -> 0 | D21: =入力用!J41 -> #DIV/0! | E21: =入力用!J54 -> 0 | F21: =入力用!J67 -> 0

Sheet 藤原
A2: NSSU Soft tennis Team Inbody Feedback Sheet
A8: 氏名： | B8: 藤原未凪 | C8: 性別： | D8: 女
A9: 測定日 | B9: 体重 (kg) | C9: 骨格筋量 (kg) | D9: 骨格筋量/体重 (%) | E9: 体脂肪量 (kg) | F9: 体脂肪率 (%)
A10: =入力用!B3 -> 24/12 | B10: =入力用!K3 -> 66.1 | C10: =入力用!K16 -> 24.4 | D10: =入力用!K29 -> 36.9 | E10: =入力用!K42 -> 20.7 | F10: =入力用!K55 -> 31.9
A11: =入力用!B4 -> 25/1 | B11: =入力用!K4 -> 67.6 | C11: =入力用!K17 -> 25 | D11: =入力用!K30 -> 37 | E11: =入力用!K43 -> 22.1 | F11: =入力用!K56 -> 32.7
A12: =入力用!B5 -> 25/2 | B12: =入力用!K5 -> 0 | C12: =入力用!K18 -> 0 | D12: =入力用!K31 -> #DIV/0! | E12: =入力用!K44 -> 0 | F12: =入力用!K57 -> 0
A13: =入力用!B6 -> 25/3 | B13: =入力用!K6 -> 69 | C13: =入力用!K19 -> 25.2 | D13: =入力用!K32 -> 36.5 | E13: =入力用!K45 -> 23.7 | F13: =入力用!K58 -> 34.4
A14: =入力用!B7 -> 25/4 | B14: =入力用!K7 -> 68 | C14: =入力用!K20 -> 25.1 | D14: =入力用!K33 -> 36.9 | E14: =入力用!K46 -> 22.6 | F14: =入力用!K59 -> 33.2
A15: =入力用!B8 -> 25/5 | B15: =入力用!K8 -> 0 | C15: =入力用!K21 -> 0 | D15: =入力用!K34 -> #DIV/0! | E15: =入力用!K47 -> 0 | F15: =入力用!K60 -> 0
A16: =入力用!B9 -> 25/6 | B16: =入力用!K9 -> 0 | C16: =入力用!K22 -> 0 | D16: =入力用!K35 -> #DIV/0! | E16: =入力用!K48 -> 0 | F16: =入力用!K61 -> 0
A17: =入力用!B10 -> 25/7 | B17: =入力用!K10 -> 69.9 | C17: =入力用!K23 -> 25.9 | D17: =入力用!K36 -> 37.1 | E17: =入力用!K49 -> 23 | F17: =入力用!K62 -> 32.9
A18: =入力用!B11 -> 25/8 | B18: =入力用!K11 -> 69.4 | C18: =入力用!K24 -> 25.3 | D18: =入力用!K37 -> 36.5 | E18: =入力用!K50 -> 23.5 | F18: =入力用!K63 -> 33.8
A19: =入力用!B12 -> 25/9 | B19: =入力用!K12 -> 0 | C19: =入力用!K25 -> 0 | D19: =入力用!K38 -> #DIV/0! | E19: =入力用!K51 -> 0 | F19: =入力用!K64 -> 0
A20: =入力用!B13 -> 25/10 | B20: =入力用!K13 -> 0 | C20: =入力用!K26 -> 0 | D20: =入力用!K39 -> #DIV/0! | E20: =入力用!K52 -> 0 | F20: =入力用!K65 -> 0
A21: =入力用!B15 -> 25/12 | B21: =入力用!K15 -> 0 | C21: =入力用!K28 -> 0 | D21: =入力用!K41 -> #DIV/0! | E21: =入力用!K54 -> 0 | F21: =入力用!K67 -> 0

Sheet 細田
A2: NSSU Soft tennis Team Inbody Feedback Sheet
A8: 氏名： | B8: =入力用!L2 -> 細田美帆 | C8: 性別： | D8: =入力用!AL2 -> 女
A9: 測定日 | B9: 体重 (kg) | C9: 骨格筋量 (kg) | D9: 骨格筋量/体重 (%) | E9: 体脂肪量 (kg) | F9: 体脂肪率 (%)
A10: =入力用!B3 -> 24/12 | B10: =入力用!L3 -> 51.6 | C10: =入力用!L16 -> 22.2 | D10: =入力用!L29 -> 43 | E10: =入力用!L42 -> 11.7 | F10: =入力用!L55 -> 22.6
A11: =入力用!B4 -> 25/1 | B11: =入力用!L4 -> 52.3 | C11: =入力用!L17 -> 22.7 | D11: =入力用!L30 -> 43.4 | E11: =入力用!L43 -> 11.5 | F11: =入力用!L56 -> 21.9
A12: =入力用!B5 -> 25/2 | B12: =入力用!L5 -> 0 | C12: =入力用!L18 -> 0 | D12: =入力用!L31 -> #DIV/0! | E12: =入力用!L44 -> 0 | F12: =入力用!L57 -> 0
A13: =入力用!B6 -> 25/3 | B13: =入力用!L6 -> 53.4 | C13: =入力用!L19 -> 22.9 | D13: =入力用!L32 -> 42.9 | E13: =入力用!L45 -> 12.3 | F13: =入力用!L58 -> 23.1
A14: =入力用!B7 -> 25/4 | B14: =入力用!L7 -> 0 | C14: =入力用!L20 -> 0 | D14: =入力用!L33 -> #DIV/0! | E14: =入力用!L46 -> 0 | F14: =入力用!L59 -> 0
A15: =入力用!B8 -> 25/5 | B15: =入力用!L8 -> 52.5 | C15: =入力用!L21 -> 22.4 | D15: =入力用!L34 -> 42.7 | E15: =入力用!L47 -> 12.2 | F15: =入力用!L60 -> 23.2
A16: =入力用!B9 -> 25/6 | B16: =入力用!L9 -> 0 | C16: =入力用!L22 -> 0 | D16: =入力用!L35 -> #DIV/0! | E16: =入力用!L48 -> 0 | F16: =入力用!L61 -> 0
A17: =入力用!B10 -> 25/7 | B17: =入力用!L10 -> 0 | C17: =入力用!L23 -> 0 | D17: =入力用!L36 -> #DIV/0! | E17: =入力用!L49 -> 0 | F17: =入力用!L62 -> 0
A18: =入力用!B11 -> 25/8 | B18: =入力用!L11 -> 0 | C18: =入力用!L24 -> 0 | D18: =入力用!L37 -> #DIV/0! | E18: =入力用!L50 -> 0 | F18: =入力用!L63 -> 0
A19: =入力用!B12 -> 25/9 | B19: =入力用!L12 -> 0 | C19: =入力用!L25 -> 0 | D19: =入力用!L38 -> #DIV/0! | E19: =入力用!L51 -> 0 | F19: =入力用!L64 -> 0
A20: =入力用!B13 -> 25/10 | B20: =入力用!L13 -> 53 | C20: =入力用!L26 -> 22.8 | D20: =入力用!L39 -> 43 | E20: =入力用!L52 -> 11.4 | F20: =入力用!L65 -> 21.5
A21: =入力用!B15 -> 25/12 | B21: =入力用!L15 -> 51.9 | C21: =入力用!L28 -> 21.5 | D21: =入力用!L41 -> 41.4 | E21: =入力用!L54 -> 13 | F21: =入力用!L67 -> 25.1

Sheet 入澤
A2: NSSU Soft tennis Team Inbody Feedback Sheet
A8: 氏名： | B8: =入力用!M2 -> 入澤瑛麻 | C8: 性別： | D8: =入力用!AL2 -> 女
A9: 測定日 | B9: 体重 (kg) | C9: 骨格筋量 (kg) | D9: 骨格筋量/体重 (%) | E9: 体脂肪量 (kg) | F9: 体脂肪率 (%)
A10: =入力用!B3 -> 24/12 | B10: =入力用!M3 -> 43.9 | C10: =入力用!M16 -> 18.9 | D10: =入力用!M29 -> 43.1 | E10: =入力用!M42 -> 9.3 | F10: =入力用!M55 -> 21.2
A11: =入力用!B4 -> 25/1 | B11: =入力用!M4 -> 45.1 | C11: =入力用!M17 -> 18.4 | D11: =入力用!M30 -> 40.8 | E11: =入力用!M43 -> 11 | F11: =入力用!M56 -> 24.4
A12: =入力用!B5 -> 25/2 | B12: =入力用!M5 -> 0 | C12: =入力用!M18 -> 0 | D12: =入力用!M31 -> #DIV/0! | E12: =入力用!M44 -> 0 | F12: =入力用!M57 -> 0
A13: =入力用!B6 -> 25/3 | B13: =入力用!M6 -> 44.3 | C13: =入力用!M19 -> 19 | D13: =入力用!M32 -> 42.9 | E13: =入力用!M45 -> 9.6 | F13: =入力用!M58 -> 21.6
A14: =入力用!B7 -> 25/4 | B14: =入力用!M7 -> 43.2 | C14: =入力用!M20 -> 18.2 | D14: =入力用!M33 -> 42.1 | E14: =入力用!M46 -> 9.6 | F14: =入力用!M59 -> 22.1
A15: =入力用!B8 -> 25/5 | B15: =入力用!M8 -> 42.6 | C15: =入力用!M21 -> 18.6 | D15: =入力用!M34 -> 43.7 | E15: =入力用!M47 -> 8.5 | F15: =入力用!M60 -> 20
A16: =入力用!B9 -> 25/6 | B16: =入力用!M9 -> 0 | C16: =入力用!M22 -> 0 | D16: =入力用!M35 -> #DIV/0! | E16: =入力用!M48 -> 0 | F16: =入力用!M61 -> 0
A17: =入力用!B10 -> 25/7 | B17: =入力用!M10 -> 43.5 | C17: =入力用!M23 -> 18.4 | D17: =入力用!M36 -> 42.3 | E17: =入力用!M49 -> 9.3 | F17: =入力用!M62 -> 21.4
A18: =入力用!B11 -> 25/8 | B18: =入力用!M11 -> 0 | C18: =入力用!M24 -> 0 | D18: =入力用!M37 -> #DIV/0! | E18: =入力用!M50 -> 0 | F18: =入力用!M63 -> 0
A19: =入力用!B12 -> 25/9 | B19: =入力用!M12 -> 0 | C19: =入力用!M25 -> 0 | D19: =入力用!M38 -> #DIV/0! | E19: =入力用!M51 -> 0 | F19: =入力用!M64 -> 0
A20: =入力用!B13 -> 25/10 | B20: =入力用!M13 -> 42.3 | C20: =入力用!M26 -> 18.5 | D20: =入力用!M39 -> 43.7 | E20: =入力用!M52 -> 8.5 | F20: =入力用!M65 -> 20
A21: =入力用!B15 -> 25/12 | B21: =入力用!M15 -> 42.7 | C21: =入力用!M28 -> 18.5 | D21: =入力用!M41 -> 43.3 | E21: =入力用!M54 -> 8.6 | F21: =入力用!M67 -> 20.1

Sheet 橋本
A2: NSSU Soft tennis Team Inbody Feedback Sheet
A8: 氏名： | B8: =入力用!R2 -> 橋本和香菜 | C8: 性別： | D8: =入力用!AL2 -> 女
A9: 測定日 | B9: 体重 (kg) | C9: 骨格筋量 (kg) | D9: 骨格筋量/体重 (%) | E9: 体脂肪量 (kg) | F9: 体脂肪率 (%)
A10: =入力用!B3 -> 24/12 | B10: =入力用!R3 -> 48 | C10: =入力用!R16 -> 20.9 | D10: =入力用!R29 -> 43.5 | E10: =入力用!R42 -> 10.1 | F10: =入力用!R55 -> 21
A11: =入力用!B4 -> 25/1 | B11: =入力用!R4 -> 48 | C11: =入力用!R17 -> 20.1 | D11: =入力用!R30 -> 41.9 | E11: =入力用!R43 -> 10.8 | F11: =入力用!R56 -> 22.4
A12: =入力用!B5 -> 25/2 | B12: =入力用!R5 -> 0 | C12: =入力用!R18 -> 0 | D12: =入力用!R31 -> #DIV/0! | E12: =入力用!R44 -> 0 | F12: =入力用!R57 -> 0
A13: =入力用!B6 -> 25/3 | B13: =入力用!R6 -> 49.4 | C13: =入力用!R19 -> 21.5 | D13: =入力用!R32 -> 43.5 | E13: =入力用!R45 -> 10.3 | F13: =入力用!R58 -> 20.9
A14: =入力用!B7 -> 25/4 | B14: =入力用!R7 -> 50.3 | C14: =入力用!R20 -> 21.4 | D14: =入力用!R33 -> 42.5 | E14: =入力用!R46 -> 11.1 | F14: =入力用!R59 -> 22
A15: =入力用!B8 -> 25/5 | B15: =入力用!R8 -> 49.6 | C15: =入力用!R21 -> 21.7 | D15: =入力用!R34 -> 43.8 | E15: =入力用!R47 -> 10.3 | F15: =入力用!R60 -> 20.8
A16: =入力用!B9 -> 25/6 | B16: =入力用!R9 -> 0 | C16: =入力用!R22 -> 0 | D16: =入力用!R35 -> #DIV/0! | E16: =入力用!R48 -> 0 | F16: =入力用!R61 -> 0
A17: =入力用!B10 -> 25/7 | B17: =入力用!R10 -> 47.5 | C17: =入力用!R23 -> 21 | D17: =入力用!R36 -> 44.2 | E17: =入力用!R49 -> 9.1 | F17: =入力用!R62 -> 19.1
A18: =入力用!B11 -> 25/8 | B18: =入力用!R11 -> 48.9 | C18: =入力用!R24 -> 21 | D18: =入力用!R37 -> 42.9 | E18: =入力用!R50 -> 10 | F18: =入力用!R63 -> 20.4
A19: =入力用!B12 -> 25/9 | B19: =入力用!R12 -> 0 | C19: =入力用!R25 -> 0 | D19: =入力用!R38 -> #DIV/0! | E19: =入力用!R51 -> 0 | F19: =入力用!R64 -> 0
A20: =入力用!B13 -> 25/10 | B20: =入力用!R13 -> 47.7 | C20: =入力用!R26 -> 21.1 | D20: =入力用!R39 -> 44.2 | E20: =入力用!R52 -> 9 | F20: =入力用!R65 -> 18.9
A21: =入力用!B15 -> 25/12 | B21: =入力用!R15 -> 48.7 | C21: =入力用!R28 -> 21.3 | D21: =入力用!R41 -> 43.7 | E21: =入力用!R54 -> 9.7 | F21: =入力用!R67 -> 20

Sheet 加藤
A2: NSSU Soft tennis Team Inbody Feedback Sheet
A8: 氏名： | B8: =入力用!N2 -> 加藤華 | C8: 性別： | D8: =入力用!AL2 -> 女
A9: 測定日 | B9: 体重 (kg) | C9: 骨格筋量 (kg) | D9: 骨格筋量/体重 (%) | E9: 体脂肪量 (kg) | F9: 体脂肪率 (%)
A10: =入力用!B3 -> 24/12 | B10: =入力用!N3 -> 49.7 | C10: =入力用!N16 -> 19.8 | D10: =入力用!N29 -> 39.8 | E10: =入力用!N42 -> 13.2 | F10: =入力用!N55 -> 26.6
A11: =入力用!B4 -> 25/1 | B11: =入力用!N4 -> 50.7 | C11: =入力用!N17 -> 19.9 | D11: =入力用!N30 -> 39.3 | E11: =入力用!N43 -> 14.1 | F11: =入力用!N56 -> 27.9
A12: =入力用!B5 -> 25/2 | B12: =入力用!N5 -> 0 | C12: =入力用!N18 -> 0 | D12: =入力用!N31 -> #DIV/0! | E12: =入力用!N44 -> 0 | F12: =入力用!N57 -> 0
A13: =入力用!B6 -> 25/3 | B13: =入力用!N6 -> 50.4 | C13: =入力用!N19 -> 20.1 | D13: =入力用!N32 -> 39.9 | E13: =入力用!N45 -> 13.7 | F13: =入力用!N58 -> 27.3
A14: =入力用!B7 -> 25/4 | B14: =入力用!N7 -> 50.8 | C14: =入力用!N20 -> 21.8 | D14: =入力用!N33 -> 42.9 | E14: =入力用!N46 -> 11.6 | F14: =入力用!N59 -> 22.9
A15: =入力用!B8 -> 25/5 | B15: =入力用!N8 -> 51 | C15: =入力用!N21 -> 20.8 | D15: =入力用!N34 -> 40.8 | E15: =入力用!N47 -> 13.2 | F15: =入力用!N60 -> 25.8
A16: =入力用!B9 -> 25/6 | B16: =入力用!N9 -> 0 | C16: =入力用!N22 -> 0 | D16: =入力用!N35 -> #DIV/0! | E16: =入力用!N48 -> 0 | F16: =入力用!N61 -> 0
A17: =入力用!B10 -> 25/7 | B17: =入力用!N10 -> 51.2 | C17: =入力用!N23 -> 21.3 | D17: =入力用!N36 -> 41.6 | E17: =入力用!N49 -> 12.6 | F17: =入力用!N62 -> 24.6
A18: =入力用!B11 -> 25/8 | B18: =入力用!N11 -> 50.5 | C18: =入力用!N24 -> 20.8 | D18: =入力用!N37 -> 41.2 | E18: =入力用!N50 -> 12.8 | F18: =入力用!N63 -> 25.3
A19: =入力用!B12 -> 25/9 | B19: =入力用!N12 -> 0 | C19: =入力用!N25 -> 0 | D19: =入力用!N38 -> #DIV/0! | E19: =入力用!N51 -> 0 | F19: =入力用!N64 -> 0
A20: =入力用!B13 -> 25/10 | B20: =入力用!N13 -> 51 | C20: =入力用!N26 -> 21 | D20: =入力用!N39 -> 41.2 | E20: =入力用!N52 -> 12.8 | F20: =入力用!N65 -> 25.2
A21: =入力用!B15 -> 25/12 | B21: =入力用!N15 -> 50.3 | C21: =入力用!N28 -> 20.5 | D21: =入力用!N41 -> 40.8 | E21: =入力用!N54 -> 13.1 | F21: =入力用!N67 -> 26

Sheet 髙橋
A2: NSSU Soft tennis Team Inbody Feedback Sheet
A8: 氏名： | B8: =入力用!O2 -> 髙橋ひかる | C8: 性別： | D8: =入力用!AL2 -> 女
A9: 測定日 | B9: 体重 (kg) | C9: 骨格筋量 (kg) | D9: 骨格筋量/体重 (%) | E9: 体脂肪量 (kg) | F9: 体脂肪率 (%)
A10: =入力用!B3 -> 24/12 | B10: =入力用!O3 -> 60.1 | C10: =入力用!O16 -> 24.9 | D10: =入力用!O29 -> 41.4 | E10: =入力用!O42 -> 15.7 | F10: =入力用!O55 -> 26.1
A11: =入力用!B4 -> 25/1 | B11: =入力用!O4 -> 61.1 | C11: =入力用!O17 -> 24.6 | D11: =入力用!O30 -> 40.3 | E11: =入力用!O43 -> 17 | F11: =入力用!O56 -> 27.8
A12: =入力用!B5 -> 25/2 | B12: =入力用!O5 -> 0 | C12: =入力用!O18 -> 0 | D12: =入力用!O31 -> #DIV/0! | E12: =入力用!O44 -> 0 | F12: =入力用!O57 -> 0
A13: =入力用!B6 -> 25/3 | B13: =入力用!O6 -> 61 | C13: =入力用!O19 -> 24.2 | D13: =入力用!O32 -> 39.7 | E13: =入力用!O45 -> 17.5 | F13: =入力用!O58 -> 28.7
A14: =入力用!B7 -> 25/4 | B14: =入力用!O7 -> 58.6 | C14: =入力用!O20 -> 23.9 | D14: =入力用!O33 -> 40.8 | E14: =入力用!O46 -> 15.7 | F14: =入力用!O59 -> 26.8
A15: =入力用!B8 -> 25/5 | B15: =入力用!O8 -> 58.6 | C15: =入力用!O21 -> 24.3 | D15: =入力用!O34 -> 41.5 | E15: =入力用!O47 -> 15.1 | F15: =入力用!O60 -> 25.8
A16: =入力用!B9 -> 25/6 | B16: =入力用!O9 -> 0 | C16: =入力用!O22 -> 0 | D16: =入力用!O35 -> #DIV/0! | E16: =入力用!O48 -> 0 | F16: =入力用!O61 -> 0
A17: =入力用!B10 -> 25/7 | B17: =入力用!O10 -> 56.8 | C17: =入力用!O23 -> 23.1 | D17: =入力用!O36 -> 40.7 | E17: =入力用!O49 -> 14.9 | F17: =入力用!O62 -> 26.2
A18: =入力用!B11 -> 25/8 | B18: =入力用!O11 -> 55.1 | C18: =入力用!O24 -> 23.5 | D18: =入力用!O37 -> 42.6 | E18: =入力用!O50 -> 13 | F18: =入力用!O63 -> 23.6
A19: =入力用!B12 -> 25/9 | B19: =入力用!O12 -> 0 | C19: =入力用!O25 -> 0 | D19: =入力用!O38 -> #DIV/0! | E19: =入力用!O51 -> 0 | F19: =入力用!O64 -> 0
A20: =入力用!B13 -> 25/10 | B20: =入力用!O13 -> 56 | C20: =入力用!O26 -> 23.3 | D20: =入力用!O39 -> 41.6 | E20: =入力用!O52 -> 13.6 | F20: =入力用!O65 -> 24.2
A21: =入力用!B15 -> 25/12 | B21: =入力用!O15 -> 53.5 | C21: =入力用!O28 -> 22.8 | D21: =入力用!O41 -> 42.6 | E21: =入力用!O54 -> 14.3 | F21: =入力用!O67 -> 21.1

Sheet 天間
A2: NSSU Soft tennis Team Inbody Feedback Sheet
A8: 氏名： | B8: =入力用!P2 -> 天間美嘉 | C8: 性別： | D8: =入力用!AL2 -> 女
A9: 測定日 | B9: 体重 (kg) | C9: 骨格筋量 (kg) | D9: 骨格筋量/体重 (%) | E9: 体脂肪量 (kg) | F9: 体脂肪率 (%)
A10: =入力用!B3 -> 24/12 | B10: =入力用!P3 -> 56.8 | C10: =入力用!P16 -> 22 | D10: =入力用!P29 -> 38.7 | E10: =入力用!P42 -> 16.7 | F10: =入力用!P55 -> 29.4
A11: =入力用!B4 -> 25/1 | B11: =入力用!P4 -> 0 | C11: =入力用!P17 -> 0 | D11: =入力用!P30 -> #DIV/0! | E11: =入力用!P43 -> 0 | F11: =入力用!P56 -> 0
A12: =入力用!B5 -> 25/2 | B12: =入力用!P5 -> 0 | C12: =入力用!P18 -> 0 | D12: =入力用!P31 -> #DIV/0! | E12: =入力用!P44 -> 0 | F12: =入力用!P57 -> 0
A13: =入力用!B6 -> 25/3 | B13: =入力用!P6 -> 58.2 | C13: =入力用!P19 -> 22.2 | D13: =入力用!P32 -> 38.1 | E13: =入力用!P45 -> 18 | F13: =入力用!P58 -> 30.9
A14: =入力用!B7 -> 25/4 | B14: =入力用!P7 -> 0 | C14: =入力用!P20 -> 0 | D14: =入力用!P33 -> #DIV/0! | E14: =入力用!P46 -> 0 | F14: =入力用!P59 -> 0
A15: =入力用!B8 -> 25/5 | B15: =入力用!P8 -> 59.7 | C15: =入力用!P21 -> 22.6 | D15: =入力用!P34 -> 37.9 | E15: =入力用!P47 -> 18.7 | F15: =入力用!P60 -> 31.3
A16: =入力用!B9 -> 25/6 | B16: =入力用!P9 -> 0 | C16: =入力用!P22 -> 0 | D16: =入力用!P35 -> #DIV/0! | E16: =入力用!P48 -> 0 | F16: =入力用!P61 -> 0
A17: =入力用!B10 -> 25/7 | B17: =入力用!P10 -> 60.5 | C17: =入力用!P23 -> 22.3 | D17: =入力用!P36 -> 36.9 | E17: =入力用!P49 -> 19.8 | F17: =入力用!P62 -> 32.6
A18: =入力用!B11 -> 25/8 | B18: =入力用!P11 -> 0 | C18: =入力用!P24 -> 0 | D18: =入力用!P37 -> #DIV/0! | E18: =入力用!P50 -> 0 | F18: =入力用!P63 -> 0
A19: =入力用!B12 -> 25/9 | B19: =入力用!P12 -> 0 | C19: =入力用!P25 -> 0 | D19: =入力用!P38 -> #DIV/0! | E19: =入力用!P51 -> 0 | F19: =入力用!P64 -> 0
A20: =入力用!B13 -> 25/10 | B20: =入力用!P13 -> 59 | C20: =入力用!P26 -> 22.5 | D20: =入力用!P39 -> 38.1 | E20: =入力用!P52 -> 17.9 | F20: =入力用!P65 -> 30.4
A21: =入力用!B15 -> 25/12 | B21: =入力用!P15 -> 56.7 | C21: =入力用!P28 -> 22.2 | D21: =入力用!P41 -> 39.2 | E21: =入力用!P54 -> 16 | F21: =入力用!P67 -> 28.3

Sheet 長根
A2: NSSU Soft tennis Team Inbody Feedback Sheet
A8: 氏名： | B8: =入力用!Q2 -> 長根理子 | C8: 性別： | D8: =入力用!AL2 -> 女
A9: 測定日 | B9: 体重 (kg) | C9: 骨格筋量 (kg) | D9: 骨格筋量/体重 (%) | E9: 体脂肪量 (kg) | F9: 体脂肪率 (%)
A10: =入力用!B3 -> 24/12 | B10: =入力用!Q3 -> 57.9 | C10: =入力用!Q16 -> 24 | D10: =入力用!Q29 -> 41.5 | E10: =入力用!Q42 -> 14.7 | F10: =入力用!Q55 -> 26.4
A11: =入力用!B4 -> 25/1 | B11: =入力用!Q4 -> 57.7 | C11: =入力用!Q17 -> 23.4 | D11: =入力用!Q30 -> 40.6 | E11: =入力用!Q43 -> 15.3 | F11: =入力用!Q56 -> 26.6
A12: =入力用!B5 -> 25/2 | B12: =入力用!Q5 -> 0 | C12: =入力用!Q18 -> 0 | D12: =入力用!Q31 -> #DIV/0! | E12: =入力用!Q44 -> 0 | F12: =入力用!Q57 -> 0
A13: =入力用!B6 -> 25/3 | B13: =入力用!Q6 -> 59.7 | C13: =入力用!Q19 -> 25.2 | D13: =入力用!Q32 -> 42.2 | E13: =入力用!Q45 -> 14.6 | F13: =入力用!Q58 -> 24.4
A14: =入力用!B7 -> 25/4 | B14: =入力用!Q7 -> 58.7 | C14: =入力用!Q20 -> 25 | D14: =入力用!Q33 -> 42.6 | E14: =入力用!Q46 -> 14 | F14: =入力用!Q59 -> 23.8
A15: =入力用!B8 -> 25/5 | B15: =入力用!Q8 -> 58.6 | C15: =入力用!Q21 -> 25 | D15: =入力用!Q34 -> 42.7 | E15: =入力用!Q47 -> 13.9 | F15: =入力用!Q60 -> 23.7
A16: =入力用!B9 -> 25/6 | B16: =入力用!Q9 -> 0 | C16: =入力用!Q22 -> 0 | D16: =入力用!Q35 -> #DIV/0! | E16: =入力用!Q48 -> 0 | F16: =入力用!Q61 -> 0
A17: =入力用!B10 -> 25/7 | B17: =入力用!Q10 -> 0 | C17: =入力用!Q23 -> 0 | D17: =入力用!Q36 -> #DIV/0! | E17: =入力用!Q49 -> 0 | F17: =入力用!Q62 -> 0
A18: =入力用!B11 -> 25/8 | B18: =入力用!Q11 -> 59.6 | C18: =入力用!Q24 -> 25.2 | D18: =入力用!Q37 -> 42.3 | E18: =入力用!Q50 -> 14.1 | F18: =入力用!Q63 -> 23.6
A19: =入力用!B12 -> 25/9 | B19: =入力用!Q12 -> 0 | C19: =入力用!Q25 -> 0 | D19: =入力用!Q38 -> #DIV/0! | E19: =入力用!Q51 -> 0 | F19: =入力用!Q64 -> 0
A20: =入力用!B13 -> 25/10 | B20: =入力用!Q13 -> 57.7 | C20: =入力用!Q26 -> 23.9 | D20: =入力用!Q39 -> 41.4 | E20: =入力用!Q52 -> 14.3 | F20: =入力用!Q65 -> 24.9
A21: =入力用!B15 -> 25/12 | B21: =入力用!Q15 -> 55.7 | C21: =入力用!Q28 -> 24.6 | D21: =入力用!Q41 -> 44.2 | E21: =入力用!Q54 -> 11.7 | F21: =入力用!Q67 -> 21

Sheet 藤井
A2: NSSU Soft tennis Team Inbody Feedback Sheet
A8: 氏名： | B8: =入力用!S2 -> 藤井真菜 | C8: 性別： | D8: =入力用!AL2 -> 女
A9: 測定日 | B9: 体重 (kg) | C9: 骨格筋量 (kg) | D9: 骨格筋量/体重 (%) | E9: 体脂肪量 (kg) | F9: 体脂肪率 (%)
A10: =入力用!B3 -> 24/12 | B10: =入力用!S3 -> 63.3 | C10: =入力用!S16 -> 27.3 | D10: =入力用!S29 -> 43.1 | E10: =入力用!S42 -> 14.4 | F10: =入力用!S55 -> 22.7
A11: =入力用!B4 -> 25/1 | B11: =入力用!S4 -> 63.5 | C11: =入力用!S17 -> 26.5 | D11: =入力用!S30 -> 41.7 | E11: =入力用!S43 -> 15.7 | F11: =入力用!S56 -> 24.7
A12: =入力用!B5 -> 25/2 | B12: =入力用!S5 -> 0 | C12: =入力用!S18 -> 0 | D12: =入力用!S31 -> #DIV/0! | E12: =入力用!S44 -> 0 | F12: =入力用!S57 -> 0
A13: =入力用!B6 -> 25/3 | B13: =入力用!S6 -> 66.1 | C13: =入力用!S19 -> 27.6 | D13: =入力用!S32 -> 41.8 | E13: =入力用!S45 -> 16.7 | F13: =入力用!S58 -> 25.2
A14: =入力用!B7 -> 25/4 | B14: =入力用!S7 -> 64.5 | C14: =入力用!S20 -> 27.2 | D14: =入力用!S33 -> 42.2 | E14: =入力用!S46 -> 16 | F14: =入力用!S59 -> 24.7
A15: =入力用!B8 -> 25/5 | B15: =入力用!S8 -> 66.1 | C15: =入力用!S21 -> 27 | D15: =入力用!S34 -> 40.8 | E15: =入力用!S47 -> 17.9 | F15: =入力用!S60 -> 27.2
A16: =入力用!B9 -> 25/6 | B16: =入力用!S9 -> 0 | C16: =入力用!S22 -> 0 | D16: =入力用!S35 -> #DIV/0! | E16: =入力用!S48 -> 0 | F16: =入力用!S61 -> 0
A17: =入力用!B10 -> 25/7 | B17: =入力用!S10 -> 64.1 | C17: =入力用!S23 -> 26.7 | D17: =入力用!S36 -> 41.7 | E17: =入力用!S49 -> 16 | F17: =入力用!S62 -> 25
A18: =入力用!B11 -> 25/8 | B18: =入力用!S11 -> 65.3 | C18: =入力用!S24 -> 27.1 | D18: =入力用!S37 -> 41.5 | E18: =入力用!S50 -> 16.5 | F18: =入力用!S63 -> 25.3
A19: =入力用!B12 -> 25/9 | B19: =入力用!S12 -> 0 | C19: =入力用!S25 -> 0 | D19: =入力用!S38 -> #DIV/0! | E19: =入力用!S51 -> 0 | F19: =入力用!S64 -> 0
A20: =入力用!B13 -> 25/10 | B20: =入力用!S13 -> 64 | C20: =入力用!S26 -> 26.2 | D20: =入力用!S39 -> 40.9 | E20: =入力用!S52 -> 16.6 | F20: =入力用!S65 -> 26
A21: =入力用!B15 -> 25/12 | B21: =入力用!S15 -> 61.1 | C21: =入力用!S28 -> 26 | D21: =入力用!S41 -> 42.6 | E21: =入力用!S54 -> 14.5 | F21: =入力用!S67 -> 23.7

Sheet 松岡
A2: NSSU Soft tennis Team Inbody Feedback Sheet
A8: 氏名： | B8: =入力用!T2 -> 松岡琴美 | C8: 性別： | D8: =入力用!AL2 -> 女
A9: 測定日 | B9: 体重 (kg) | C9: 骨格筋量 (kg) | D9: 骨格筋量/体重 (%) | E9: 体脂肪量 (kg) | F9: 体脂肪率 (%)
A10: =入力用!B3 -> 24/12 | B10: =入力用!T3 -> 49.6 | C10: =入力用!T16 -> 20.2 | D10: =入力用!T29 -> 40.7 | E10: =入力用!T42 -> 12.6 | F10: =入力用!T55 -> 25.4
A11: =入力用!B4 -> 25/1 | B11: =入力用!T4 -> 50 | C11: =入力用!T17 -> 19.7 | D11: =入力用!T30 -> 39.4 | E11: =入力用!T43 -> 13.7 | F11: =入力用!T56 -> 27.3
A12: =入力用!B5 -> 25/2 | B12: =入力用!T5 -> 0 | C12: =入力用!T18 -> 0 | D12: =入力用!T31 -> #DIV/0! | E12: =入力用!T44 -> 0 | F12: =入力用!T57 -> 0
A13: =入力用!B6 -> 25/3 | B13: =入力用!T6 -> 52.8 | C13: =入力用!T19 -> 21 | D13: =入力用!T32 -> 39.8 | E13: =入力用!T45 -> 14.8 | F13: =入力用!T58 -> 28
A14: =入力用!B7 -> 25/4 | B14: =入力用!T7 -> 51.1 | C14: =入力用!T20 -> 20.8 | D14: =入力用!T33 -> 40.7 | E14: =入力用!T46 -> 13.6 | F14: =入力用!T59 -> 26.7
A15: =入力用!B8 -> 25/5 | B15: =入力用!T8 -> 52.9 | C15: =入力用!T21 -> 22.5 | D15: =入力用!T34 -> 42.5 | E15: =入力用!T47 -> 12.4 | F15: =入力用!T60 -> 23.4
A16: =入力用!B9 -> 25/6 | B16: =入力用!T9 -> 0 | C16: =入力用!T22 -> 0 | D16: =入力用!T35 -> #DIV/0! | E16: =入力用!T48 -> 0 | F16: =入力用!T61 -> 0
A17: =入力用!B10 -> 25/7 | B17: =入力用!T10 -> 52.1 | C17: =入力用!T23 -> 21 | D17: =入力用!T36 -> 40.3 | E17: =入力用!T49 -> 13.8 | F17: =入力用!T62 -> 26.5
A18: =入力用!B11 -> 25/8 | B18: =入力用!T11 -> 51.9 | C18: =入力用!T24 -> 21.3 | D18: =入力用!T37 -> 41 | E18: =入力用!T50 -> 13.3 | F18: =入力用!T63 -> 25.6
A19: =入力用!B12 -> 25/9 | B19: =入力用!T12 -> 0 | C19: =入力用!T25 -> 0 | D19: =入力用!T38 -> #DIV/0! | E19: =入力用!T51 -> 0 | F19: =入力用!T64 -> 0
A20: =入力用!B13 -> 25/10 | B20: =入力用!T13 -> 51.6 | C20: =入力用!T26 -> 20.7 | D20: =入力用!T39 -> 40.1 | E20: =入力用!T52 -> 13.9 | F20: =入力用!T65 -> 27
A21: =入力用!B15 -> 25/12 | B21: =入力用!T15 -> 50.8 | C21: =入力用!T28 -> 21.1 | D21: =入力用!T41 -> 41.5 | E21: =入力用!T54 -> 12.7 | F21: =入力用!T67 -> 25

Sheet 吉木
A2: NSSU Soft tennis Team Inbody Feedback Sheet
A8: 氏名： | B8: =入力用!U2 -> 吉木理彩 | C8: 性別： | D8: =入力用!AL2 -> 女
A9: 測定日 | B9: 体重 (kg) | C9: 骨格筋量 (kg) | D9: 骨格筋量/体重 (%) | E9: 体脂肪量 (kg) | F9: 体脂肪率 (%)
A10: =入力用!B3 -> 24/12 | B10: =入力用!U3 -> 54 | C10: =入力用!U16 -> 23 | D10: =入力用!U29 -> 42.6 | E10: =入力用!U42 -> 12.3 | F10: =入力用!U55 -> 22.8
A11: =入力用!B4 -> 25/1 | B11: =入力用!U4 -> 55.5 | C11: =入力用!U17 -> 22.5 | D11: =入力用!U30 -> 40.5 | E11: =入力用!U43 -> 14.2 | F11: =入力用!U56 -> 25.5
A12: =入力用!B5 -> 25/2 | B12: =入力用!U5 -> 0 | C12: =入力用!U18 -> 0 | D12: =入力用!U31 -> #DIV/0! | E12: =入力用!U44 -> 0 | F12: =入力用!U57 -> 0
A13: =入力用!B6 -> 25/3 | B13: =入力用!U6 -> 57.5 | C13: =入力用!U19 -> 24 | D13: =入力用!U32 -> 41.7 | E13: =入力用!U45 -> 14 | F13: =入力用!U58 -> 24.4
A14: =入力用!B7 -> 25/4 | B14: =入力用!U7 -> 56.5 | C14: =入力用!U20 -> 23.4 | D14: =入力用!U33 -> 41.4 | E14: =入力用!U46 -> 14 | F14: =入力用!U59 -> 24.8
A15: =入力用!B8 -> 25/5 | B15: =入力用!U8 -> 56.4 | C15: =入力用!U21 -> 23.5 | D15: =入力用!U34 -> 41.7 | E15: =入力用!U47 -> 14 | F15: =入力用!U60 -> 24.8
A16: =入力用!B9 -> 25/6 | B16: =入力用!U9 -> 0 | C16: =入力用!U22 -> 0 | D16: =入力用!U35 -> #DIV/0! | E16: =入力用!U48 -> 0 | F16: =入力用!U61 -> 0
A17: =入力用!B10 -> 25/7 | B17: =入力用!U10 -> 54.9 | C17: =入力用!U23 -> 23.7 | D17: =入力用!U36 -> 43.2 | E17: =入力用!U49 -> 12.7 | F17: =入力用!U62 -> 23.1
A18: =入力用!B11 -> 25/8 | B18: =入力用!U11 -> 0 | C18: =入力用!U24 -> 0 | D18: =入力用!U37 -> #DIV/0! | E18: =入力用!U50 -> 0 | F18: =入力用!U63 -> 0
A19: =入力用!B12 -> 25/9 | B19: =入力用!U12 -> 0 | C19: =入力用!U25 -> 0 | D19: =入力用!U38 -> #DIV/0! | E19: =入力用!U51 -> 0 | F19: =入力用!U64 -> 0
A20: =入力用!B13 -> 25/10 | B20: =入力用!U13 -> 57.5 | C20: =入力用!U26 -> 24.1 | D20: =入力用!U39 -> 41.9 | E20: =入力用!U52 -> 14 | F20: =入力用!U65 -> 24.4
A21: =入力用!B15 -> 25/12 | B21: =入力用!U15 -> 57.2 | C21: =入力用!U28 -> 22.6 | D21: =入力用!U41 -> 39.5 | E21: =入力用!U54 -> 16.4 | F21: =入力用!U67 -> 28.7

Sheet 渡邉
A2: NSSU Soft tennis Team Inbody Feedback Sheet
A8: 氏名： | B8: =入力用!V2 -> 渡邉妃菜乃 | C8: 性別： | D8: =入力用!AL2 -> 女
A9: 測定日 | B9: 体重 (kg) | C9: 骨格筋量 (kg) | D9: 骨格筋量/体重 (%) | E9: 体脂肪量 (kg) | F9: 体脂肪率 (%)
A10: =入力用!B3 -> 24/12 | B10: =入力用!V3 -> 51.5 | C10: =入力用!V16 -> 19.4 | D10: =入力用!V29 -> 37.7 | E10: =入力用!V42 -> 15.8 | F10: =入力用!V55 -> 30.7
A11: =入力用!B4 -> 25/1 | B11: =入力用!V4 -> 51.4 | C11: =入力用!V17 -> 18.8 | D11: =入力用!V30 -> 36.6 | E11: =入力用!V43 -> 16.5 | F11: =入力用!V56 -> 32
A12: =入力用!B5 -> 25/2 | B12: =入力用!V5 -> 0 | C12: =入力用!V18 -> 0 | D12: =入力用!V31 -> #DIV/0! | E12: =入力用!V44 -> 0 | F12: =入力用!V57 -> 0
A13: =入力用!B6 -> 25/3 | B13: =入力用!V6 -> 50.6 | C13: =入力用!V19 -> 18.9 | D13: =入力用!V32 -> 37.4 | E13: =入力用!V45 -> 16 | F13: =入力用!V58 -> 31.6
A14: =入力用!B7 -> 25/4 | B14: =入力用!V7 -> 49.2 | C14: =入力用!V20 -> 18.8 | D14: =入力用!V33 -> 38.2 | E14: =入力用!V46 -> 14.7 | F14: =入力用!V59 -> 29.9
A15: =入力用!B8 -> 25/5 | B15: =入力用!V8 -> 50.3 | C15: =入力用!V21 -> 19.3 | D15: =入力用!V34 -> 38.4 | E15: =入力用!V47 -> 14.9 | F15: =入力用!V60 -> 29.5
A16: =入力用!B9 -> 25/6 | B16: =入力用!V9 -> 0 | C16: =入力用!V22 -> 0 | D16: =入力用!V35 -> #DIV/0! | E16: =入力用!V48 -> 0 | F16: =入力用!V61 -> 0
A17: =入力用!B10 -> 25/7 | B17: =入力用!V10 -> 48.4 | C17: =入力用!V23 -> 19 | D17: =入力用!V36 -> 39.3 | E17: =入力用!V49 -> 13.3 | F17: =入力用!V62 -> 27.5
A18: =入力用!B11 -> 25/8 | B18: =入力用!V11 -> 48.4 | C18: =入力用!V24 -> 19.1 | D18: =入力用!V37 -> 39.5 | E18: =入力用!V50 -> 12.8 | F18: =入力用!V63 -> 26.5
A19: =入力用!B12 -> 25/9 | B19: =入力用!V12 -> 0 | C19: =入力用!V25 -> 0 | D19: =入力用!V38 -> #DIV/0! | E19: =入力用!V51 -> 0 | F19: =入力用!V64 -> 0
A20: =入力用!B13 -> 25/10 | B20: =入力用!V13 -> 49 | C20: =入力用!V26 -> 18.8 | D20: =入力用!V39 -> 38.4 | E20: =入力用!V52 -> 14.1 | F20: =入力用!V65 -> 28.7
A21: =入力用!B15 -> 25/12 | B21: =入力用!V15 -> 48.2 | C21: =入力用!V28 -> 18.5 | D21: =入力用!V41 -> 38.4 | E21: =入力用!V54 -> 14.1 | F21: =入力用!V67 -> 29.2

Sheet 岩田
A2: NSSU Soft tennis Team Inbody Feedback Sheet
A8: 氏名： | B8: =入力用!W2 -> 岩田愛美 | C8: 性別： | D8: 女
A9: 測定日 | B9: 体重 (kg) | C9: 骨格筋量 (kg) | D9: 骨格筋量/体重 (%) | E9: 体脂肪量 (kg) | F9: 体脂肪率 (%)
A10: =入力用!B3 -> 24/12 | B10: =入力用!W3 -> 55.3 | C10: =入力用!W16 -> 24.7 | D10: =入力用!W29 -> 44.7 | E10: =入力用!W42 -> 11.3 | F10: =入力用!W55 -> 20.4
A11: =入力用!B4 -> 25/1 | B11: =入力用!W4 -> 55.5 | C11: =入力用!W17 -> 24.3 | D11: =入力用!W30 -> 43.8 | E11: =入力用!W43 -> 11.7 | F11: =入力用!W56 -> 21.1
A12: =入力用!B5 -> 25/2 | B12: =入力用!W5 -> 0 | C12: =入力用!W18 -> 0 | D12: =入力用!W31 -> #DIV/0! | E12: =入力用!W44 -> 0 | F12: =入力用!W57 -> 0
A13: =入力用!B6 -> 25/3 | B13: =入力用!W6 -> 54.5 | C13: =入力用!W19 -> 24.5 | D13: =入力用!W32 -> 45 | E13: =入力用!W45 -> 10.8 | F13: =入力用!W58 -> 19.9
A14: =入力用!B7 -> 25/4 | B14: =入力用!W7 -> 54.3 | C14: =入力用!W20 -> 24 | D14: =入力用!W33 -> 44.2 | E14: =入力用!W46 -> 11.4 | F14: =入力用!W59 -> 21.1
A15: =入力用!B8 -> 25/5 | B15: =入力用!W8 -> 54 | C15: =入力用!W21 -> 24.2 | D15: =入力用!W34 -> 44.8 | E15: =入力用!W47 -> 10.9 | F15: =入力用!W60 -> 20.2
A16: =入力用!B9 -> 25/6 | B16: =入力用!W9 -> 0 | C16: =入力用!W22 -> 0 | D16: =入力用!W35 -> #DIV/0! | E16: =入力用!W48 -> 0 | F16: =入力用!W61 -> 0
A17: =入力用!B10 -> 25/7 | B17: =入力用!W10 -> 52.7 | C17: =入力用!W23 -> 24 | D17: =入力用!W36 -> 45.5 | E17: =入力用!W49 -> 9.7 | F17: =入力用!W62 -> 18.4
A18: =入力用!B11 -> 25/8 | B18: =入力用!W11 -> 53.5 | C18: =入力用!W24 -> 24.8 | D18: =入力用!W37 -> 46.4 | E18: =入力用!W50 -> 9.3 | F18: =入力用!W63 -> 17.4
A19: =入力用!B12 -> 25/9 | B19: =入力用!W12 -> 0 | C19: =入力用!W25 -> 0 | D19: =入力用!W38 -> #DIV/0! | E19: =入力用!W51 -> 0 | F19: =入力用!W64 -> 0
A20: =入力用!B13 -> 25/10 | B20: =入力用!W13 -> 54.3 | C20: =入力用!W26 -> 23.9 | D20: =入力用!W39 -> 44 | E20: =入力用!W52 -> 11.5 | F20: =入力用!W65 -> 21.2
A21: =入力用!B15 -> 25/12 | B21: =入力用!W15 -> 53.2 | C21: =入力用!W28 -> 24.2 | D21: =入力用!W41 -> 45.5 | E21: =入力用!W54 -> 10.2 | F21: =入力用!W67 -> 19.1

Sheet 内田
A2: NSSU Soft tennis Team Inbody Feedback Sheet
A8: 氏名： | B8: =入力用!X2 -> 内田真愛 | C8: 性別： | D8: 女
A9: 測定日 | B9: 体重 (kg) | C9: 骨格筋量 (kg) | D9: 骨格筋量/体重 (%) | E9: 体脂肪量 (kg) | F9: 体脂肪率 (%)
A10: =入力用!B3 -> 24/12 | B10: =入力用!X3 -> 57.4 | C10: =入力用!X16 -> 24.7 | D10: =入力用!X29 -> 43 | E10: =入力用!X42 -> 12.5 | F10: =入力用!X55 -> 21.8
A11: =入力用!B4 -> 25/1 | B11: =入力用!X4 -> 56 | C11: =入力用!X17 -> 24.2 | D11: =入力用!X30 -> 43.2 | E11: =入力用!X43 -> 12.1 | F11: =入力用!X56 -> 21.6
A12: =入力用!B5 -> 25/2 | B12: =入力用!X5 -> 0 | C12: =入力用!X18 -> 0 | D12: =入力用!X31 -> #DIV/0! | E12: =入力用!X44 -> 0 | F12: =入力用!X57 -> 0
A13: =入力用!B6 -> 25/3 | B13: =入力用!X6 -> 55.7 | C13: =入力用!X19 -> 24 | D13: =入力用!X32 -> 43.1 | E13: =入力用!X45 -> 12.4 | F13: =入力用!X58 -> 22.3
A14: =入力用!B7 -> 25/4 | B14: =入力用!X7 -> 56.9 | C14: =入力用!X20 -> 24.6 | D14: =入力用!X33 -> 43.2 | E14: =入力用!X46 -> 12.4 | F14: =入力用!X59 -> 21.7
A15: =入力用!B8 -> 25/5 | B15: =入力用!X8 -> 55.5 | C15: =入力用!X21 -> 24.3 | D15: =入力用!X34 -> 43.8 | E15: =入力用!X47 -> 11.6 | F15: =入力用!X60 -> 20.8
A16: =入力用!B9 -> 25/6 | B16: =入力用!X9 -> 0 | C16: =入力用!X22 -> 0 | D16: =入力用!X35 -> #DIV/0! | E16: =入力用!X48 -> 0 | F16: =入力用!X61 -> 0
A17: =入力用!B10 -> 25/7 | B17: =入力用!X10 -> 55.2 | C17: =入力用!X23 -> 24.5 | D17: =入力用!X36 -> 44.4 | E17: =入力用!X49 -> 11 | F17: =入力用!X62 -> 19.9
A18: =入力用!B11 -> 25/8 | B18: =入力用!X11 -> 53.5 | C18: =入力用!X24 -> 23.3 | D18: =入力用!X37 -> 43.6 | E18: =入力用!X50 -> 11.1 | F18: =入力用!X63 -> 20.8
A19: =入力用!B12 -> 25/9 | B19: =入力用!X12 -> 0 | C19: =入力用!X25 -> 0 | D19: =入力用!X38 -> #DIV/0! | E19: =入力用!X51 -> 0 | F19: =入力用!X64 -> 0
A20: =入力用!B13 -> 25/10 | B20: =入力用!X13 -> 54.9 | C20: =入力用!X26 -> 23.7 | D20: =入力用!X39 -> 43.2 | E20: =入力用!X52 -> 12 | F20: =入力用!X65 -> 21.8
A21: =入力用!B15 -> 25/12 | B21: =入力用!X15 -> 55.2 | C21: =入力用!X28 -> 24.9 | D21: =入力用!X41 -> 45.1 | E21: =入力用!X54 -> 10.4 | F21: =入力用!X67 -> 18.8

Sheet 徳山
A2: NSSU Soft tennis Team Inbody Feedback Sheet
A8: 氏名： | B8: =入力用!Y2 -> 徳山暖枝 | C8: 性別： | D8: 女
A9: 測定日 | B9: 体重 (kg) | C9: 骨格筋量 (kg) | D9: 骨格筋量/体重 (%) | E9: 体脂肪量 (kg) | F9: 体脂肪率 (%)
A10: =入力用!B3 -> 24/12 | B10: =入力用!Y3 -> 62.8 | C10: =入力用!Y16 -> 22.8 | D10: =入力用!Y29 -> 36.3 | E10: =入力用!Y42 -> 21.5 | F10: =入力用!Y55 -> 34.2
A11: =入力用!B4 -> 25/1 | B11: =入力用!Y4 -> 60.8 | C11: =入力用!Y17 -> 22.3 | D11: =入力用!Y30 -> 36.7 | E11: =入力用!Y43 -> 20.4 | F11: =入力用!Y56 -> 33.5
A12: =入力用!B5 -> 25/2 | B12: =入力用!Y5 -> 0 | C12: =入力用!Y18 -> 0 | D12: =入力用!Y31 -> #DIV/0! | E12: =入力用!Y44 -> 0 | F12: =入力用!Y57 -> 0
A13: =入力用!B6 -> 25/3 | B13: =入力用!Y6 -> 63.6 | C13: =入力用!Y19 -> 23.3 | D13: =入力用!Y32 -> 36.6 | E13: =入力用!Y45 -> 21.7 | F13: =入力用!Y58 -> 34.1
A14: =入力用!B7 -> 25/4 | B14: =入力用!Y7 -> 61.9 | C14: =入力用!Y20 -> 22.9 | D14: =入力用!Y33 -> 37 | E14: =入力用!Y46 -> 20.7 | F14: =入力用!Y59 -> 33.4
A15: =入力用!B8 -> 25/5 | B15: =入力用!Y8 -> 63.6 | C15: =入力用!Y21 -> 24.1 | D15: =入力用!Y34 -> 37.9 | E15: =入力用!Y47 -> 20.2 | F15: =入力用!Y60 -> 31.8
A16: =入力用!B9 -> 25/6 | B16: =入力用!Y9 -> 0 | C16: =入力用!Y22 -> 0 | D16: =入力用!Y35 -> #DIV/0! | E16: =入力用!Y48 -> 0 | F16: =入力用!Y61 -> 0
A17: =入力用!B10 -> 25/7 | B17: =入力用!Y10 -> 62.2 | C17: =入力用!Y23 -> 23.2 | D17: =入力用!Y36 -> 37.3 | E17: =入力用!Y49 -> 20.4 | F17: =入力用!Y62 -> 32.7
A18: =入力用!B11 -> 25/8 | B18: =入力用!Y11 -> 61.1 | C18: =入力用!Y24 -> 22.7 | D18: =入力用!Y37 -> 37.2 | E18: =入力用!Y50 -> 19.9 | F18: =入力用!Y63 -> 32.6
A19: =入力用!B12 -> 25/9 | B19: =入力用!Y12 -> 0 | C19: =入力用!Y25 -> 0 | D19: =入力用!Y38 -> #DIV/0! | E19: =入力用!Y51 -> 0 | F19: =入力用!Y64 -> 0
A20: =入力用!B13 -> 25/10 | B20: =入力用!Y13 -> 61 | C20: =入力用!Y26 -> 22.7 | D20: =入力用!Y39 -> 37.2 | E20: =入力用!Y52 -> 19.8 | F20: =入力用!Y65 -> 32.4
A21: =入力用!B15 -> 25/12 | B21: =入力用!Y15 -> 61.8 | C21: =入力用!Y28 -> 23.2 | D21: =入力用!Y41 -> 37.5 | E21: =入力用!Y54 -> 20 | F21: =入力用!Y67 -> 32.4

Sheet 中村
A2: NSSU Soft tennis Team Inbody Feedback Sheet
A8: 氏名： | B8: =入力用!Z2 -> 中村楓芽 | C8: 性別： | D8: 女
A9: 測定日 | B9: 体重 (kg) | C9: 骨格筋量 (kg) | D9: 骨格筋量/体重 (%) | E9: 体脂肪量 (kg) | F9: 体脂肪率 (%)
A10: =入力用!B3 -> 24/12 | B10: =入力用!Z3 -> 58.2 | C10: =入力用!Z16 -> 24.3 | D10: =入力用!Z29 -> 41.8 | E10: =入力用!Z42 -> 15 | F10: =入力用!Z55 -> 25.8
A11: =入力用!B4 -> 25/1 | B11: =入力用!Z4 -> 57.3 | C11: =入力用!Z17 -> 23.9 | D11: =入力用!Z30 -> 41.7 | E11: =入力用!Z43 -> 14.9 | F11: =入力用!Z56 -> 26
A12: =入力用!B5 -> 25/2 | B12: =入力用!Z5 -> 0 | C12: =入力用!Z18 -> 0 | D12: =入力用!Z31 -> #DIV/0! | E12: =入力用!Z44 -> 0 | F12: =入力用!Z57 -> 0
A13: =入力用!B6 -> 25/3 | B13: =入力用!Z6 -> 57.4 | C13: =入力用!Z19 -> 24.2 | D13: =入力用!Z32 -> 42.2 | E13: =入力用!Z45 -> 14.4 | F13: =入力用!Z58 -> 25.1
A14: =入力用!B7 -> 25/4 | B14: =入力用!Z7 -> 57.9 | C14: =入力用!Z20 -> 23.9 | D14: =入力用!Z33 -> 41.3 | E14: =入力用!Z46 -> 15.3 | F14: =入力用!Z59 -> 26
A15: =入力用!B8 -> 25/5 | B15: =入力用!Z8 -> 58 | C15: =入力用!Z21 -> 24.2 | D15: =入力用!Z34 -> 41.7 | E15: =入力用!Z47 -> 15.3 | F15: =入力用!Z60 -> 26.4
A16: =入力用!B9 -> 25/6 | B16: =入力用!Z9 -> 0 | C16: =入力用!Z22 -> 0 | D16: =入力用!Z35 -> #DIV/0! | E16: =入力用!Z48 -> 0 | F16: =入力用!Z61 -> 0
A17: =入力用!B10 -> 25/7 | B17: =入力用!Z10 -> 59.6 | C17: =入力用!Z23 -> 25 | D17: =入力用!Z36 -> 41.9 | E17: =入力用!Z49 -> 14.8 | F17: =入力用!Z62 -> 24.9
A18: =入力用!B11 -> 25/8 | B18: =入力用!Z11 -> 57.4 | C18: =入力用!Z24 -> 24.5 | D18: =入力用!Z37 -> 42.7 | E18: =入力用!Z50 -> 13.7 | F18: =入力用!Z63 -> 23.8
A19: =入力用!B12 -> 25/9 | B19: =入力用!Z12 -> 0 | C19: =入力用!Z25 -> 0 | D19: =入力用!Z38 -> #DIV/0! | E19: =入力用!Z51 -> 0 | F19: =入力用!Z64 -> 0
